<sdf version='1.7'>
  <world name='default'>
    <model name='ground_plane'>
      <static>1</static>
      <link name='link'>
        <collision name='collision'>
          <geometry>
            <plane>
              <normal>0 0 1</normal>
              <size>100 100</size>
            </plane>
          </geometry>
          <surface>
            <contact>
              <collide_bitmask>65535</collide_bitmask>
              <ode/>
            </contact>
            <friction>
              <ode>
                <mu>100</mu>
                <mu2>50</mu2>
              </ode>
              <torsional>
                <ode/>
              </torsional>
            </friction>
            <bounce/>
          </surface>
          <max_contacts>10</max_contacts>
        </collision>
        <visual name='visual'>
          <cast_shadows>0</cast_shadows>
          <geometry>
            <plane>
              <normal>0 0 1</normal>
              <size>100 100</size>
            </plane>
          </geometry>
          <material>
            <script>
              <uri>file://media/materials/scripts/gazebo.material</uri>
              <name>Gazebo/Grey</name>
            </script>
          </material>
        </visual>
        <self_collide>0</self_collide>
        <enable_wind>0</enable_wind>
        <kinematic>0</kinematic>
      </link>
    </model>
    <light name='sun' type='directional'>
      <cast_shadows>1</cast_shadows>
      <pose>0 0 10 0 -0 0</pose>
      <diffuse>0.8 0.8 0.8 1</diffuse>
      <specular>0.2 0.2 0.2 1</specular>
      <attenuation>
        <range>1000</range>
        <constant>0.9</constant>
        <linear>0.01</linear>
        <quadratic>0.001</quadratic>
      </attenuation>
      <direction>-0.5 0.1 -0.9</direction>
      <spot>
        <inner_angle>0</inner_angle>
        <outer_angle>0</outer_angle>
        <falloff>0</falloff>
      </spot>
    </light>
    <gravity>0 0 -9.8</gravity>
    <magnetic_field>6e-06 2.3e-05 -4.2e-05</magnetic_field>
    <atmosphere type='adiabatic'/>
    <physics type='ode'>
      <max_step_size>0.001</max_step_size>
      <real_time_factor>1</real_time_factor>
      <real_time_update_rate>1000</real_time_update_rate>
    </physics>
    <scene>
      <ambient>0.4 0.4 0.4 1</ambient>
      <background>0.7 0.7 0.7 1</background>
      <shadows>1</shadows>
    </scene>
    <wind/>
    <spherical_coordinates>
      <surface_model>EARTH_WGS84</surface_model>
      <latitude_deg>0</latitude_deg>
      <longitude_deg>0</longitude_deg>
      <elevation>0</elevation>
      <heading_deg>0</heading_deg>
    </spherical_coordinates>
    <model name='robot'>
      <link name='base_footprint'>
        <inertial>
          <pose>0.004411 -0.000743 0.098793 0 -0 0</pose>
          <mass>33.664</mass>
          <inertia>
            <ixx>1.07533</ixx>
            <ixy>-0.131285</ixy>
            <ixz>-0.0155619</ixz>
            <iyy>2.41453</iyy>
            <iyz>0.00261984</iyz>
            <izz>3.12176</izz>
          </inertia>
        </inertial>
        <collision name='base_footprint_fixed_joint_lump__base_link_collision'>
          <pose>0 0 0.081572 0 -0 0</pose>
          <geometry>
            <mesh>
              <scale>0.01 0.01 0.01</scale>
              <uri>/home/jinmin/zm_ws/src/zm_robot/robot_description/meshes/agv_base.stl</uri>
            </mesh>
          </geometry>
          <surface>
            <contact>
              <ode>
                <kp>1e+30</kp>
                <kd>1e+20</kd>
              </ode>
            </contact>
            <friction>
              <ode>
                <mu>10</mu>
                <mu2>10</mu2>
              </ode>
              <torsional>
                <ode/>
              </torsional>
            </friction>
            <bounce/>
          </surface>
          <max_contacts>10</max_contacts>
        </collision>
        <collision name='base_footprint_fixed_joint_lump__IMU_sensor_collision_1'>
          <pose>0 0 0.161572 0 -0 0</pose>
          <geometry>
            <mesh>
              <scale>0.01 0.01 0.01</scale>
              <uri>/home/jinmin/zm_ws/src/zm_robot/robot_description/meshes/IMU_sensor.stl</uri>
            </mesh>
          </geometry>
          <surface>
            <contact>
              <ode/>
            </contact>
            <friction>
              <ode/>
              <torsional>
                <ode/>
              </torsional>
            </friction>
            <bounce/>
          </surface>
          <max_contacts>10</max_contacts>
        </collision>
        <collision name='base_footprint_fixed_joint_lump__kinect_v2_collision_2'>
          <pose>0.297 -0.05 0.203587 0 -0 0</pose>
          <geometry>
            <mesh>
              <scale>0.01 0.01 0.01</scale>
              <uri>/home/jinmin/zm_ws/src/zm_robot/robot_description/meshes/kinect_v2.stl</uri>
            </mesh>
          </geometry>
          <surface>
            <contact>
              <ode>
                <kp>1e+60</kp>
                <kd>1e+50</kd>
              </ode>
            </contact>
            <friction>
              <ode>
                <mu>30</mu>
                <mu2>30</mu2>
              </ode>
              <torsional>
                <ode/>
              </torsional>
            </friction>
            <bounce/>
          </surface>
          <max_contacts>10</max_contacts>
        </collision>
        <collision name='base_footprint_fixed_joint_lump__sick_lidar0_collision_3'>
          <pose>0.33 0.175 0.277294 0 -0 0.7854</pose>
          <geometry>
            <mesh>
              <scale>0.01 0.01 0.01</scale>
              <uri>/home/jinmin/zm_ws/src/zm_robot/robot_description/meshes/sick_s30b.stl</uri>
            </mesh>
          </geometry>
          <surface>
            <contact>
              <ode>
                <kp>1e+60</kp>
                <kd>1e+50</kd>
              </ode>
            </contact>
            <friction>
              <ode>
                <mu>30</mu>
                <mu2>30</mu2>
              </ode>
              <torsional>
                <ode/>
              </torsional>
            </friction>
            <bounce/>
          </surface>
          <max_contacts>10</max_contacts>
        </collision>
        <collision name='base_footprint_fixed_joint_lump__sick_lidar1_collision_4'>
          <pose>-0.33 -0.175 0.277294 0 0 -2.35619</pose>
          <geometry>
            <mesh>
              <scale>0.01 0.01 0.01</scale>
              <uri>/home/jinmin/zm_ws/src/zm_robot/robot_description/meshes/sick_s30b.stl</uri>
            </mesh>
          </geometry>
          <surface>
            <contact>
              <ode>
                <kp>1e+60</kp>
                <kd>1e+50</kd>
              </ode>
            </contact>
            <friction>
              <ode>
                <mu>30</mu>
                <mu2>30</mu2>
              </ode>
              <torsional>
                <ode/>
              </torsional>
            </friction>
            <bounce/>
          </surface>
          <max_contacts>10</max_contacts>
        </collision>
        <collision name='base_footprint_fixed_joint_lump__ultrasound_1_collision_5'>
          <pose>0.4 0.15 0.111572 0 -0 0</pose>
          <geometry>
            <mesh>
              <scale>0.1 0.1 0.1</scale>
              <uri>/home/jinmin/zm_ws/src/zm_robot/robot_description/meshes/ultrasound.stl</uri>
            </mesh>
          </geometry>
          <surface>
            <contact>
              <ode/>
            </contact>
            <friction>
              <ode/>
              <torsional>
                <ode/>
              </torsional>
            </friction>
            <bounce/>
          </surface>
          <max_contacts>10</max_contacts>
        </collision>
        <collision name='base_footprint_fixed_joint_lump__ultrasound_2_collision_6'>
          <pose>0.4 -0.15 0.111572 0 -0 0</pose>
          <geometry>
            <mesh>
              <scale>0.1 0.1 0.1</scale>
              <uri>/home/jinmin/zm_ws/src/zm_robot/robot_description/meshes/ultrasound.stl</uri>
            </mesh>
          </geometry>
          <surface>
            <contact>
              <ode/>
            </contact>
            <friction>
              <ode/>
              <torsional>
                <ode/>
              </torsional>
            </friction>
            <bounce/>
          </surface>
          <max_contacts>10</max_contacts>
        </collision>
        <collision name='base_footprint_fixed_joint_lump__ultrasound_3_collision_7'>
          <pose>-0.4 0.15 0.111572 0 0 -3.14159</pose>
          <geometry>
            <mesh>
              <scale>0.1 0.1 0.1</scale>
              <uri>/home/jinmin/zm_ws/src/zm_robot/robot_description/meshes/ultrasound.stl</uri>
            </mesh>
          </geometry>
          <surface>
            <contact>
              <ode/>
            </contact>
            <friction>
              <ode/>
              <torsional>
                <ode/>
              </torsional>
            </friction>
            <bounce/>
          </surface>
          <max_contacts>10</max_contacts>
        </collision>
        <collision name='base_footprint_fixed_joint_lump__ultrasound_4_collision_8'>
          <pose>-0.4 -0.15 0.111572 0 0 -3.14159</pose>
          <geometry>
            <mesh>
              <scale>0.1 0.1 0.1</scale>
              <uri>/home/jinmin/zm_ws/src/zm_robot/robot_description/meshes/ultrasound.stl</uri>
            </mesh>
          </geometry>
          <surface>
            <contact>
              <ode/>
            </contact>
            <friction>
              <ode/>
              <torsional>
                <ode/>
              </torsional>
            </friction>
            <bounce/>
          </surface>
          <max_contacts>10</max_contacts>
        </collision>
        <visual name='base_footprint_fixed_joint_lump__base_link_visual'>
          <pose>0 0 0.081572 0 -0 0</pose>
          <geometry>
            <mesh>
              <scale>0.01 0.01 0.01</scale>
              <uri>/home/jinmin/zm_ws/src/zm_robot/robot_description/meshes/agv_base.stl</uri>
            </mesh>
          </geometry>
          <material>
            <script>
              <name>Gazebo/Orange</name>
              <uri>file://media/materials/scripts/gazebo.material</uri>
            </script>
          </material>
        </visual>
        <visual name='base_footprint_fixed_joint_lump__IMU_sensor_visual_1'>
          <pose>0 0 0.161572 0 -0 0</pose>
          <geometry>
            <mesh>
              <scale>0.01 0.01 0.01</scale>
              <uri>/home/jinmin/zm_ws/src/zm_robot/robot_description/meshes/IMU_sensor.stl</uri>
            </mesh>
          </geometry>
        </visual>
        <visual name='base_footprint_fixed_joint_lump__kinect_v2_visual_2'>
          <pose>0.297 -0.05 0.203587 0 -0 0</pose>
          <geometry>
            <mesh>
              <scale>0.01 0.01 0.01</scale>
              <uri>/home/jinmin/zm_ws/src/zm_robot/robot_description/meshes/kinect_v2.stl</uri>
            </mesh>
          </geometry>
          <material>
            <script>
              <name>Gazebo/Black</name>
              <uri>file://media/materials/scripts/gazebo.material</uri>
            </script>
          </material>
        </visual>
        <visual name='base_footprint_fixed_joint_lump__sick_lidar0_visual_3'>
          <pose>0.33 0.175 0.277294 0 -0 0.7854</pose>
          <geometry>
            <mesh>
              <scale>0.01 0.01 0.01</scale>
              <uri>/home/jinmin/zm_ws/src/zm_robot/robot_description/meshes/sick_s30b.stl</uri>
            </mesh>
          </geometry>
          <material>
            <script>
              <name>Gazebo/Yellow</name>
              <uri>file://media/materials/scripts/gazebo.material</uri>
            </script>
          </material>
        </visual>
        <visual name='base_footprint_fixed_joint_lump__sick_lidar1_visual_4'>
          <pose>-0.33 -0.175 0.277294 0 0 -2.35619</pose>
          <geometry>
            <mesh>
              <scale>0.01 0.01 0.01</scale>
              <uri>/home/jinmin/zm_ws/src/zm_robot/robot_description/meshes/sick_s30b.stl</uri>
            </mesh>
          </geometry>
          <material>
            <script>
              <name>Gazebo/Yellow</name>
              <uri>file://media/materials/scripts/gazebo.material</uri>
            </script>
          </material>
        </visual>
        <visual name='base_footprint_fixed_joint_lump__ultrasound_1_visual_5'>
          <pose>0.4 0.15 0.111572 0 -0 0</pose>
          <geometry>
            <mesh>
              <scale>0.1 0.1 0.1</scale>
              <uri>/home/jinmin/zm_ws/src/zm_robot/robot_description/meshes/ultrasound.stl</uri>
            </mesh>
          </geometry>
        </visual>
        <visual name='base_footprint_fixed_joint_lump__ultrasound_2_visual_6'>
          <pose>0.4 -0.15 0.111572 0 -0 0</pose>
          <geometry>
            <mesh>
              <scale>0.1 0.1 0.1</scale>
              <uri>/home/jinmin/zm_ws/src/zm_robot/robot_description/meshes/ultrasound.stl</uri>
            </mesh>
          </geometry>
        </visual>
        <visual name='base_footprint_fixed_joint_lump__ultrasound_3_visual_7'>
          <pose>-0.4 0.15 0.111572 0 0 -3.14159</pose>
          <geometry>
            <mesh>
              <scale>0.1 0.1 0.1</scale>
              <uri>/home/jinmin/zm_ws/src/zm_robot/robot_description/meshes/ultrasound.stl</uri>
            </mesh>
          </geometry>
        </visual>
        <visual name='base_footprint_fixed_joint_lump__ultrasound_4_visual_8'>
          <pose>-0.4 -0.15 0.111572 0 0 -3.14159</pose>
          <geometry>
            <mesh>
              <scale>0.1 0.1 0.1</scale>
              <uri>/home/jinmin/zm_ws/src/zm_robot/robot_description/meshes/ultrasound.stl</uri>
            </mesh>
          </geometry>
        </visual>
        <gravity>1</gravity>
        <gravity>1</gravity>
        <sensor name='imu_sensor' type='imu'>
          <always_on>1</always_on>
          <update_rate>100</update_rate>
          <visualize>1</visualize>
          <topic>__default_topic__</topic>
          <plugin name='imu_plugin' filename='libgazebo_ros_imu_sensor.so'>
            <topicName>robot_imu</topicName>
            <bodyName>IMU_sensor</bodyName>
            <updateRateHZ>10.0</updateRateHZ>
            <gaussianNoise>0.0</gaussianNoise>
            <xyzOffset>0 0 0</xyzOffset>
            <rpyOffset>0 0 0</rpyOffset>
            <frameName>IMU_sensor</frameName>
            <initialOrientationAsReference>0</initialOrientationAsReference>
            <robotNamespace>/</robotNamespace>
          </plugin>
          <pose>0 0 0.161572 0 -0 0</pose>
          <imu/>
        </sensor>
        <gravity>1</gravity>
        <sensor name='kinect_v2_camera' type='depth'>
          <update_rate>30</update_rate>
          <camera>
            <horizontal_fov>1.0472</horizontal_fov>
            <image>
              <width>960</width>
              <height>540</height>
              <format>R8G8B8</format>
            </image>
            <clip>
              <near>0.05</near>
              <far>3</far>
            </clip>
          </camera>
          <plugin name='kinect_v2_controller' filename='libgazebo_ros_openni_kinect.so'>
            <baseline>0.2</baseline>
            <alwaysOn>1</alwaysOn>
            <updateRate>1.0</updateRate>
            <cameraName>kinect_v2_ir</cameraName>
            <imageTopicName>/kinect_v2/color/image_raw</imageTopicName>
            <cameraInfoTopicName>/kinect_v2/color/camera_info</cameraInfoTopicName>
            <depthImageTopicName>/kinect_v2/depth/image_raw</depthImageTopicName>
            <depthImageInfoTopicName>/kinect_v2/depth/camera_info</depthImageInfoTopicName>
            <pointCloudTopicName>/kinect_v2/depth/points</pointCloudTopicName>
            <frameName>kinect_v2</frameName>
            <pointCloudCutoff>0.5</pointCloudCutoff>
            <pointCloudCutoffMax>3.0</pointCloudCutoffMax>
            <distortionK1>0.00000001</distortionK1>
            <distortionK2>0.00000001</distortionK2>
            <distortionK3>0.00000001</distortionK3>
            <distortionT1>0.00000001</distortionT1>
            <distortionT2>0.00000001</distortionT2>
            <CxPrime>0</CxPrime>
            <Cx>0</Cx>
            <Cy>0</Cy>
            <focalLength>0</focalLength>
            <hackBaseline>0</hackBaseline>
            <robotNamespace>/</robotNamespace>
          </plugin>
          <pose>0.297 -0.05 0.203587 0 -0 0</pose>
        </sensor>
        <gravity>1</gravity>
        <sensor name='sick_LiDAR0_sensor' type='ray'>
          <visualize>0</visualize>
          <update_rate>40</update_rate>
          <ray>
            <scan>
              <horizontal>
                <samples>720</samples>
                <resolution>1</resolution>
                <min_angle>-2.35619</min_angle>
                <max_angle>2.35619</max_angle>
              </horizontal>
              <vertical>
                <samples>1</samples>
                <min_angle>0</min_angle>
                <max_angle>0</max_angle>
              </vertical>
            </scan>
            <range>
              <min>0.1</min>
              <max>30</max>
              <resolution>0.01</resolution>
            </range>
            <noise>
              <type>gaussian</type>
              <mean>0</mean>
              <stddev>0.01</stddev>
            </noise>
          </ray>
          <plugin name='gazebo_ros_head_hokuyo_controller' filename='libgazebo_ros_laser.so'>
            <topicName>/sick_s30b/laser/scan0</topicName>
            <frameName>sick_lidar0</frameName>
            <robotNamespace>/</robotNamespace>
          </plugin>
          <pose>0.33 0.175 0.277294 0 -0 0.7854</pose>
        </sensor>
        <self_collide>0</self_collide>
        <gravity>1</gravity>
        <sensor name='sick_LiDAR1_sensor' type='ray'>
          <visualize>0</visualize>
          <update_rate>40</update_rate>
          <ray>
            <scan>
              <horizontal>
                <samples>720</samples>
                <resolution>1</resolution>
                <min_angle>-2.35619</min_angle>
                <max_angle>2.35619</max_angle>
              </horizontal>
              <vertical>
                <samples>1</samples>
                <min_angle>0</min_angle>
                <max_angle>0</max_angle>
              </vertical>
            </scan>
            <range>
              <min>0.1</min>
              <max>30</max>
              <resolution>0.01</resolution>
            </range>
            <noise>
              <type>gaussian</type>
              <mean>0</mean>
              <stddev>0.01</stddev>
            </noise>
          </ray>
          <plugin name='gazebo_ros_head_hokuyo_controller' filename='libgazebo_ros_laser.so'>
            <topicName>/sick_s30b/laser/scan1</topicName>
            <frameName>sick_lidar1</frameName>
            <robotNamespace>/</robotNamespace>
          </plugin>
          <pose>-0.33 -0.175 0.277294 0 0 -2.35619</pose>
        </sensor>
        <sensor name='TeraRanger' type='ray'>
          <visualize>1</visualize>
          <update_rate>50</update_rate>
          <ray>
            <scan>
              <horizontal>
                <samples>10</samples>
                <resolution>1</resolution>
                <min_angle>-0.14835</min_angle>
                <max_angle>0.14835</max_angle>
              </horizontal>
              <vertical>
                <samples>10</samples>
                <resolution>1</resolution>
                <min_angle>-0.14835</min_angle>
                <max_angle>0.14835</max_angle>
              </vertical>
            </scan>
            <range>
              <min>0.03</min>
              <max>0.5</max>
              <resolution>0.01</resolution>
            </range>
          </ray>
          <plugin name='gazebo_ros_range' filename='libgazebo_ros_range.so'>
            <gaussianNoise>0.005</gaussianNoise>
            <alwaysOn>1</alwaysOn>
            <updateRate>50</updateRate>
            <topicName>/ultrasound_1</topicName>
            <frameName>ultrasound_1</frameName>
            <radiation>INFRARED</radiation>
            <fov>0.5</fov>
            <robotNamespace>/</robotNamespace>
          </plugin>
          <pose>0.4 0.15 0.111572 0 -0 0</pose>
        </sensor>
        <sensor name='TeraRanger' type='ray'>
          <visualize>1</visualize>
          <update_rate>50</update_rate>
          <ray>
            <scan>
              <horizontal>
                <samples>10</samples>
                <resolution>1</resolution>
                <min_angle>-0.14835</min_angle>
                <max_angle>0.14835</max_angle>
              </horizontal>
              <vertical>
                <samples>10</samples>
                <resolution>1</resolution>
                <min_angle>-0.14835</min_angle>
                <max_angle>0.14835</max_angle>
              </vertical>
            </scan>
            <range>
              <min>0.03</min>
              <max>0.5</max>
              <resolution>0.01</resolution>
            </range>
          </ray>
          <plugin name='gazebo_ros_range' filename='libgazebo_ros_range.so'>
            <gaussianNoise>0.005</gaussianNoise>
            <alwaysOn>1</alwaysOn>
            <updateRate>50</updateRate>
            <topicName>/ultrasound_2</topicName>
            <frameName>ultrasound_2</frameName>
            <radiation>INFRARED</radiation>
            <fov>0.5</fov>
            <robotNamespace>/</robotNamespace>
          </plugin>
          <pose>0.4 -0.15 0.111572 0 -0 0</pose>
        </sensor>
        <sensor name='TeraRanger' type='ray'>
          <visualize>1</visualize>
          <update_rate>50</update_rate>
          <ray>
            <scan>
              <horizontal>
                <samples>10</samples>
                <resolution>1</resolution>
                <min_angle>-0.14835</min_angle>
                <max_angle>0.14835</max_angle>
              </horizontal>
              <vertical>
                <samples>10</samples>
                <resolution>1</resolution>
                <min_angle>-0.14835</min_angle>
                <max_angle>0.14835</max_angle>
              </vertical>
            </scan>
            <range>
              <min>0.03</min>
              <max>0.5</max>
              <resolution>0.01</resolution>
            </range>
          </ray>
          <plugin name='gazebo_ros_range' filename='libgazebo_ros_range.so'>
            <gaussianNoise>0.005</gaussianNoise>
            <alwaysOn>1</alwaysOn>
            <updateRate>50</updateRate>
            <topicName>/ultrasound_3</topicName>
            <frameName>ultrasound_3</frameName>
            <radiation>INFRARED</radiation>
            <fov>0.5</fov>
            <robotNamespace>/</robotNamespace>
          </plugin>
          <pose>-0.4 0.15 0.111572 0 -0 -3.14159</pose>
        </sensor>
        <sensor name='TeraRanger' type='ray'>
          <visualize>1</visualize>
          <update_rate>50</update_rate>
          <ray>
            <scan>
              <horizontal>
                <samples>10</samples>
                <resolution>1</resolution>
                <min_angle>-0.14835</min_angle>
                <max_angle>0.14835</max_angle>
              </horizontal>
              <vertical>
                <samples>10</samples>
                <resolution>1</resolution>
                <min_angle>-0.14835</min_angle>
                <max_angle>0.14835</max_angle>
              </vertical>
            </scan>
            <range>
              <min>0.03</min>
              <max>0.5</max>
              <resolution>0.01</resolution>
            </range>
          </ray>
          <plugin name='gazebo_ros_range' filename='libgazebo_ros_range.so'>
            <gaussianNoise>0.005</gaussianNoise>
            <alwaysOn>1</alwaysOn>
            <updateRate>50</updateRate>
            <topicName>/ultrasound_4</topicName>
            <frameName>ultrasound_4</frameName>
            <radiation>INFRARED</radiation>
            <fov>0.5</fov>
            <robotNamespace>/</robotNamespace>
          </plugin>
          <pose>-0.4 -0.15 0.111572 0 -0 -3.14159</pose>
        </sensor>
        <enable_wind>0</enable_wind>
        <kinematic>0</kinematic>
      </link>
      <joint name='wheel_joint_1' type='revolute'>
        <pose relative_to='base_footprint'>-0.25 0.3 0.081572 -1.5708 0 0</pose>
        <parent>base_footprint</parent>
        <child>wheel_1</child>
        <axis>
          <xyz>0 0 1</xyz>
          <limit>
            <lower>-1e+16</lower>
            <upper>1e+16</upper>
          </limit>
          <dynamics>
            <damping>3</damping>
            <friction>5</friction>
            <spring_reference>0</spring_reference>
            <spring_stiffness>0</spring_stiffness>
          </dynamics>
        </axis>
      </joint>
      <link name='wheel_1'>
        <pose relative_to='wheel_joint_1'>0 0 0 0 -0 0</pose>
        <inertial>
          <pose>0.001 0 0 0 -0 0</pose>
          <mass>1.7</mass>
          <inertia>
            <ixx>0.00424805</ixx>
            <ixy>0</ixy>
            <ixz>0</ixz>
            <iyy>0.00424804</iyy>
            <iyz>0</iyz>
            <izz>0.00487997</izz>
          </inertia>
        </inertial>
        <collision name='wheel_1_collision'>
          <pose>0 0 0 0 -0 0</pose>
          <geometry>
            <mesh>
              <scale>0.01 0.01 0.01</scale>
              <uri>/home/jinmin/zm_ws/src/zm_robot/robot_description/meshes/mecanum_left_after.stl</uri>
            </mesh>
          </geometry>
          <surface>
            <contact>
              <ode>
                <kp>1e+50</kp>
                <kd>1e+50</kd>
              </ode>
            </contact>
            <friction>
              <ode>
                <mu>30</mu>
                <mu2>30</mu2>
              </ode>
              <torsional>
                <ode/>
              </torsional>
            </friction>
            <bounce/>
          </surface>
          <max_contacts>10</max_contacts>
        </collision>
        <visual name='wheel_1_visual'>
          <pose>0 0 0 0 -0 0</pose>
          <geometry>
            <mesh>
              <scale>0.01 0.01 0.01</scale>
              <uri>/home/jinmin/zm_ws/src/zm_robot/robot_description/meshes/mecanum_left_after.stl</uri>
            </mesh>
          </geometry>
          <material>
            <script>
              <name>Gazebo/White</name>
              <uri>file://media/materials/scripts/gazebo.material</uri>
            </script>
          </material>
        </visual>
        <self_collide>0</self_collide>
        <gravity>1</gravity>
        <enable_wind>0</enable_wind>
        <kinematic>0</kinematic>
      </link>
      <joint name='roller_1_1_joint' type='revolute'>
        <pose relative_to='wheel_1'>0 0.065 0 0.7854 -0 1.5708</pose>
        <parent>wheel_1</parent>
        <child>roller_1_1</child>
        <axis>
          <xyz>0 0 1</xyz>
          <limit>
            <lower>-1e+16</lower>
            <upper>1e+16</upper>
          </limit>
          <dynamics>
            <damping>0</damping>
            <friction>0</friction>
            <spring_reference>0</spring_reference>
            <spring_stiffness>0</spring_stiffness>
          </dynamics>
        </axis>
      </joint>
      <link name='roller_1_1'>
        <pose relative_to='roller_1_1_joint'>0 0 0 0 -0 0</pose>
        <inertial>
          <pose>0 0 0 0 -0 0</pose>
          <mass>0.124</mass>
          <inertia>
            <ixx>0.0051893</ixx>
            <ixy>0</ixy>
            <ixz>0</ixz>
            <iyy>0.0051893</iyy>
            <iyz>0</iyz>
            <izz>0.0013891</izz>
          </inertia>
        </inertial>
        <collision name='roller_1_1_collision'>
          <pose>0 0 0 0 -0 0</pose>
          <geometry>
            <mesh>
              <scale>0.01 0.01 0.01</scale>
              <uri>/home/jinmin/zm_ws/src/zm_robot/robot_description/meshes/mecanum_roller.stl</uri>
            </mesh>
          </geometry>
          <surface>
            <contact>
              <ode>
                <kp>1e+50</kp>
                <kd>1e+50</kd>
              </ode>
            </contact>
            <friction>
              <ode>
                <mu>30</mu>
                <mu2>30</mu2>
              </ode>
              <torsional>
                <ode/>
              </torsional>
            </friction>
            <bounce/>
          </surface>
          <max_contacts>10</max_contacts>
        </collision>
        <visual name='roller_1_1_visual'>
          <pose>0 0 0 0 -0 0</pose>
          <geometry>
            <mesh>
              <scale>0.01 0.01 0.01</scale>
              <uri>/home/jinmin/zm_ws/src/zm_robot/robot_description/meshes/mecanum_roller.stl</uri>
            </mesh>
          </geometry>
          <material>
            <script>
              <name>Gazebo/Black</name>
              <uri>file://media/materials/scripts/gazebo.material</uri>
            </script>
          </material>
        </visual>
        <self_collide>0</self_collide>
        <gravity>1</gravity>
        <enable_wind>0</enable_wind>
        <kinematic>0</kinematic>
      </link>
      <joint name='roller_1_2_joint' type='revolute'>
        <pose relative_to='wheel_1'>0.041781 0.049792 0 0.7854 -0 0.8727</pose>
        <parent>wheel_1</parent>
        <child>roller_1_2</child>
        <axis>
          <xyz>0 0 1</xyz>
          <limit>
            <lower>-1e+16</lower>
            <upper>1e+16</upper>
          </limit>
          <dynamics>
            <damping>0</damping>
            <friction>0</friction>
            <spring_reference>0</spring_reference>
            <spring_stiffness>0</spring_stiffness>
          </dynamics>
        </axis>
      </joint>
      <link name='roller_1_2'>
        <pose relative_to='roller_1_2_joint'>0 0 0 0 -0 0</pose>
        <inertial>
          <pose>0 0 0 0 -0 0</pose>
          <mass>0.124</mass>
          <inertia>
            <ixx>0.0051893</ixx>
            <ixy>0</ixy>
            <ixz>0</ixz>
            <iyy>0.0051893</iyy>
            <iyz>0</iyz>
            <izz>0.0013891</izz>
          </inertia>
        </inertial>
        <collision name='roller_1_2_collision'>
          <pose>0 0 0 0 -0 0</pose>
          <geometry>
            <mesh>
              <scale>0.01 0.01 0.01</scale>
              <uri>/home/jinmin/zm_ws/src/zm_robot/robot_description/meshes/mecanum_roller.stl</uri>
            </mesh>
          </geometry>
          <surface>
            <contact>
              <ode>
                <kp>1e+50</kp>
                <kd>1e+50</kd>
              </ode>
            </contact>
            <friction>
              <ode>
                <mu>30</mu>
                <mu2>30</mu2>
              </ode>
              <torsional>
                <ode/>
              </torsional>
            </friction>
            <bounce/>
          </surface>
          <max_contacts>10</max_contacts>
        </collision>
        <visual name='roller_1_2_visual'>
          <pose>0 0 0 0 -0 0</pose>
          <geometry>
            <mesh>
              <scale>0.01 0.01 0.01</scale>
              <uri>/home/jinmin/zm_ws/src/zm_robot/robot_description/meshes/mecanum_roller.stl</uri>
            </mesh>
          </geometry>
          <material>
            <script>
              <name>Gazebo/Black</name>
              <uri>file://media/materials/scripts/gazebo.material</uri>
            </script>
          </material>
        </visual>
        <self_collide>0</self_collide>
        <gravity>1</gravity>
        <enable_wind>0</enable_wind>
        <kinematic>0</kinematic>
      </link>
      <joint name='roller_1_3_joint' type='revolute'>
        <pose relative_to='wheel_1'>0.064012 0.011287 0 0.7854 -0 0.1746</pose>
        <parent>wheel_1</parent>
        <child>roller_1_3</child>
        <axis>
          <xyz>0 0 1</xyz>
          <limit>
            <lower>-1e+16</lower>
            <upper>1e+16</upper>
          </limit>
          <dynamics>
            <damping>0</damping>
            <friction>0</friction>
            <spring_reference>0</spring_reference>
            <spring_stiffness>0</spring_stiffness>
          </dynamics>
        </axis>
      </joint>
      <link name='roller_1_3'>
        <pose relative_to='roller_1_3_joint'>0 0 0 0 -0 0</pose>
        <inertial>
          <pose>0 0 0 0 -0 0</pose>
          <mass>0.124</mass>
          <inertia>
            <ixx>0.0051893</ixx>
            <ixy>0</ixy>
            <ixz>0</ixz>
            <iyy>0.0051893</iyy>
            <iyz>0</iyz>
            <izz>0.0013891</izz>
          </inertia>
        </inertial>
        <collision name='roller_1_3_collision'>
          <pose>0 0 0 0 -0 0</pose>
          <geometry>
            <mesh>
              <scale>0.01 0.01 0.01</scale>
              <uri>/home/jinmin/zm_ws/src/zm_robot/robot_description/meshes/mecanum_roller.stl</uri>
            </mesh>
          </geometry>
          <surface>
            <contact>
              <ode>
                <kp>1e+50</kp>
                <kd>1e+50</kd>
              </ode>
            </contact>
            <friction>
              <ode>
                <mu>30</mu>
                <mu2>30</mu2>
              </ode>
              <torsional>
                <ode/>
              </torsional>
            </friction>
            <bounce/>
          </surface>
          <max_contacts>10</max_contacts>
        </collision>
        <visual name='roller_1_3_visual'>
          <pose>0 0 0 0 -0 0</pose>
          <geometry>
            <mesh>
              <scale>0.01 0.01 0.01</scale>
              <uri>/home/jinmin/zm_ws/src/zm_robot/robot_description/meshes/mecanum_roller.stl</uri>
            </mesh>
          </geometry>
          <material>
            <script>
              <name>Gazebo/Black</name>
              <uri>file://media/materials/scripts/gazebo.material</uri>
            </script>
          </material>
        </visual>
        <self_collide>0</self_collide>
        <gravity>1</gravity>
        <enable_wind>0</enable_wind>
        <kinematic>0</kinematic>
      </link>
      <joint name='roller_1_4_joint' type='revolute'>
        <pose relative_to='wheel_1'>0.056291 -0.0325 0 0.7854 -0 -0.5235</pose>
        <parent>wheel_1</parent>
        <child>roller_1_4</child>
        <axis>
          <xyz>0 0 1</xyz>
          <limit>
            <lower>-1e+16</lower>
            <upper>1e+16</upper>
          </limit>
          <dynamics>
            <damping>0</damping>
            <friction>0</friction>
            <spring_reference>0</spring_reference>
            <spring_stiffness>0</spring_stiffness>
          </dynamics>
        </axis>
      </joint>
      <link name='roller_1_4'>
        <pose relative_to='roller_1_4_joint'>0 0 0 0 -0 0</pose>
        <inertial>
          <pose>0 0 0 0 -0 0</pose>
          <mass>0.124</mass>
          <inertia>
            <ixx>0.0051893</ixx>
            <ixy>0</ixy>
            <ixz>0</ixz>
            <iyy>0.0051893</iyy>
            <iyz>0</iyz>
            <izz>0.0013891</izz>
          </inertia>
        </inertial>
        <collision name='roller_1_4_collision'>
          <pose>0 0 0 0 -0 0</pose>
          <geometry>
            <mesh>
              <scale>0.01 0.01 0.01</scale>
              <uri>/home/jinmin/zm_ws/src/zm_robot/robot_description/meshes/mecanum_roller.stl</uri>
            </mesh>
          </geometry>
          <surface>
            <contact>
              <ode>
                <kp>1e+50</kp>
                <kd>1e+50</kd>
              </ode>
            </contact>
            <friction>
              <ode>
                <mu>30</mu>
                <mu2>30</mu2>
              </ode>
              <torsional>
                <ode/>
              </torsional>
            </friction>
            <bounce/>
          </surface>
          <max_contacts>10</max_contacts>
        </collision>
        <visual name='roller_1_4_visual'>
          <pose>0 0 0 0 -0 0</pose>
          <geometry>
            <mesh>
              <scale>0.01 0.01 0.01</scale>
              <uri>/home/jinmin/zm_ws/src/zm_robot/robot_description/meshes/mecanum_roller.stl</uri>
            </mesh>
          </geometry>
          <material>
            <script>
              <name>Gazebo/Black</name>
              <uri>file://media/materials/scripts/gazebo.material</uri>
            </script>
          </material>
        </visual>
        <self_collide>0</self_collide>
        <gravity>1</gravity>
        <enable_wind>0</enable_wind>
        <kinematic>0</kinematic>
      </link>
      <joint name='roller_1_5_joint' type='revolute'>
        <pose relative_to='wheel_1'>0.022231 -0.06108 0 0.7854 0 -1.2216</pose>
        <parent>wheel_1</parent>
        <child>roller_1_5</child>
        <axis>
          <xyz>0 0 1</xyz>
          <limit>
            <lower>-1e+16</lower>
            <upper>1e+16</upper>
          </limit>
          <dynamics>
            <damping>0</damping>
            <friction>0</friction>
            <spring_reference>0</spring_reference>
            <spring_stiffness>0</spring_stiffness>
          </dynamics>
        </axis>
      </joint>
      <link name='roller_1_5'>
        <pose relative_to='roller_1_5_joint'>0 0 0 0 -0 0</pose>
        <inertial>
          <pose>0 0 0 0 -0 0</pose>
          <mass>0.124</mass>
          <inertia>
            <ixx>0.0051893</ixx>
            <ixy>0</ixy>
            <ixz>0</ixz>
            <iyy>0.0051893</iyy>
            <iyz>0</iyz>
            <izz>0.0013891</izz>
          </inertia>
        </inertial>
        <collision name='roller_1_5_collision'>
          <pose>0 0 0 0 -0 0</pose>
          <geometry>
            <mesh>
              <scale>0.01 0.01 0.01</scale>
              <uri>/home/jinmin/zm_ws/src/zm_robot/robot_description/meshes/mecanum_roller.stl</uri>
            </mesh>
          </geometry>
          <surface>
            <contact>
              <ode>
                <kp>1e+50</kp>
                <kd>1e+50</kd>
              </ode>
            </contact>
            <friction>
              <ode>
                <mu>30</mu>
                <mu2>30</mu2>
              </ode>
              <torsional>
                <ode/>
              </torsional>
            </friction>
            <bounce/>
          </surface>
          <max_contacts>10</max_contacts>
        </collision>
        <visual name='roller_1_5_visual'>
          <pose>0 0 0 0 -0 0</pose>
          <geometry>
            <mesh>
              <scale>0.01 0.01 0.01</scale>
              <uri>/home/jinmin/zm_ws/src/zm_robot/robot_description/meshes/mecanum_roller.stl</uri>
            </mesh>
          </geometry>
          <material>
            <script>
              <name>Gazebo/Black</name>
              <uri>file://media/materials/scripts/gazebo.material</uri>
            </script>
          </material>
        </visual>
        <self_collide>0</self_collide>
        <gravity>1</gravity>
        <enable_wind>0</enable_wind>
        <kinematic>0</kinematic>
      </link>
      <joint name='roller_1_6_joint' type='revolute'>
        <pose relative_to='wheel_1'>-0.022231 -0.06108 0 0.7854 -0 -1.91999</pose>
        <parent>wheel_1</parent>
        <child>roller_1_6</child>
        <axis>
          <xyz>0 0 1</xyz>
          <limit>
            <lower>-1e+16</lower>
            <upper>1e+16</upper>
          </limit>
          <dynamics>
            <damping>0</damping>
            <friction>0</friction>
            <spring_reference>0</spring_reference>
            <spring_stiffness>0</spring_stiffness>
          </dynamics>
        </axis>
      </joint>
      <link name='roller_1_6'>
        <pose relative_to='roller_1_6_joint'>0 0 0 0 -0 0</pose>
        <inertial>
          <pose>0 0 0 0 -0 0</pose>
          <mass>0.124</mass>
          <inertia>
            <ixx>0.0051893</ixx>
            <ixy>0</ixy>
            <ixz>0</ixz>
            <iyy>0.0051893</iyy>
            <iyz>0</iyz>
            <izz>0.0013891</izz>
          </inertia>
        </inertial>
        <collision name='roller_1_6_collision'>
          <pose>0 0 0 0 -0 0</pose>
          <geometry>
            <mesh>
              <scale>0.01 0.01 0.01</scale>
              <uri>/home/jinmin/zm_ws/src/zm_robot/robot_description/meshes/mecanum_roller.stl</uri>
            </mesh>
          </geometry>
          <surface>
            <contact>
              <ode>
                <kp>1e+50</kp>
                <kd>1e+50</kd>
              </ode>
            </contact>
            <friction>
              <ode>
                <mu>30</mu>
                <mu2>30</mu2>
              </ode>
              <torsional>
                <ode/>
              </torsional>
            </friction>
            <bounce/>
          </surface>
          <max_contacts>10</max_contacts>
        </collision>
        <visual name='roller_1_6_visual'>
          <pose>0 0 0 0 -0 0</pose>
          <geometry>
            <mesh>
              <scale>0.01 0.01 0.01</scale>
              <uri>/home/jinmin/zm_ws/src/zm_robot/robot_description/meshes/mecanum_roller.stl</uri>
            </mesh>
          </geometry>
          <material>
            <script>
              <name>Gazebo/Black</name>
              <uri>file://media/materials/scripts/gazebo.material</uri>
            </script>
          </material>
        </visual>
        <self_collide>0</self_collide>
        <gravity>1</gravity>
        <enable_wind>0</enable_wind>
        <kinematic>0</kinematic>
      </link>
      <joint name='roller_1_7_joint' type='revolute'>
        <pose relative_to='wheel_1'>-0.056291 -0.0325 0 0.7854 -0 -2.61809</pose>
        <parent>wheel_1</parent>
        <child>roller_1_7</child>
        <axis>
          <xyz>0 0 1</xyz>
          <limit>
            <lower>-1e+16</lower>
            <upper>1e+16</upper>
          </limit>
          <dynamics>
            <damping>0</damping>
            <friction>0</friction>
            <spring_reference>0</spring_reference>
            <spring_stiffness>0</spring_stiffness>
          </dynamics>
        </axis>
      </joint>
      <link name='roller_1_7'>
        <pose relative_to='roller_1_7_joint'>0 0 0 0 -0 0</pose>
        <inertial>
          <pose>0 0 0 0 -0 0</pose>
          <mass>0.124</mass>
          <inertia>
            <ixx>0.0051893</ixx>
            <ixy>0</ixy>
            <ixz>0</ixz>
            <iyy>0.0051893</iyy>
            <iyz>0</iyz>
            <izz>0.0013891</izz>
          </inertia>
        </inertial>
        <collision name='roller_1_7_collision'>
          <pose>0 0 0 0 -0 0</pose>
          <geometry>
            <mesh>
              <scale>0.01 0.01 0.01</scale>
              <uri>/home/jinmin/zm_ws/src/zm_robot/robot_description/meshes/mecanum_roller.stl</uri>
            </mesh>
          </geometry>
          <surface>
            <contact>
              <ode>
                <kp>1e+50</kp>
                <kd>1e+50</kd>
              </ode>
            </contact>
            <friction>
              <ode>
                <mu>30</mu>
                <mu2>30</mu2>
              </ode>
              <torsional>
                <ode/>
              </torsional>
            </friction>
            <bounce/>
          </surface>
          <max_contacts>10</max_contacts>
        </collision>
        <visual name='roller_1_7_visual'>
          <pose>0 0 0 0 -0 0</pose>
          <geometry>
            <mesh>
              <scale>0.01 0.01 0.01</scale>
              <uri>/home/jinmin/zm_ws/src/zm_robot/robot_description/meshes/mecanum_roller.stl</uri>
            </mesh>
          </geometry>
          <material>
            <script>
              <name>Gazebo/Black</name>
              <uri>file://media/materials/scripts/gazebo.material</uri>
            </script>
          </material>
        </visual>
        <self_collide>0</self_collide>
        <gravity>1</gravity>
        <enable_wind>0</enable_wind>
        <kinematic>0</kinematic>
      </link>
      <joint name='roller_1_8_joint' type='revolute'>
        <pose relative_to='wheel_1'>-0.064012 0.011287 0 0.7854 -0 2.967</pose>
        <parent>wheel_1</parent>
        <child>roller_1_8</child>
        <axis>
          <xyz>0 0 1</xyz>
          <limit>
            <lower>-1e+16</lower>
            <upper>1e+16</upper>
          </limit>
          <dynamics>
            <damping>0</damping>
            <friction>0</friction>
            <spring_reference>0</spring_reference>
            <spring_stiffness>0</spring_stiffness>
          </dynamics>
        </axis>
      </joint>
      <link name='roller_1_8'>
        <pose relative_to='roller_1_8_joint'>0 0 0 0 -0 0</pose>
        <inertial>
          <pose>0 0 0 0 -0 0</pose>
          <mass>0.124</mass>
          <inertia>
            <ixx>0.0051893</ixx>
            <ixy>0</ixy>
            <ixz>0</ixz>
            <iyy>0.0051893</iyy>
            <iyz>0</iyz>
            <izz>0.0013891</izz>
          </inertia>
        </inertial>
        <collision name='roller_1_8_collision'>
          <pose>0 0 0 0 -0 0</pose>
          <geometry>
            <mesh>
              <scale>0.01 0.01 0.01</scale>
              <uri>/home/jinmin/zm_ws/src/zm_robot/robot_description/meshes/mecanum_roller.stl</uri>
            </mesh>
          </geometry>
          <surface>
            <contact>
              <ode>
                <kp>1e+50</kp>
                <kd>1e+50</kd>
              </ode>
            </contact>
            <friction>
              <ode>
                <mu>30</mu>
                <mu2>30</mu2>
              </ode>
              <torsional>
                <ode/>
              </torsional>
            </friction>
            <bounce/>
          </surface>
          <max_contacts>10</max_contacts>
        </collision>
        <visual name='roller_1_8_visual'>
          <pose>0 0 0 0 -0 0</pose>
          <geometry>
            <mesh>
              <scale>0.01 0.01 0.01</scale>
              <uri>/home/jinmin/zm_ws/src/zm_robot/robot_description/meshes/mecanum_roller.stl</uri>
            </mesh>
          </geometry>
          <material>
            <script>
              <name>Gazebo/Black</name>
              <uri>file://media/materials/scripts/gazebo.material</uri>
            </script>
          </material>
        </visual>
        <self_collide>0</self_collide>
        <gravity>1</gravity>
        <enable_wind>0</enable_wind>
        <kinematic>0</kinematic>
      </link>
      <joint name='roller_1_9_joint' type='revolute'>
        <pose relative_to='wheel_1'>-0.041781 0.049792 0 0.7854 -0 2.2689</pose>
        <parent>wheel_1</parent>
        <child>roller_1_9</child>
        <axis>
          <xyz>0 0 1</xyz>
          <limit>
            <lower>-1e+16</lower>
            <upper>1e+16</upper>
          </limit>
          <dynamics>
            <damping>0</damping>
            <friction>0</friction>
            <spring_reference>0</spring_reference>
            <spring_stiffness>0</spring_stiffness>
          </dynamics>
        </axis>
      </joint>
      <link name='roller_1_9'>
        <pose relative_to='roller_1_9_joint'>0 0 0 0 -0 0</pose>
        <inertial>
          <pose>0 0 0 0 -0 0</pose>
          <mass>0.124</mass>
          <inertia>
            <ixx>0.0051893</ixx>
            <ixy>0</ixy>
            <ixz>0</ixz>
            <iyy>0.0051893</iyy>
            <iyz>0</iyz>
            <izz>0.0013891</izz>
          </inertia>
        </inertial>
        <collision name='roller_1_9_collision'>
          <pose>0 0 0 0 -0 0</pose>
          <geometry>
            <mesh>
              <scale>0.01 0.01 0.01</scale>
              <uri>/home/jinmin/zm_ws/src/zm_robot/robot_description/meshes/mecanum_roller.stl</uri>
            </mesh>
          </geometry>
          <surface>
            <contact>
              <ode>
                <kp>1e+50</kp>
                <kd>1e+50</kd>
              </ode>
            </contact>
            <friction>
              <ode>
                <mu>30</mu>
                <mu2>30</mu2>
              </ode>
              <torsional>
                <ode/>
              </torsional>
            </friction>
            <bounce/>
          </surface>
          <max_contacts>10</max_contacts>
        </collision>
        <visual name='roller_1_9_visual'>
          <pose>0 0 0 0 -0 0</pose>
          <geometry>
            <mesh>
              <scale>0.01 0.01 0.01</scale>
              <uri>/home/jinmin/zm_ws/src/zm_robot/robot_description/meshes/mecanum_roller.stl</uri>
            </mesh>
          </geometry>
          <material>
            <script>
              <name>Gazebo/Black</name>
              <uri>file://media/materials/scripts/gazebo.material</uri>
            </script>
          </material>
        </visual>
        <self_collide>0</self_collide>
        <gravity>1</gravity>
        <enable_wind>0</enable_wind>
        <kinematic>0</kinematic>
      </link>
      <joint name='wheel_joint_2' type='revolute'>
        <pose relative_to='base_footprint'>0.25 0.3 0.081572 -1.5708 0 0</pose>
        <parent>base_footprint</parent>
        <child>wheel_2</child>
        <axis>
          <xyz>0 0 1</xyz>
          <limit>
            <lower>-1e+16</lower>
            <upper>1e+16</upper>
          </limit>
          <dynamics>
            <damping>3</damping>
            <friction>5</friction>
            <spring_reference>0</spring_reference>
            <spring_stiffness>0</spring_stiffness>
          </dynamics>
        </axis>
      </joint>
      <link name='wheel_2'>
        <pose relative_to='wheel_joint_2'>0 0 0 0 -0 0</pose>
        <inertial>
          <pose>0.001 0 0 0 -0 0</pose>
          <mass>1.7</mass>
          <inertia>
            <ixx>0.00424805</ixx>
            <ixy>0</ixy>
            <ixz>0</ixz>
            <iyy>0.00424804</iyy>
            <iyz>0</iyz>
            <izz>0.00487997</izz>
          </inertia>
        </inertial>
        <collision name='wheel_2_collision'>
          <pose>0 0 0 0 -0 0</pose>
          <geometry>
            <mesh>
              <scale>0.01 0.01 0.01</scale>
              <uri>/home/jinmin/zm_ws/src/zm_robot/robot_description/meshes/mecanum_left_before.stl</uri>
            </mesh>
          </geometry>
          <surface>
            <contact>
              <ode>
                <kp>1e+50</kp>
                <kd>1e+50</kd>
              </ode>
            </contact>
            <friction>
              <ode>
                <mu>30</mu>
                <mu2>30</mu2>
              </ode>
              <torsional>
                <ode/>
              </torsional>
            </friction>
            <bounce/>
          </surface>
          <max_contacts>10</max_contacts>
        </collision>
        <visual name='wheel_2_visual'>
          <pose>0 0 0 0 -0 0</pose>
          <geometry>
            <mesh>
              <scale>0.01 0.01 0.01</scale>
              <uri>/home/jinmin/zm_ws/src/zm_robot/robot_description/meshes/mecanum_left_before.stl</uri>
            </mesh>
          </geometry>
          <material>
            <script>
              <name>Gazebo/White</name>
              <uri>file://media/materials/scripts/gazebo.material</uri>
            </script>
          </material>
        </visual>
        <self_collide>0</self_collide>
        <gravity>1</gravity>
        <enable_wind>0</enable_wind>
        <kinematic>0</kinematic>
      </link>
      <joint name='roller_2_1_joint' type='revolute'>
        <pose relative_to='wheel_2'>0.065 0 0 -0.7854 0 0</pose>
        <parent>wheel_2</parent>
        <child>roller_2_1</child>
        <axis>
          <xyz>0 0 1</xyz>
          <limit>
            <lower>-1e+16</lower>
            <upper>1e+16</upper>
          </limit>
          <dynamics>
            <damping>0</damping>
            <friction>0</friction>
            <spring_reference>0</spring_reference>
            <spring_stiffness>0</spring_stiffness>
          </dynamics>
        </axis>
      </joint>
      <link name='roller_2_1'>
        <pose relative_to='roller_2_1_joint'>0 0 0 0 -0 0</pose>
        <inertial>
          <pose>0 0 0 0 -0 0</pose>
          <mass>0.124</mass>
          <inertia>
            <ixx>0.0051893</ixx>
            <ixy>0</ixy>
            <ixz>0</ixz>
            <iyy>0.0051893</iyy>
            <iyz>0</iyz>
            <izz>0.0013891</izz>
          </inertia>
        </inertial>
        <collision name='roller_2_1_collision'>
          <pose>0 0 0 0 -0 0</pose>
          <geometry>
            <mesh>
              <scale>0.01 0.01 0.01</scale>
              <uri>/home/jinmin/zm_ws/src/zm_robot/robot_description/meshes/mecanum_roller.stl</uri>
            </mesh>
          </geometry>
          <surface>
            <contact>
              <ode>
                <kp>1e+50</kp>
                <kd>1e+50</kd>
              </ode>
            </contact>
            <friction>
              <ode>
                <mu>30</mu>
                <mu2>30</mu2>
              </ode>
              <torsional>
                <ode/>
              </torsional>
            </friction>
            <bounce/>
          </surface>
          <max_contacts>10</max_contacts>
        </collision>
        <visual name='roller_2_1_visual'>
          <pose>0 0 0 0 -0 0</pose>
          <geometry>
            <mesh>
              <scale>0.01 0.01 0.01</scale>
              <uri>/home/jinmin/zm_ws/src/zm_robot/robot_description/meshes/mecanum_roller.stl</uri>
            </mesh>
          </geometry>
          <material>
            <script>
              <name>Gazebo/Black</name>
              <uri>file://media/materials/scripts/gazebo.material</uri>
            </script>
          </material>
        </visual>
        <self_collide>0</self_collide>
        <gravity>1</gravity>
        <enable_wind>0</enable_wind>
        <kinematic>0</kinematic>
      </link>
      <joint name='roller_2_2_joint' type='revolute'>
        <pose relative_to='wheel_2'>0.049792 0.041781 0 -0.7854 0 0.6981</pose>
        <parent>wheel_2</parent>
        <child>roller_2_2</child>
        <axis>
          <xyz>0 0 1</xyz>
          <limit>
            <lower>-1e+16</lower>
            <upper>1e+16</upper>
          </limit>
          <dynamics>
            <damping>0</damping>
            <friction>0</friction>
            <spring_reference>0</spring_reference>
            <spring_stiffness>0</spring_stiffness>
          </dynamics>
        </axis>
      </joint>
      <link name='roller_2_2'>
        <pose relative_to='roller_2_2_joint'>0 0 0 0 -0 0</pose>
        <inertial>
          <pose>0 0 0 0 -0 0</pose>
          <mass>0.124</mass>
          <inertia>
            <ixx>0.0051893</ixx>
            <ixy>0</ixy>
            <ixz>0</ixz>
            <iyy>0.0051893</iyy>
            <iyz>0</iyz>
            <izz>0.0013891</izz>
          </inertia>
        </inertial>
        <collision name='roller_2_2_collision'>
          <pose>0 0 0 0 -0 0</pose>
          <geometry>
            <mesh>
              <scale>0.01 0.01 0.01</scale>
              <uri>/home/jinmin/zm_ws/src/zm_robot/robot_description/meshes/mecanum_roller.stl</uri>
            </mesh>
          </geometry>
          <surface>
            <contact>
              <ode>
                <kp>1e+50</kp>
                <kd>1e+50</kd>
              </ode>
            </contact>
            <friction>
              <ode>
                <mu>30</mu>
                <mu2>30</mu2>
              </ode>
              <torsional>
                <ode/>
              </torsional>
            </friction>
            <bounce/>
          </surface>
          <max_contacts>10</max_contacts>
        </collision>
        <visual name='roller_2_2_visual'>
          <pose>0 0 0 0 -0 0</pose>
          <geometry>
            <mesh>
              <scale>0.01 0.01 0.01</scale>
              <uri>/home/jinmin/zm_ws/src/zm_robot/robot_description/meshes/mecanum_roller.stl</uri>
            </mesh>
          </geometry>
          <material>
            <script>
              <name>Gazebo/Black</name>
              <uri>file://media/materials/scripts/gazebo.material</uri>
            </script>
          </material>
        </visual>
        <self_collide>0</self_collide>
        <gravity>1</gravity>
        <enable_wind>0</enable_wind>
        <kinematic>0</kinematic>
      </link>
      <joint name='roller_2_3_joint' type='revolute'>
        <pose relative_to='wheel_2'>0.011287 0.064012 0 -0.7854 -0 1.3962</pose>
        <parent>wheel_2</parent>
        <child>roller_2_3</child>
        <axis>
          <xyz>0 0 1</xyz>
          <limit>
            <lower>-1e+16</lower>
            <upper>1e+16</upper>
          </limit>
          <dynamics>
            <damping>0</damping>
            <friction>0</friction>
            <spring_reference>0</spring_reference>
            <spring_stiffness>0</spring_stiffness>
          </dynamics>
        </axis>
      </joint>
      <link name='roller_2_3'>
        <pose relative_to='roller_2_3_joint'>0 0 0 0 -0 0</pose>
        <inertial>
          <pose>0 0 0 0 -0 0</pose>
          <mass>0.124</mass>
          <inertia>
            <ixx>0.0051893</ixx>
            <ixy>0</ixy>
            <ixz>0</ixz>
            <iyy>0.0051893</iyy>
            <iyz>0</iyz>
            <izz>0.0013891</izz>
          </inertia>
        </inertial>
        <collision name='roller_2_3_collision'>
          <pose>0 0 0 0 -0 0</pose>
          <geometry>
            <mesh>
              <scale>0.01 0.01 0.01</scale>
              <uri>/home/jinmin/zm_ws/src/zm_robot/robot_description/meshes/mecanum_roller.stl</uri>
            </mesh>
          </geometry>
          <surface>
            <contact>
              <ode>
                <kp>1e+50</kp>
                <kd>1e+50</kd>
              </ode>
            </contact>
            <friction>
              <ode>
                <mu>30</mu>
                <mu2>30</mu2>
              </ode>
              <torsional>
                <ode/>
              </torsional>
            </friction>
            <bounce/>
          </surface>
          <max_contacts>10</max_contacts>
        </collision>
        <visual name='roller_2_3_visual'>
          <pose>0 0 0 0 -0 0</pose>
          <geometry>
            <mesh>
              <scale>0.01 0.01 0.01</scale>
              <uri>/home/jinmin/zm_ws/src/zm_robot/robot_description/meshes/mecanum_roller.stl</uri>
            </mesh>
          </geometry>
          <material>
            <script>
              <name>Gazebo/Black</name>
              <uri>file://media/materials/scripts/gazebo.material</uri>
            </script>
          </material>
        </visual>
        <self_collide>0</self_collide>
        <gravity>1</gravity>
        <enable_wind>0</enable_wind>
        <kinematic>0</kinematic>
      </link>
      <joint name='roller_2_4_joint' type='revolute'>
        <pose relative_to='wheel_2'>-0.0325 0.056291 0 -0.7854 0 2.0943</pose>
        <parent>wheel_2</parent>
        <child>roller_2_4</child>
        <axis>
          <xyz>0 0 1</xyz>
          <limit>
            <lower>-1e+16</lower>
            <upper>1e+16</upper>
          </limit>
          <dynamics>
            <damping>0</damping>
            <friction>0</friction>
            <spring_reference>0</spring_reference>
            <spring_stiffness>0</spring_stiffness>
          </dynamics>
        </axis>
      </joint>
      <link name='roller_2_4'>
        <pose relative_to='roller_2_4_joint'>0 0 0 0 -0 0</pose>
        <inertial>
          <pose>0 0 0 0 -0 0</pose>
          <mass>0.124</mass>
          <inertia>
            <ixx>0.0051893</ixx>
            <ixy>0</ixy>
            <ixz>0</ixz>
            <iyy>0.0051893</iyy>
            <iyz>0</iyz>
            <izz>0.0013891</izz>
          </inertia>
        </inertial>
        <collision name='roller_2_4_collision'>
          <pose>0 0 0 0 -0 0</pose>
          <geometry>
            <mesh>
              <scale>0.01 0.01 0.01</scale>
              <uri>/home/jinmin/zm_ws/src/zm_robot/robot_description/meshes/mecanum_roller.stl</uri>
            </mesh>
          </geometry>
          <surface>
            <contact>
              <ode>
                <kp>1e+50</kp>
                <kd>1e+50</kd>
              </ode>
            </contact>
            <friction>
              <ode>
                <mu>30</mu>
                <mu2>30</mu2>
              </ode>
              <torsional>
                <ode/>
              </torsional>
            </friction>
            <bounce/>
          </surface>
          <max_contacts>10</max_contacts>
        </collision>
        <visual name='roller_2_4_visual'>
          <pose>0 0 0 0 -0 0</pose>
          <geometry>
            <mesh>
              <scale>0.01 0.01 0.01</scale>
              <uri>/home/jinmin/zm_ws/src/zm_robot/robot_description/meshes/mecanum_roller.stl</uri>
            </mesh>
          </geometry>
          <material>
            <script>
              <name>Gazebo/Black</name>
              <uri>file://media/materials/scripts/gazebo.material</uri>
            </script>
          </material>
        </visual>
        <self_collide>0</self_collide>
        <gravity>1</gravity>
        <enable_wind>0</enable_wind>
        <kinematic>0</kinematic>
      </link>
      <joint name='roller_2_5_joint' type='revolute'>
        <pose relative_to='wheel_2'>-0.06108 0.022231 0 -0.7854 -0 2.7924</pose>
        <parent>wheel_2</parent>
        <child>roller_2_5</child>
        <axis>
          <xyz>0 0 1</xyz>
          <limit>
            <lower>-1e+16</lower>
            <upper>1e+16</upper>
          </limit>
          <dynamics>
            <damping>0</damping>
            <friction>0</friction>
            <spring_reference>0</spring_reference>
            <spring_stiffness>0</spring_stiffness>
          </dynamics>
        </axis>
      </joint>
      <link name='roller_2_5'>
        <pose relative_to='roller_2_5_joint'>0 0 0 0 -0 0</pose>
        <inertial>
          <pose>0 0 0 0 -0 0</pose>
          <mass>0.124</mass>
          <inertia>
            <ixx>0.0051893</ixx>
            <ixy>0</ixy>
            <ixz>0</ixz>
            <iyy>0.0051893</iyy>
            <iyz>0</iyz>
            <izz>0.0013891</izz>
          </inertia>
        </inertial>
        <collision name='roller_2_5_collision'>
          <pose>0 0 0 0 -0 0</pose>
          <geometry>
            <mesh>
              <scale>0.01 0.01 0.01</scale>
              <uri>/home/jinmin/zm_ws/src/zm_robot/robot_description/meshes/mecanum_roller.stl</uri>
            </mesh>
          </geometry>
          <surface>
            <contact>
              <ode>
                <kp>1e+50</kp>
                <kd>1e+50</kd>
              </ode>
            </contact>
            <friction>
              <ode>
                <mu>30</mu>
                <mu2>30</mu2>
              </ode>
              <torsional>
                <ode/>
              </torsional>
            </friction>
            <bounce/>
          </surface>
          <max_contacts>10</max_contacts>
        </collision>
        <visual name='roller_2_5_visual'>
          <pose>0 0 0 0 -0 0</pose>
          <geometry>
            <mesh>
              <scale>0.01 0.01 0.01</scale>
              <uri>/home/jinmin/zm_ws/src/zm_robot/robot_description/meshes/mecanum_roller.stl</uri>
            </mesh>
          </geometry>
          <material>
            <script>
              <name>Gazebo/Black</name>
              <uri>file://media/materials/scripts/gazebo.material</uri>
            </script>
          </material>
        </visual>
        <self_collide>0</self_collide>
        <gravity>1</gravity>
        <enable_wind>0</enable_wind>
        <kinematic>0</kinematic>
      </link>
      <joint name='roller_2_6_joint' type='revolute'>
        <pose relative_to='wheel_2'>-0.06108 -0.022231 0 -0.7854 -0 -2.7924</pose>
        <parent>wheel_2</parent>
        <child>roller_2_6</child>
        <axis>
          <xyz>0 0 1</xyz>
          <limit>
            <lower>-1e+16</lower>
            <upper>1e+16</upper>
          </limit>
          <dynamics>
            <damping>0</damping>
            <friction>0</friction>
            <spring_reference>0</spring_reference>
            <spring_stiffness>0</spring_stiffness>
          </dynamics>
        </axis>
      </joint>
      <link name='roller_2_6'>
        <pose relative_to='roller_2_6_joint'>0 0 0 0 -0 0</pose>
        <inertial>
          <pose>0 0 0 0 -0 0</pose>
          <mass>0.124</mass>
          <inertia>
            <ixx>0.0051893</ixx>
            <ixy>0</ixy>
            <ixz>0</ixz>
            <iyy>0.0051893</iyy>
            <iyz>0</iyz>
            <izz>0.0013891</izz>
          </inertia>
        </inertial>
        <collision name='roller_2_6_collision'>
          <pose>0 0 0 0 -0 0</pose>
          <geometry>
            <mesh>
              <scale>0.01 0.01 0.01</scale>
              <uri>/home/jinmin/zm_ws/src/zm_robot/robot_description/meshes/mecanum_roller.stl</uri>
            </mesh>
          </geometry>
          <surface>
            <contact>
              <ode>
                <kp>1e+50</kp>
                <kd>1e+50</kd>
              </ode>
            </contact>
            <friction>
              <ode>
                <mu>30</mu>
                <mu2>30</mu2>
              </ode>
              <torsional>
                <ode/>
              </torsional>
            </friction>
            <bounce/>
          </surface>
          <max_contacts>10</max_contacts>
        </collision>
        <visual name='roller_2_6_visual'>
          <pose>0 0 0 0 -0 0</pose>
          <geometry>
            <mesh>
              <scale>0.01 0.01 0.01</scale>
              <uri>/home/jinmin/zm_ws/src/zm_robot/robot_description/meshes/mecanum_roller.stl</uri>
            </mesh>
          </geometry>
          <material>
            <script>
              <name>Gazebo/Black</name>
              <uri>file://media/materials/scripts/gazebo.material</uri>
            </script>
          </material>
        </visual>
        <self_collide>0</self_collide>
        <gravity>1</gravity>
        <enable_wind>0</enable_wind>
        <kinematic>0</kinematic>
      </link>
      <joint name='roller_2_7_joint' type='revolute'>
        <pose relative_to='wheel_2'>-0.0325 -0.056291 0 -0.7854 -0 -2.0943</pose>
        <parent>wheel_2</parent>
        <child>roller_2_7</child>
        <axis>
          <xyz>0 0 1</xyz>
          <limit>
            <lower>-1e+16</lower>
            <upper>1e+16</upper>
          </limit>
          <dynamics>
            <damping>0</damping>
            <friction>0</friction>
            <spring_reference>0</spring_reference>
            <spring_stiffness>0</spring_stiffness>
          </dynamics>
        </axis>
      </joint>
      <link name='roller_2_7'>
        <pose relative_to='roller_2_7_joint'>0 0 0 0 -0 0</pose>
        <inertial>
          <pose>0 0 0 0 -0 0</pose>
          <mass>0.124</mass>
          <inertia>
            <ixx>0.0051893</ixx>
            <ixy>0</ixy>
            <ixz>0</ixz>
            <iyy>0.0051893</iyy>
            <iyz>0</iyz>
            <izz>0.0013891</izz>
          </inertia>
        </inertial>
        <collision name='roller_2_7_collision'>
          <pose>0 0 0 0 -0 0</pose>
          <geometry>
            <mesh>
              <scale>0.01 0.01 0.01</scale>
              <uri>/home/jinmin/zm_ws/src/zm_robot/robot_description/meshes/mecanum_roller.stl</uri>
            </mesh>
          </geometry>
          <surface>
            <contact>
              <ode>
                <kp>1e+50</kp>
                <kd>1e+50</kd>
              </ode>
            </contact>
            <friction>
              <ode>
                <mu>30</mu>
                <mu2>30</mu2>
              </ode>
              <torsional>
                <ode/>
              </torsional>
            </friction>
            <bounce/>
          </surface>
          <max_contacts>10</max_contacts>
        </collision>
        <visual name='roller_2_7_visual'>
          <pose>0 0 0 0 -0 0</pose>
          <geometry>
            <mesh>
              <scale>0.01 0.01 0.01</scale>
              <uri>/home/jinmin/zm_ws/src/zm_robot/robot_description/meshes/mecanum_roller.stl</uri>
            </mesh>
          </geometry>
          <material>
            <script>
              <name>Gazebo/Black</name>
              <uri>file://media/materials/scripts/gazebo.material</uri>
            </script>
          </material>
        </visual>
        <self_collide>0</self_collide>
        <gravity>1</gravity>
        <enable_wind>0</enable_wind>
        <kinematic>0</kinematic>
      </link>
      <joint name='roller_2_8_joint' type='revolute'>
        <pose relative_to='wheel_2'>0.011287 -0.064012 0 -0.7854 0 -1.3962</pose>
        <parent>wheel_2</parent>
        <child>roller_2_8</child>
        <axis>
          <xyz>0 0 1</xyz>
          <limit>
            <lower>-1e+16</lower>
            <upper>1e+16</upper>
          </limit>
          <dynamics>
            <damping>0</damping>
            <friction>0</friction>
            <spring_reference>0</spring_reference>
            <spring_stiffness>0</spring_stiffness>
          </dynamics>
        </axis>
      </joint>
      <link name='roller_2_8'>
        <pose relative_to='roller_2_8_joint'>0 0 0 0 -0 0</pose>
        <inertial>
          <pose>0 0 0 0 -0 0</pose>
          <mass>0.124</mass>
          <inertia>
            <ixx>0.0051893</ixx>
            <ixy>0</ixy>
            <ixz>0</ixz>
            <iyy>0.0051893</iyy>
            <iyz>0</iyz>
            <izz>0.0013891</izz>
          </inertia>
        </inertial>
        <collision name='roller_2_8_collision'>
          <pose>0 0 0 0 -0 0</pose>
          <geometry>
            <mesh>
              <scale>0.01 0.01 0.01</scale>
              <uri>/home/jinmin/zm_ws/src/zm_robot/robot_description/meshes/mecanum_roller.stl</uri>
            </mesh>
          </geometry>
          <surface>
            <contact>
              <ode>
                <kp>1e+50</kp>
                <kd>1e+50</kd>
              </ode>
            </contact>
            <friction>
              <ode>
                <mu>30</mu>
                <mu2>30</mu2>
              </ode>
              <torsional>
                <ode/>
              </torsional>
            </friction>
            <bounce/>
          </surface>
          <max_contacts>10</max_contacts>
        </collision>
        <visual name='roller_2_8_visual'>
          <pose>0 0 0 0 -0 0</pose>
          <geometry>
            <mesh>
              <scale>0.01 0.01 0.01</scale>
              <uri>/home/jinmin/zm_ws/src/zm_robot/robot_description/meshes/mecanum_roller.stl</uri>
            </mesh>
          </geometry>
          <material>
            <script>
              <name>Gazebo/Black</name>
              <uri>file://media/materials/scripts/gazebo.material</uri>
            </script>
          </material>
        </visual>
        <self_collide>0</self_collide>
        <gravity>1</gravity>
        <enable_wind>0</enable_wind>
        <kinematic>0</kinematic>
      </link>
      <joint name='roller_2_9_joint' type='revolute'>
        <pose relative_to='wheel_2'>0.049792 -0.041781 0 -0.7854 -0 -0.6981</pose>
        <parent>wheel_2</parent>
        <child>roller_2_9</child>
        <axis>
          <xyz>0 0 1</xyz>
          <limit>
            <lower>-1e+16</lower>
            <upper>1e+16</upper>
          </limit>
          <dynamics>
            <damping>0</damping>
            <friction>0</friction>
            <spring_reference>0</spring_reference>
            <spring_stiffness>0</spring_stiffness>
          </dynamics>
        </axis>
      </joint>
      <link name='roller_2_9'>
        <pose relative_to='roller_2_9_joint'>0 0 0 0 -0 0</pose>
        <inertial>
          <pose>0 0 0 0 -0 0</pose>
          <mass>0.124</mass>
          <inertia>
            <ixx>0.0051893</ixx>
            <ixy>0</ixy>
            <ixz>0</ixz>
            <iyy>0.0051893</iyy>
            <iyz>0</iyz>
            <izz>0.0013891</izz>
          </inertia>
        </inertial>
        <collision name='roller_2_9_collision'>
          <pose>0 0 0 0 -0 0</pose>
          <geometry>
            <mesh>
              <scale>0.01 0.01 0.01</scale>
              <uri>/home/jinmin/zm_ws/src/zm_robot/robot_description/meshes/mecanum_roller.stl</uri>
            </mesh>
          </geometry>
          <surface>
            <contact>
              <ode>
                <kp>1e+50</kp>
                <kd>1e+50</kd>
              </ode>
            </contact>
            <friction>
              <ode>
                <mu>30</mu>
                <mu2>30</mu2>
              </ode>
              <torsional>
                <ode/>
              </torsional>
            </friction>
            <bounce/>
          </surface>
          <max_contacts>10</max_contacts>
        </collision>
        <visual name='roller_2_9_visual'>
          <pose>0 0 0 0 -0 0</pose>
          <geometry>
            <mesh>
              <scale>0.01 0.01 0.01</scale>
              <uri>/home/jinmin/zm_ws/src/zm_robot/robot_description/meshes/mecanum_roller.stl</uri>
            </mesh>
          </geometry>
          <material>
            <script>
              <name>Gazebo/Black</name>
              <uri>file://media/materials/scripts/gazebo.material</uri>
            </script>
          </material>
        </visual>
        <self_collide>0</self_collide>
        <gravity>1</gravity>
        <enable_wind>0</enable_wind>
        <kinematic>0</kinematic>
      </link>
      <joint name='wheel_joint_3' type='revolute'>
        <pose relative_to='base_footprint'>0.25 -0.3 0.081572 -1.5708 0 0</pose>
        <parent>base_footprint</parent>
        <child>wheel_3</child>
        <axis>
          <xyz>0 0 1</xyz>
          <limit>
            <lower>-1e+16</lower>
            <upper>1e+16</upper>
          </limit>
          <dynamics>
            <damping>3</damping>
            <friction>5</friction>
            <spring_reference>0</spring_reference>
            <spring_stiffness>0</spring_stiffness>
          </dynamics>
        </axis>
      </joint>
      <link name='wheel_3'>
        <pose relative_to='wheel_joint_3'>0 0 0 0 -0 0</pose>
        <inertial>
          <pose>-0.001 0 0 0 -0 0</pose>
          <mass>1.7</mass>
          <inertia>
            <ixx>0.00424805</ixx>
            <ixy>0</ixy>
            <ixz>0</ixz>
            <iyy>0.00424804</iyy>
            <iyz>0</iyz>
            <izz>-0.00487997</izz>
          </inertia>
        </inertial>
        <collision name='wheel_3_collision'>
          <pose>0 0 0 0 -0 0</pose>
          <geometry>
            <mesh>
              <scale>0.01 0.01 0.01</scale>
              <uri>/home/jinmin/zm_ws/src/zm_robot/robot_description/meshes/mecanum_right_before.stl</uri>
            </mesh>
          </geometry>
          <surface>
            <contact>
              <ode>
                <kp>1e+50</kp>
                <kd>1e+50</kd>
              </ode>
            </contact>
            <friction>
              <ode>
                <mu>30</mu>
                <mu2>30</mu2>
              </ode>
              <torsional>
                <ode/>
              </torsional>
            </friction>
            <bounce/>
          </surface>
          <max_contacts>10</max_contacts>
        </collision>
        <visual name='wheel_3_visual'>
          <pose>0 0 0 0 -0 0</pose>
          <geometry>
            <mesh>
              <scale>0.01 0.01 0.01</scale>
              <uri>/home/jinmin/zm_ws/src/zm_robot/robot_description/meshes/mecanum_right_before.stl</uri>
            </mesh>
          </geometry>
          <material>
            <script>
              <name>Gazebo/White</name>
              <uri>file://media/materials/scripts/gazebo.material</uri>
            </script>
          </material>
        </visual>
        <self_collide>0</self_collide>
        <gravity>1</gravity>
        <enable_wind>0</enable_wind>
        <kinematic>0</kinematic>
      </link>
      <joint name='roller_3_1_joint' type='revolute'>
        <pose relative_to='wheel_3'>0 0.065 0 0.7854 -0 1.5708</pose>
        <parent>wheel_3</parent>
        <child>roller_3_1</child>
        <axis>
          <xyz>0 0 1</xyz>
          <limit>
            <lower>-1e+16</lower>
            <upper>1e+16</upper>
          </limit>
          <dynamics>
            <damping>0</damping>
            <friction>0</friction>
            <spring_reference>0</spring_reference>
            <spring_stiffness>0</spring_stiffness>
          </dynamics>
        </axis>
      </joint>
      <link name='roller_3_1'>
        <pose relative_to='roller_3_1_joint'>0 0 0 0 -0 0</pose>
        <inertial>
          <pose>0 0 0 0 -0 0</pose>
          <mass>0.124</mass>
          <inertia>
            <ixx>0.0051893</ixx>
            <ixy>0</ixy>
            <ixz>0</ixz>
            <iyy>0.0051893</iyy>
            <iyz>0</iyz>
            <izz>0.0013891</izz>
          </inertia>
        </inertial>
        <collision name='roller_3_1_collision'>
          <pose>0 0 0 0 -0 0</pose>
          <geometry>
            <mesh>
              <scale>0.01 0.01 0.01</scale>
              <uri>/home/jinmin/zm_ws/src/zm_robot/robot_description/meshes/mecanum_roller.stl</uri>
            </mesh>
          </geometry>
          <surface>
            <contact>
              <ode>
                <kp>1e+50</kp>
                <kd>1e+50</kd>
              </ode>
            </contact>
            <friction>
              <ode>
                <mu>30</mu>
                <mu2>30</mu2>
              </ode>
              <torsional>
                <ode/>
              </torsional>
            </friction>
            <bounce/>
          </surface>
          <max_contacts>10</max_contacts>
        </collision>
        <visual name='roller_3_1_visual'>
          <pose>0 0 0 0 -0 0</pose>
          <geometry>
            <mesh>
              <scale>0.01 0.01 0.01</scale>
              <uri>/home/jinmin/zm_ws/src/zm_robot/robot_description/meshes/mecanum_roller.stl</uri>
            </mesh>
          </geometry>
          <material>
            <script>
              <name>Gazebo/Black</name>
              <uri>file://media/materials/scripts/gazebo.material</uri>
            </script>
          </material>
        </visual>
        <self_collide>0</self_collide>
        <gravity>1</gravity>
        <enable_wind>0</enable_wind>
        <kinematic>0</kinematic>
      </link>
      <joint name='roller_3_2_joint' type='revolute'>
        <pose relative_to='wheel_3'>0.041781 0.049792 0 0.7854 -0 0.8727</pose>
        <parent>wheel_3</parent>
        <child>roller_3_2</child>
        <axis>
          <xyz>0 0 1</xyz>
          <limit>
            <lower>-1e+16</lower>
            <upper>1e+16</upper>
          </limit>
          <dynamics>
            <damping>0</damping>
            <friction>0</friction>
            <spring_reference>0</spring_reference>
            <spring_stiffness>0</spring_stiffness>
          </dynamics>
        </axis>
      </joint>
      <link name='roller_3_2'>
        <pose relative_to='roller_3_2_joint'>0 0 0 0 -0 0</pose>
        <inertial>
          <pose>0 0 0 0 -0 0</pose>
          <mass>0.124</mass>
          <inertia>
            <ixx>0.0051893</ixx>
            <ixy>0</ixy>
            <ixz>0</ixz>
            <iyy>0.0051893</iyy>
            <iyz>0</iyz>
            <izz>0.0013891</izz>
          </inertia>
        </inertial>
        <collision name='roller_3_2_collision'>
          <pose>0 0 0 0 -0 0</pose>
          <geometry>
            <mesh>
              <scale>0.01 0.01 0.01</scale>
              <uri>/home/jinmin/zm_ws/src/zm_robot/robot_description/meshes/mecanum_roller.stl</uri>
            </mesh>
          </geometry>
          <surface>
            <contact>
              <ode>
                <kp>1e+50</kp>
                <kd>1e+50</kd>
              </ode>
            </contact>
            <friction>
              <ode>
                <mu>30</mu>
                <mu2>30</mu2>
              </ode>
              <torsional>
                <ode/>
              </torsional>
            </friction>
            <bounce/>
          </surface>
          <max_contacts>10</max_contacts>
        </collision>
        <visual name='roller_3_2_visual'>
          <pose>0 0 0 0 -0 0</pose>
          <geometry>
            <mesh>
              <scale>0.01 0.01 0.01</scale>
              <uri>/home/jinmin/zm_ws/src/zm_robot/robot_description/meshes/mecanum_roller.stl</uri>
            </mesh>
          </geometry>
          <material>
            <script>
              <name>Gazebo/Black</name>
              <uri>file://media/materials/scripts/gazebo.material</uri>
            </script>
          </material>
        </visual>
        <self_collide>0</self_collide>
        <gravity>1</gravity>
        <enable_wind>0</enable_wind>
        <kinematic>0</kinematic>
      </link>
      <joint name='roller_3_3_joint' type='revolute'>
        <pose relative_to='wheel_3'>0.064012 0.011287 0 0.7854 -0 0.1746</pose>
        <parent>wheel_3</parent>
        <child>roller_3_3</child>
        <axis>
          <xyz>0 0 1</xyz>
          <limit>
            <lower>-1e+16</lower>
            <upper>1e+16</upper>
          </limit>
          <dynamics>
            <damping>0</damping>
            <friction>0</friction>
            <spring_reference>0</spring_reference>
            <spring_stiffness>0</spring_stiffness>
          </dynamics>
        </axis>
      </joint>
      <link name='roller_3_3'>
        <pose relative_to='roller_3_3_joint'>0 0 0 0 -0 0</pose>
        <inertial>
          <pose>0 0 0 0 -0 0</pose>
          <mass>0.124</mass>
          <inertia>
            <ixx>0.0051893</ixx>
            <ixy>0</ixy>
            <ixz>0</ixz>
            <iyy>0.0051893</iyy>
            <iyz>0</iyz>
            <izz>0.0013891</izz>
          </inertia>
        </inertial>
        <collision name='roller_3_3_collision'>
          <pose>0 0 0 0 -0 0</pose>
          <geometry>
            <mesh>
              <scale>0.01 0.01 0.01</scale>
              <uri>/home/jinmin/zm_ws/src/zm_robot/robot_description/meshes/mecanum_roller.stl</uri>
            </mesh>
          </geometry>
          <surface>
            <contact>
              <ode>
                <kp>1e+50</kp>
                <kd>1e+50</kd>
              </ode>
            </contact>
            <friction>
              <ode>
                <mu>30</mu>
                <mu2>30</mu2>
              </ode>
              <torsional>
                <ode/>
              </torsional>
            </friction>
            <bounce/>
          </surface>
          <max_contacts>10</max_contacts>
        </collision>
        <visual name='roller_3_3_visual'>
          <pose>0 0 0 0 -0 0</pose>
          <geometry>
            <mesh>
              <scale>0.01 0.01 0.01</scale>
              <uri>/home/jinmin/zm_ws/src/zm_robot/robot_description/meshes/mecanum_roller.stl</uri>
            </mesh>
          </geometry>
          <material>
            <script>
              <name>Gazebo/Black</name>
              <uri>file://media/materials/scripts/gazebo.material</uri>
            </script>
          </material>
        </visual>
        <self_collide>0</self_collide>
        <gravity>1</gravity>
        <enable_wind>0</enable_wind>
        <kinematic>0</kinematic>
      </link>
      <joint name='roller_3_4_joint' type='revolute'>
        <pose relative_to='wheel_3'>0.056291 -0.0325 0 0.7854 -0 -0.5235</pose>
        <parent>wheel_3</parent>
        <child>roller_3_4</child>
        <axis>
          <xyz>0 0 1</xyz>
          <limit>
            <lower>-1e+16</lower>
            <upper>1e+16</upper>
          </limit>
          <dynamics>
            <damping>0</damping>
            <friction>0</friction>
            <spring_reference>0</spring_reference>
            <spring_stiffness>0</spring_stiffness>
          </dynamics>
        </axis>
      </joint>
      <link name='roller_3_4'>
        <pose relative_to='roller_3_4_joint'>0 0 0 0 -0 0</pose>
        <inertial>
          <pose>0 0 0 0 -0 0</pose>
          <mass>0.124</mass>
          <inertia>
            <ixx>0.0051893</ixx>
            <ixy>0</ixy>
            <ixz>0</ixz>
            <iyy>0.0051893</iyy>
            <iyz>0</iyz>
            <izz>0.0013891</izz>
          </inertia>
        </inertial>
        <collision name='roller_3_4_collision'>
          <pose>0 0 0 0 -0 0</pose>
          <geometry>
            <mesh>
              <scale>0.01 0.01 0.01</scale>
              <uri>/home/jinmin/zm_ws/src/zm_robot/robot_description/meshes/mecanum_roller.stl</uri>
            </mesh>
          </geometry>
          <surface>
            <contact>
              <ode>
                <kp>1e+50</kp>
                <kd>1e+50</kd>
              </ode>
            </contact>
            <friction>
              <ode>
                <mu>30</mu>
                <mu2>30</mu2>
              </ode>
              <torsional>
                <ode/>
              </torsional>
            </friction>
            <bounce/>
          </surface>
          <max_contacts>10</max_contacts>
        </collision>
        <visual name='roller_3_4_visual'>
          <pose>0 0 0 0 -0 0</pose>
          <geometry>
            <mesh>
              <scale>0.01 0.01 0.01</scale>
              <uri>/home/jinmin/zm_ws/src/zm_robot/robot_description/meshes/mecanum_roller.stl</uri>
            </mesh>
          </geometry>
          <material>
            <script>
              <name>Gazebo/Black</name>
              <uri>file://media/materials/scripts/gazebo.material</uri>
            </script>
          </material>
        </visual>
        <self_collide>0</self_collide>
        <gravity>1</gravity>
        <enable_wind>0</enable_wind>
        <kinematic>0</kinematic>
      </link>
      <joint name='roller_3_5_joint' type='revolute'>
        <pose relative_to='wheel_3'>0.022231 -0.06108 0 0.7854 0 -1.2216</pose>
        <parent>wheel_3</parent>
        <child>roller_3_5</child>
        <axis>
          <xyz>0 0 1</xyz>
          <limit>
            <lower>-1e+16</lower>
            <upper>1e+16</upper>
          </limit>
          <dynamics>
            <damping>0</damping>
            <friction>0</friction>
            <spring_reference>0</spring_reference>
            <spring_stiffness>0</spring_stiffness>
          </dynamics>
        </axis>
      </joint>
      <link name='roller_3_5'>
        <pose relative_to='roller_3_5_joint'>0 0 0 0 -0 0</pose>
        <inertial>
          <pose>0 0 0 0 -0 0</pose>
          <mass>0.124</mass>
          <inertia>
            <ixx>0.0051893</ixx>
            <ixy>0</ixy>
            <ixz>0</ixz>
            <iyy>0.0051893</iyy>
            <iyz>0</iyz>
            <izz>0.0013891</izz>
          </inertia>
        </inertial>
        <collision name='roller_3_5_collision'>
          <pose>0 0 0 0 -0 0</pose>
          <geometry>
            <mesh>
              <scale>0.01 0.01 0.01</scale>
              <uri>/home/jinmin/zm_ws/src/zm_robot/robot_description/meshes/mecanum_roller.stl</uri>
            </mesh>
          </geometry>
          <surface>
            <contact>
              <ode>
                <kp>1e+50</kp>
                <kd>1e+50</kd>
              </ode>
            </contact>
            <friction>
              <ode>
                <mu>30</mu>
                <mu2>30</mu2>
              </ode>
              <torsional>
                <ode/>
              </torsional>
            </friction>
            <bounce/>
          </surface>
          <max_contacts>10</max_contacts>
        </collision>
        <visual name='roller_3_5_visual'>
          <pose>0 0 0 0 -0 0</pose>
          <geometry>
            <mesh>
              <scale>0.01 0.01 0.01</scale>
              <uri>/home/jinmin/zm_ws/src/zm_robot/robot_description/meshes/mecanum_roller.stl</uri>
            </mesh>
          </geometry>
          <material>
            <script>
              <name>Gazebo/Black</name>
              <uri>file://media/materials/scripts/gazebo.material</uri>
            </script>
          </material>
        </visual>
        <self_collide>0</self_collide>
        <gravity>1</gravity>
        <enable_wind>0</enable_wind>
        <kinematic>0</kinematic>
      </link>
      <joint name='roller_3_6_joint' type='revolute'>
        <pose relative_to='wheel_3'>-0.022231 -0.06108 0 0.7854 -0 -1.91999</pose>
        <parent>wheel_3</parent>
        <child>roller_3_6</child>
        <axis>
          <xyz>0 0 1</xyz>
          <limit>
            <lower>-1e+16</lower>
            <upper>1e+16</upper>
          </limit>
          <dynamics>
            <damping>0</damping>
            <friction>0</friction>
            <spring_reference>0</spring_reference>
            <spring_stiffness>0</spring_stiffness>
          </dynamics>
        </axis>
      </joint>
      <link name='roller_3_6'>
        <pose relative_to='roller_3_6_joint'>0 0 0 0 -0 0</pose>
        <inertial>
          <pose>0 0 0 0 -0 0</pose>
          <mass>0.124</mass>
          <inertia>
            <ixx>0.0051893</ixx>
            <ixy>0</ixy>
            <ixz>0</ixz>
            <iyy>0.0051893</iyy>
            <iyz>0</iyz>
            <izz>0.0013891</izz>
          </inertia>
        </inertial>
        <collision name='roller_3_6_collision'>
          <pose>0 0 0 0 -0 0</pose>
          <geometry>
            <mesh>
              <scale>0.01 0.01 0.01</scale>
              <uri>/home/jinmin/zm_ws/src/zm_robot/robot_description/meshes/mecanum_roller.stl</uri>
            </mesh>
          </geometry>
          <surface>
            <contact>
              <ode>
                <kp>1e+50</kp>
                <kd>1e+50</kd>
              </ode>
            </contact>
            <friction>
              <ode>
                <mu>30</mu>
                <mu2>30</mu2>
              </ode>
              <torsional>
                <ode/>
              </torsional>
            </friction>
            <bounce/>
          </surface>
          <max_contacts>10</max_contacts>
        </collision>
        <visual name='roller_3_6_visual'>
          <pose>0 0 0 0 -0 0</pose>
          <geometry>
            <mesh>
              <scale>0.01 0.01 0.01</scale>
              <uri>/home/jinmin/zm_ws/src/zm_robot/robot_description/meshes/mecanum_roller.stl</uri>
            </mesh>
          </geometry>
          <material>
            <script>
              <name>Gazebo/Black</name>
              <uri>file://media/materials/scripts/gazebo.material</uri>
            </script>
          </material>
        </visual>
        <self_collide>0</self_collide>
        <gravity>1</gravity>
        <enable_wind>0</enable_wind>
        <kinematic>0</kinematic>
      </link>
      <joint name='roller_3_7_joint' type='revolute'>
        <pose relative_to='wheel_3'>-0.056291 -0.0325 0 0.7854 -0 -2.61809</pose>
        <parent>wheel_3</parent>
        <child>roller_3_7</child>
        <axis>
          <xyz>0 0 1</xyz>
          <limit>
            <lower>-1e+16</lower>
            <upper>1e+16</upper>
          </limit>
          <dynamics>
            <damping>0</damping>
            <friction>0</friction>
            <spring_reference>0</spring_reference>
            <spring_stiffness>0</spring_stiffness>
          </dynamics>
        </axis>
      </joint>
      <link name='roller_3_7'>
        <pose relative_to='roller_3_7_joint'>0 0 0 0 -0 0</pose>
        <inertial>
          <pose>0 0 0 0 -0 0</pose>
          <mass>0.124</mass>
          <inertia>
            <ixx>0.0051893</ixx>
            <ixy>0</ixy>
            <ixz>0</ixz>
            <iyy>0.0051893</iyy>
            <iyz>0</iyz>
            <izz>0.0013891</izz>
          </inertia>
        </inertial>
        <collision name='roller_3_7_collision'>
          <pose>0 0 0 0 -0 0</pose>
          <geometry>
            <mesh>
              <scale>0.01 0.01 0.01</scale>
              <uri>/home/jinmin/zm_ws/src/zm_robot/robot_description/meshes/mecanum_roller.stl</uri>
            </mesh>
          </geometry>
          <surface>
            <contact>
              <ode>
                <kp>1e+50</kp>
                <kd>1e+50</kd>
              </ode>
            </contact>
            <friction>
              <ode>
                <mu>30</mu>
                <mu2>30</mu2>
              </ode>
              <torsional>
                <ode/>
              </torsional>
            </friction>
            <bounce/>
          </surface>
          <max_contacts>10</max_contacts>
        </collision>
        <visual name='roller_3_7_visual'>
          <pose>0 0 0 0 -0 0</pose>
          <geometry>
            <mesh>
              <scale>0.01 0.01 0.01</scale>
              <uri>/home/jinmin/zm_ws/src/zm_robot/robot_description/meshes/mecanum_roller.stl</uri>
            </mesh>
          </geometry>
          <material>
            <script>
              <name>Gazebo/Black</name>
              <uri>file://media/materials/scripts/gazebo.material</uri>
            </script>
          </material>
        </visual>
        <self_collide>0</self_collide>
        <gravity>1</gravity>
        <enable_wind>0</enable_wind>
        <kinematic>0</kinematic>
      </link>
      <joint name='roller_3_8_joint' type='revolute'>
        <pose relative_to='wheel_3'>-0.064012 0.011287 0 0.7854 -0 2.967</pose>
        <parent>wheel_3</parent>
        <child>roller_3_8</child>
        <axis>
          <xyz>0 0 1</xyz>
          <limit>
            <lower>-1e+16</lower>
            <upper>1e+16</upper>
          </limit>
          <dynamics>
            <damping>0</damping>
            <friction>0</friction>
            <spring_reference>0</spring_reference>
            <spring_stiffness>0</spring_stiffness>
          </dynamics>
        </axis>
      </joint>
      <link name='roller_3_8'>
        <pose relative_to='roller_3_8_joint'>0 0 0 0 -0 0</pose>
        <inertial>
          <pose>0 0 0 0 -0 0</pose>
          <mass>0.124</mass>
          <inertia>
            <ixx>0.0051893</ixx>
            <ixy>0</ixy>
            <ixz>0</ixz>
            <iyy>0.0051893</iyy>
            <iyz>0</iyz>
            <izz>0.0013891</izz>
          </inertia>
        </inertial>
        <collision name='roller_3_8_collision'>
          <pose>0 0 0 0 -0 0</pose>
          <geometry>
            <mesh>
              <scale>0.01 0.01 0.01</scale>
              <uri>/home/jinmin/zm_ws/src/zm_robot/robot_description/meshes/mecanum_roller.stl</uri>
            </mesh>
          </geometry>
          <surface>
            <contact>
              <ode>
                <kp>1e+50</kp>
                <kd>1e+50</kd>
              </ode>
            </contact>
            <friction>
              <ode>
                <mu>30</mu>
                <mu2>30</mu2>
              </ode>
              <torsional>
                <ode/>
              </torsional>
            </friction>
            <bounce/>
          </surface>
          <max_contacts>10</max_contacts>
        </collision>
        <visual name='roller_3_8_visual'>
          <pose>0 0 0 0 -0 0</pose>
          <geometry>
            <mesh>
              <scale>0.01 0.01 0.01</scale>
              <uri>/home/jinmin/zm_ws/src/zm_robot/robot_description/meshes/mecanum_roller.stl</uri>
            </mesh>
          </geometry>
          <material>
            <script>
              <name>Gazebo/Black</name>
              <uri>file://media/materials/scripts/gazebo.material</uri>
            </script>
          </material>
        </visual>
        <self_collide>0</self_collide>
        <gravity>1</gravity>
        <enable_wind>0</enable_wind>
        <kinematic>0</kinematic>
      </link>
      <joint name='roller_3_9_joint' type='revolute'>
        <pose relative_to='wheel_3'>-0.041781 0.049792 0 0.7854 -0 2.2689</pose>
        <parent>wheel_3</parent>
        <child>roller_3_9</child>
        <axis>
          <xyz>0 0 1</xyz>
          <limit>
            <lower>-1e+16</lower>
            <upper>1e+16</upper>
          </limit>
          <dynamics>
            <damping>0</damping>
            <friction>0</friction>
            <spring_reference>0</spring_reference>
            <spring_stiffness>0</spring_stiffness>
          </dynamics>
        </axis>
      </joint>
      <link name='roller_3_9'>
        <pose relative_to='roller_3_9_joint'>0 0 0 0 -0 0</pose>
        <inertial>
          <pose>0 0 0 0 -0 0</pose>
          <mass>0.124</mass>
          <inertia>
            <ixx>0.0051893</ixx>
            <ixy>0</ixy>
            <ixz>0</ixz>
            <iyy>0.0051893</iyy>
            <iyz>0</iyz>
            <izz>0.0013891</izz>
          </inertia>
        </inertial>
        <collision name='roller_3_9_collision'>
          <pose>0 0 0 0 -0 0</pose>
          <geometry>
            <mesh>
              <scale>0.01 0.01 0.01</scale>
              <uri>/home/jinmin/zm_ws/src/zm_robot/robot_description/meshes/mecanum_roller.stl</uri>
            </mesh>
          </geometry>
          <surface>
            <contact>
              <ode>
                <kp>1e+50</kp>
                <kd>1e+50</kd>
              </ode>
            </contact>
            <friction>
              <ode>
                <mu>30</mu>
                <mu2>30</mu2>
              </ode>
              <torsional>
                <ode/>
              </torsional>
            </friction>
            <bounce/>
          </surface>
          <max_contacts>10</max_contacts>
        </collision>
        <visual name='roller_3_9_visual'>
          <pose>0 0 0 0 -0 0</pose>
          <geometry>
            <mesh>
              <scale>0.01 0.01 0.01</scale>
              <uri>/home/jinmin/zm_ws/src/zm_robot/robot_description/meshes/mecanum_roller.stl</uri>
            </mesh>
          </geometry>
          <material>
            <script>
              <name>Gazebo/Black</name>
              <uri>file://media/materials/scripts/gazebo.material</uri>
            </script>
          </material>
        </visual>
        <self_collide>0</self_collide>
        <gravity>1</gravity>
        <enable_wind>0</enable_wind>
        <kinematic>0</kinematic>
      </link>
      <joint name='wheel_joint_4' type='revolute'>
        <pose relative_to='base_footprint'>-0.25 -0.3 0.081572 -1.5708 0 0</pose>
        <parent>base_footprint</parent>
        <child>wheel_4</child>
        <axis>
          <xyz>0 0 1</xyz>
          <limit>
            <lower>-1e+16</lower>
            <upper>1e+16</upper>
          </limit>
          <dynamics>
            <damping>3</damping>
            <friction>5</friction>
            <spring_reference>0</spring_reference>
            <spring_stiffness>0</spring_stiffness>
          </dynamics>
        </axis>
      </joint>
      <link name='wheel_4'>
        <pose relative_to='wheel_joint_4'>0 0 0 0 -0 0</pose>
        <inertial>
          <pose>-0.001 0 0 0 -0 0</pose>
          <mass>1.7</mass>
          <inertia>
            <ixx>0.00424805</ixx>
            <ixy>0</ixy>
            <ixz>0</ixz>
            <iyy>0.00424804</iyy>
            <iyz>0</iyz>
            <izz>-0.00487997</izz>
          </inertia>
        </inertial>
        <collision name='wheel_4_collision'>
          <pose>0 0 0 0 -0 0</pose>
          <geometry>
            <mesh>
              <scale>0.01 0.01 0.01</scale>
              <uri>/home/jinmin/zm_ws/src/zm_robot/robot_description/meshes/mecanum_right_after.stl</uri>
            </mesh>
          </geometry>
          <surface>
            <contact>
              <ode>
                <kp>1e+50</kp>
                <kd>1e+50</kd>
              </ode>
            </contact>
            <friction>
              <ode>
                <mu>30</mu>
                <mu2>30</mu2>
              </ode>
              <torsional>
                <ode/>
              </torsional>
            </friction>
            <bounce/>
          </surface>
          <max_contacts>10</max_contacts>
        </collision>
        <visual name='wheel_4_visual'>
          <pose>0 0 0 0 -0 0</pose>
          <geometry>
            <mesh>
              <scale>0.01 0.01 0.01</scale>
              <uri>/home/jinmin/zm_ws/src/zm_robot/robot_description/meshes/mecanum_right_after.stl</uri>
            </mesh>
          </geometry>
          <material>
            <script>
              <name>Gazebo/White</name>
              <uri>file://media/materials/scripts/gazebo.material</uri>
            </script>
          </material>
        </visual>
        <self_collide>0</self_collide>
        <gravity>1</gravity>
        <enable_wind>0</enable_wind>
        <kinematic>0</kinematic>
      </link>
      <joint name='roller_4_1_joint' type='revolute'>
        <pose relative_to='wheel_4'>0.065 0 0 -0.7854 0 0</pose>
        <parent>wheel_4</parent>
        <child>roller_4_1</child>
        <axis>
          <xyz>0 0 1</xyz>
          <limit>
            <lower>-1e+16</lower>
            <upper>1e+16</upper>
          </limit>
          <dynamics>
            <damping>0</damping>
            <friction>0</friction>
            <spring_reference>0</spring_reference>
            <spring_stiffness>0</spring_stiffness>
          </dynamics>
        </axis>
      </joint>
      <link name='roller_4_1'>
        <pose relative_to='roller_4_1_joint'>0 0 0 0 -0 0</pose>
        <inertial>
          <pose>0 0 0 0 -0 0</pose>
          <mass>0.124</mass>
          <inertia>
            <ixx>0.0051893</ixx>
            <ixy>0</ixy>
            <ixz>0</ixz>
            <iyy>0.0051893</iyy>
            <iyz>0</iyz>
            <izz>0.0013891</izz>
          </inertia>
        </inertial>
        <collision name='roller_4_1_collision'>
          <pose>0 0 0 0 -0 0</pose>
          <geometry>
            <mesh>
              <scale>0.01 0.01 0.01</scale>
              <uri>/home/jinmin/zm_ws/src/zm_robot/robot_description/meshes/mecanum_roller.stl</uri>
            </mesh>
          </geometry>
          <surface>
            <contact>
              <ode>
                <kp>1e+50</kp>
                <kd>1e+50</kd>
              </ode>
            </contact>
            <friction>
              <ode>
                <mu>30</mu>
                <mu2>30</mu2>
              </ode>
              <torsional>
                <ode/>
              </torsional>
            </friction>
            <bounce/>
          </surface>
          <max_contacts>10</max_contacts>
        </collision>
        <visual name='roller_4_1_visual'>
          <pose>0 0 0 0 -0 0</pose>
          <geometry>
            <mesh>
              <scale>0.01 0.01 0.01</scale>
              <uri>/home/jinmin/zm_ws/src/zm_robot/robot_description/meshes/mecanum_roller.stl</uri>
            </mesh>
          </geometry>
          <material>
            <script>
              <name>Gazebo/Black</name>
              <uri>file://media/materials/scripts/gazebo.material</uri>
            </script>
          </material>
        </visual>
        <self_collide>0</self_collide>
        <gravity>1</gravity>
        <enable_wind>0</enable_wind>
        <kinematic>0</kinematic>
      </link>
      <joint name='roller_4_2_joint' type='revolute'>
        <pose relative_to='wheel_4'>0.049792 0.041781 0 -0.7854 0 0.6981</pose>
        <parent>wheel_4</parent>
        <child>roller_4_2</child>
        <axis>
          <xyz>0 0 1</xyz>
          <limit>
            <lower>-1e+16</lower>
            <upper>1e+16</upper>
          </limit>
          <dynamics>
            <damping>0</damping>
            <friction>0</friction>
            <spring_reference>0</spring_reference>
            <spring_stiffness>0</spring_stiffness>
          </dynamics>
        </axis>
      </joint>
      <link name='roller_4_2'>
        <pose relative_to='roller_4_2_joint'>0 0 0 0 -0 0</pose>
        <inertial>
          <pose>0 0 0 0 -0 0</pose>
          <mass>0.124</mass>
          <inertia>
            <ixx>0.0051893</ixx>
            <ixy>0</ixy>
            <ixz>0</ixz>
            <iyy>0.0051893</iyy>
            <iyz>0</iyz>
            <izz>0.0013891</izz>
          </inertia>
        </inertial>
        <collision name='roller_4_2_collision'>
          <pose>0 0 0 0 -0 0</pose>
          <geometry>
            <mesh>
              <scale>0.01 0.01 0.01</scale>
              <uri>/home/jinmin/zm_ws/src/zm_robot/robot_description/meshes/mecanum_roller.stl</uri>
            </mesh>
          </geometry>
          <surface>
            <contact>
              <ode>
                <kp>1e+50</kp>
                <kd>1e+50</kd>
              </ode>
            </contact>
            <friction>
              <ode>
                <mu>30</mu>
                <mu2>30</mu2>
              </ode>
              <torsional>
                <ode/>
              </torsional>
            </friction>
            <bounce/>
          </surface>
          <max_contacts>10</max_contacts>
        </collision>
        <visual name='roller_4_2_visual'>
          <pose>0 0 0 0 -0 0</pose>
          <geometry>
            <mesh>
              <scale>0.01 0.01 0.01</scale>
              <uri>/home/jinmin/zm_ws/src/zm_robot/robot_description/meshes/mecanum_roller.stl</uri>
            </mesh>
          </geometry>
          <material>
            <script>
              <name>Gazebo/Black</name>
              <uri>file://media/materials/scripts/gazebo.material</uri>
            </script>
          </material>
        </visual>
        <self_collide>0</self_collide>
        <gravity>1</gravity>
        <enable_wind>0</enable_wind>
        <kinematic>0</kinematic>
      </link>
      <joint name='roller_4_3_joint' type='revolute'>
        <pose relative_to='wheel_4'>0.011287 0.064012 0 -0.7854 -0 1.3962</pose>
        <parent>wheel_4</parent>
        <child>roller_4_3</child>
        <axis>
          <xyz>0 0 1</xyz>
          <limit>
            <lower>-1e+16</lower>
            <upper>1e+16</upper>
          </limit>
          <dynamics>
            <damping>0</damping>
            <friction>0</friction>
            <spring_reference>0</spring_reference>
            <spring_stiffness>0</spring_stiffness>
          </dynamics>
        </axis>
      </joint>
      <link name='roller_4_3'>
        <pose relative_to='roller_4_3_joint'>0 0 0 0 -0 0</pose>
        <inertial>
          <pose>0 0 0 0 -0 0</pose>
          <mass>0.124</mass>
          <inertia>
            <ixx>0.0051893</ixx>
            <ixy>0</ixy>
            <ixz>0</ixz>
            <iyy>0.0051893</iyy>
            <iyz>0</iyz>
            <izz>0.0013891</izz>
          </inertia>
        </inertial>
        <collision name='roller_4_3_collision'>
          <pose>0 0 0 0 -0 0</pose>
          <geometry>
            <mesh>
              <scale>0.01 0.01 0.01</scale>
              <uri>/home/jinmin/zm_ws/src/zm_robot/robot_description/meshes/mecanum_roller.stl</uri>
            </mesh>
          </geometry>
          <surface>
            <contact>
              <ode>
                <kp>1e+50</kp>
                <kd>1e+50</kd>
              </ode>
            </contact>
            <friction>
              <ode>
                <mu>30</mu>
                <mu2>30</mu2>
              </ode>
              <torsional>
                <ode/>
              </torsional>
            </friction>
            <bounce/>
          </surface>
          <max_contacts>10</max_contacts>
        </collision>
        <visual name='roller_4_3_visual'>
          <pose>0 0 0 0 -0 0</pose>
          <geometry>
            <mesh>
              <scale>0.01 0.01 0.01</scale>
              <uri>/home/jinmin/zm_ws/src/zm_robot/robot_description/meshes/mecanum_roller.stl</uri>
            </mesh>
          </geometry>
          <material>
            <script>
              <name>Gazebo/Black</name>
              <uri>file://media/materials/scripts/gazebo.material</uri>
            </script>
          </material>
        </visual>
        <self_collide>0</self_collide>
        <gravity>1</gravity>
        <enable_wind>0</enable_wind>
        <kinematic>0</kinematic>
      </link>
      <joint name='roller_4_4_joint' type='revolute'>
        <pose relative_to='wheel_4'>-0.0325 0.056291 0 -0.7854 0 2.0943</pose>
        <parent>wheel_4</parent>
        <child>roller_4_4</child>
        <axis>
          <xyz>0 0 1</xyz>
          <limit>
            <lower>-1e+16</lower>
            <upper>1e+16</upper>
          </limit>
          <dynamics>
            <damping>0</damping>
            <friction>0</friction>
            <spring_reference>0</spring_reference>
            <spring_stiffness>0</spring_stiffness>
          </dynamics>
        </axis>
      </joint>
      <link name='roller_4_4'>
        <pose relative_to='roller_4_4_joint'>0 0 0 0 -0 0</pose>
        <inertial>
          <pose>0 0 0 0 -0 0</pose>
          <mass>0.124</mass>
          <inertia>
            <ixx>0.0051893</ixx>
            <ixy>0</ixy>
            <ixz>0</ixz>
            <iyy>0.0051893</iyy>
            <iyz>0</iyz>
            <izz>0.0013891</izz>
          </inertia>
        </inertial>
        <collision name='roller_4_4_collision'>
          <pose>0 0 0 0 -0 0</pose>
          <geometry>
            <mesh>
              <scale>0.01 0.01 0.01</scale>
              <uri>/home/jinmin/zm_ws/src/zm_robot/robot_description/meshes/mecanum_roller.stl</uri>
            </mesh>
          </geometry>
          <surface>
            <contact>
              <ode>
                <kp>1e+50</kp>
                <kd>1e+50</kd>
              </ode>
            </contact>
            <friction>
              <ode>
                <mu>30</mu>
                <mu2>30</mu2>
              </ode>
              <torsional>
                <ode/>
              </torsional>
            </friction>
            <bounce/>
          </surface>
          <max_contacts>10</max_contacts>
        </collision>
        <visual name='roller_4_4_visual'>
          <pose>0 0 0 0 -0 0</pose>
          <geometry>
            <mesh>
              <scale>0.01 0.01 0.01</scale>
              <uri>/home/jinmin/zm_ws/src/zm_robot/robot_description/meshes/mecanum_roller.stl</uri>
            </mesh>
          </geometry>
          <material>
            <script>
              <name>Gazebo/Black</name>
              <uri>file://media/materials/scripts/gazebo.material</uri>
            </script>
          </material>
        </visual>
        <self_collide>0</self_collide>
        <gravity>1</gravity>
        <enable_wind>0</enable_wind>
        <kinematic>0</kinematic>
      </link>
      <joint name='roller_4_5_joint' type='revolute'>
        <pose relative_to='wheel_4'>-0.06108 0.022231 0 -0.7854 -0 2.7924</pose>
        <parent>wheel_4</parent>
        <child>roller_4_5</child>
        <axis>
          <xyz>0 0 1</xyz>
          <limit>
            <lower>-1e+16</lower>
            <upper>1e+16</upper>
          </limit>
          <dynamics>
            <damping>0</damping>
            <friction>0</friction>
            <spring_reference>0</spring_reference>
            <spring_stiffness>0</spring_stiffness>
          </dynamics>
        </axis>
      </joint>
      <link name='roller_4_5'>
        <pose relative_to='roller_4_5_joint'>0 0 0 0 -0 0</pose>
        <inertial>
          <pose>0 0 0 0 -0 0</pose>
          <mass>0.124</mass>
          <inertia>
            <ixx>0.0051893</ixx>
            <ixy>0</ixy>
            <ixz>0</ixz>
            <iyy>0.0051893</iyy>
            <iyz>0</iyz>
            <izz>0.0013891</izz>
          </inertia>
        </inertial>
        <collision name='roller_4_5_collision'>
          <pose>0 0 0 0 -0 0</pose>
          <geometry>
            <mesh>
              <scale>0.01 0.01 0.01</scale>
              <uri>/home/jinmin/zm_ws/src/zm_robot/robot_description/meshes/mecanum_roller.stl</uri>
            </mesh>
          </geometry>
          <surface>
            <contact>
              <ode>
                <kp>1e+50</kp>
                <kd>1e+50</kd>
              </ode>
            </contact>
            <friction>
              <ode>
                <mu>30</mu>
                <mu2>30</mu2>
              </ode>
              <torsional>
                <ode/>
              </torsional>
            </friction>
            <bounce/>
          </surface>
          <max_contacts>10</max_contacts>
        </collision>
        <visual name='roller_4_5_visual'>
          <pose>0 0 0 0 -0 0</pose>
          <geometry>
            <mesh>
              <scale>0.01 0.01 0.01</scale>
              <uri>/home/jinmin/zm_ws/src/zm_robot/robot_description/meshes/mecanum_roller.stl</uri>
            </mesh>
          </geometry>
          <material>
            <script>
              <name>Gazebo/Black</name>
              <uri>file://media/materials/scripts/gazebo.material</uri>
            </script>
          </material>
        </visual>
        <self_collide>0</self_collide>
        <gravity>1</gravity>
        <enable_wind>0</enable_wind>
        <kinematic>0</kinematic>
      </link>
      <joint name='roller_4_6_joint' type='revolute'>
        <pose relative_to='wheel_4'>-0.06108 -0.022231 0 -0.7854 -0 -2.7924</pose>
        <parent>wheel_4</parent>
        <child>roller_4_6</child>
        <axis>
          <xyz>0 0 1</xyz>
          <limit>
            <lower>-1e+16</lower>
            <upper>1e+16</upper>
          </limit>
          <dynamics>
            <damping>0</damping>
            <friction>0</friction>
            <spring_reference>0</spring_reference>
            <spring_stiffness>0</spring_stiffness>
          </dynamics>
        </axis>
      </joint>
      <link name='roller_4_6'>
        <pose relative_to='roller_4_6_joint'>0 0 0 0 -0 0</pose>
        <inertial>
          <pose>0 0 0 0 -0 0</pose>
          <mass>0.124</mass>
          <inertia>
            <ixx>0.0051893</ixx>
            <ixy>0</ixy>
            <ixz>0</ixz>
            <iyy>0.0051893</iyy>
            <iyz>0</iyz>
            <izz>0.0013891</izz>
          </inertia>
        </inertial>
        <collision name='roller_4_6_collision'>
          <pose>0 0 0 0 -0 0</pose>
          <geometry>
            <mesh>
              <scale>0.01 0.01 0.01</scale>
              <uri>/home/jinmin/zm_ws/src/zm_robot/robot_description/meshes/mecanum_roller.stl</uri>
            </mesh>
          </geometry>
          <surface>
            <contact>
              <ode>
                <kp>1e+50</kp>
                <kd>1e+50</kd>
              </ode>
            </contact>
            <friction>
              <ode>
                <mu>30</mu>
                <mu2>30</mu2>
              </ode>
              <torsional>
                <ode/>
              </torsional>
            </friction>
            <bounce/>
          </surface>
          <max_contacts>10</max_contacts>
        </collision>
        <visual name='roller_4_6_visual'>
          <pose>0 0 0 0 -0 0</pose>
          <geometry>
            <mesh>
              <scale>0.01 0.01 0.01</scale>
              <uri>/home/jinmin/zm_ws/src/zm_robot/robot_description/meshes/mecanum_roller.stl</uri>
            </mesh>
          </geometry>
          <material>
            <script>
              <name>Gazebo/Black</name>
              <uri>file://media/materials/scripts/gazebo.material</uri>
            </script>
          </material>
        </visual>
        <self_collide>0</self_collide>
        <gravity>1</gravity>
        <enable_wind>0</enable_wind>
        <kinematic>0</kinematic>
      </link>
      <joint name='roller_4_7_joint' type='revolute'>
        <pose relative_to='wheel_4'>-0.0325 -0.056291 0 -0.7854 -0 -2.0943</pose>
        <parent>wheel_4</parent>
        <child>roller_4_7</child>
        <axis>
          <xyz>0 0 1</xyz>
          <limit>
            <lower>-1e+16</lower>
            <upper>1e+16</upper>
          </limit>
          <dynamics>
            <damping>0</damping>
            <friction>0</friction>
            <spring_reference>0</spring_reference>
            <spring_stiffness>0</spring_stiffness>
          </dynamics>
        </axis>
      </joint>
      <link name='roller_4_7'>
        <pose relative_to='roller_4_7_joint'>0 0 0 0 -0 0</pose>
        <inertial>
          <pose>0 0 0 0 -0 0</pose>
          <mass>0.124</mass>
          <inertia>
            <ixx>0.0051893</ixx>
            <ixy>0</ixy>
            <ixz>0</ixz>
            <iyy>0.0051893</iyy>
            <iyz>0</iyz>
            <izz>0.0013891</izz>
          </inertia>
        </inertial>
        <collision name='roller_4_7_collision'>
          <pose>0 0 0 0 -0 0</pose>
          <geometry>
            <mesh>
              <scale>0.01 0.01 0.01</scale>
              <uri>/home/jinmin/zm_ws/src/zm_robot/robot_description/meshes/mecanum_roller.stl</uri>
            </mesh>
          </geometry>
          <surface>
            <contact>
              <ode>
                <kp>1e+50</kp>
                <kd>1e+50</kd>
              </ode>
            </contact>
            <friction>
              <ode>
                <mu>30</mu>
                <mu2>30</mu2>
              </ode>
              <torsional>
                <ode/>
              </torsional>
            </friction>
            <bounce/>
          </surface>
          <max_contacts>10</max_contacts>
        </collision>
        <visual name='roller_4_7_visual'>
          <pose>0 0 0 0 -0 0</pose>
          <geometry>
            <mesh>
              <scale>0.01 0.01 0.01</scale>
              <uri>/home/jinmin/zm_ws/src/zm_robot/robot_description/meshes/mecanum_roller.stl</uri>
            </mesh>
          </geometry>
          <material>
            <script>
              <name>Gazebo/Black</name>
              <uri>file://media/materials/scripts/gazebo.material</uri>
            </script>
          </material>
        </visual>
        <self_collide>0</self_collide>
        <gravity>1</gravity>
        <enable_wind>0</enable_wind>
        <kinematic>0</kinematic>
      </link>
      <joint name='roller_4_8_joint' type='revolute'>
        <pose relative_to='wheel_4'>0.011287 -0.064012 0 -0.7854 0 -1.3962</pose>
        <parent>wheel_4</parent>
        <child>roller_4_8</child>
        <axis>
          <xyz>0 0 1</xyz>
          <limit>
            <lower>-1e+16</lower>
            <upper>1e+16</upper>
          </limit>
          <dynamics>
            <damping>0</damping>
            <friction>0</friction>
            <spring_reference>0</spring_reference>
            <spring_stiffness>0</spring_stiffness>
          </dynamics>
        </axis>
      </joint>
      <link name='roller_4_8'>
        <pose relative_to='roller_4_8_joint'>0 0 0 0 -0 0</pose>
        <inertial>
          <pose>0 0 0 0 -0 0</pose>
          <mass>0.124</mass>
          <inertia>
            <ixx>0.0051893</ixx>
            <ixy>0</ixy>
            <ixz>0</ixz>
            <iyy>0.0051893</iyy>
            <iyz>0</iyz>
            <izz>0.0013891</izz>
          </inertia>
        </inertial>
        <collision name='roller_4_8_collision'>
          <pose>0 0 0 0 -0 0</pose>
          <geometry>
            <mesh>
              <scale>0.01 0.01 0.01</scale>
              <uri>/home/jinmin/zm_ws/src/zm_robot/robot_description/meshes/mecanum_roller.stl</uri>
            </mesh>
          </geometry>
          <surface>
            <contact>
              <ode>
                <kp>1e+50</kp>
                <kd>1e+50</kd>
              </ode>
            </contact>
            <friction>
              <ode>
                <mu>30</mu>
                <mu2>30</mu2>
              </ode>
              <torsional>
                <ode/>
              </torsional>
            </friction>
            <bounce/>
          </surface>
          <max_contacts>10</max_contacts>
        </collision>
        <visual name='roller_4_8_visual'>
          <pose>0 0 0 0 -0 0</pose>
          <geometry>
            <mesh>
              <scale>0.01 0.01 0.01</scale>
              <uri>/home/jinmin/zm_ws/src/zm_robot/robot_description/meshes/mecanum_roller.stl</uri>
            </mesh>
          </geometry>
          <material>
            <script>
              <name>Gazebo/Black</name>
              <uri>file://media/materials/scripts/gazebo.material</uri>
            </script>
          </material>
        </visual>
        <self_collide>0</self_collide>
        <gravity>1</gravity>
        <enable_wind>0</enable_wind>
        <kinematic>0</kinematic>
      </link>
      <joint name='roller_4_9_joint' type='revolute'>
        <pose relative_to='wheel_4'>0.049792 -0.041781 0 -0.7854 -0 -0.6981</pose>
        <parent>wheel_4</parent>
        <child>roller_4_9</child>
        <axis>
          <xyz>0 0 1</xyz>
          <limit>
            <lower>-1e+16</lower>
            <upper>1e+16</upper>
          </limit>
          <dynamics>
            <damping>0</damping>
            <friction>0</friction>
            <spring_reference>0</spring_reference>
            <spring_stiffness>0</spring_stiffness>
          </dynamics>
        </axis>
      </joint>
      <link name='roller_4_9'>
        <pose relative_to='roller_4_9_joint'>0 0 0 0 -0 0</pose>
        <inertial>
          <pose>0 0 0 0 -0 0</pose>
          <mass>0.124</mass>
          <inertia>
            <ixx>0.0051893</ixx>
            <ixy>0</ixy>
            <ixz>0</ixz>
            <iyy>0.0051893</iyy>
            <iyz>0</iyz>
            <izz>0.0013891</izz>
          </inertia>
        </inertial>
        <collision name='roller_4_9_collision'>
          <pose>0 0 0 0 -0 0</pose>
          <geometry>
            <mesh>
              <scale>0.01 0.01 0.01</scale>
              <uri>/home/jinmin/zm_ws/src/zm_robot/robot_description/meshes/mecanum_roller.stl</uri>
            </mesh>
          </geometry>
          <surface>
            <contact>
              <ode>
                <kp>1e+50</kp>
                <kd>1e+50</kd>
              </ode>
            </contact>
            <friction>
              <ode>
                <mu>30</mu>
                <mu2>30</mu2>
              </ode>
              <torsional>
                <ode/>
              </torsional>
            </friction>
            <bounce/>
          </surface>
          <max_contacts>10</max_contacts>
        </collision>
        <visual name='roller_4_9_visual'>
          <pose>0 0 0 0 -0 0</pose>
          <geometry>
            <mesh>
              <scale>0.01 0.01 0.01</scale>
              <uri>/home/jinmin/zm_ws/src/zm_robot/robot_description/meshes/mecanum_roller.stl</uri>
            </mesh>
          </geometry>
          <material>
            <script>
              <name>Gazebo/Black</name>
              <uri>file://media/materials/scripts/gazebo.material</uri>
            </script>
          </material>
        </visual>
        <self_collide>0</self_collide>
        <gravity>1</gravity>
        <enable_wind>0</enable_wind>
        <kinematic>0</kinematic>
      </link>
      <static>0</static>
      <plugin name='robot_diff_drive' filename='libgazebo_ros_mecanum_drive.so'>
        <commandTopic>cmd_vel</commandTopic>
        <odometryTopic>odom</odometryTopic>
        <odometryFrame>odom</odometryFrame>
        <robotBaseFrame>base_footprint</robotBaseFrame>
        <LeftRear>wheel_joint_1</LeftRear>
        <LeftFront>wheel_joint_2</LeftFront>
        <RightFront>wheel_joint_3</RightFront>
        <RightRear>wheel_joint_4</RightRear>
        <odometryRate>20</odometryRate>
        <publishWheelTF>0</publishWheelTF>
        <publishWheelJointState>1</publishWheelJointState>
        <WheelTorque>30</WheelTorque>
        <WheelSeparationW>0.5</WheelSeparationW>
        <WheelSeparationL>0.6</WheelSeparationL>
        <wheelAccel>5</wheelAccel>
        <wheelDiameter>0.13</wheelDiameter>
        <publishOdom>1</publishOdom>
        <isRollerModel>1</isRollerModel>
        <robotNamespace>/</robotNamespace>
      </plugin>
      <pose>0 0 0 0 -0 0</pose>
    </model>
    <model name='test2'>
      <pose>2.21743 -0.602689 0 0 -0 0</pose>
      <link name='Wall_0'>
        <collision name='Wall_0_Collision'>
          <geometry>
            <box>
              <size>4.15 0.15 1</size>
            </box>
          </geometry>
          <pose>0 0 0.5 0 -0 0</pose>
          <max_contacts>10</max_contacts>
          <surface>
            <contact>
              <ode/>
            </contact>
            <bounce/>
            <friction>
              <torsional>
                <ode/>
              </torsional>
              <ode/>
            </friction>
          </surface>
        </collision>
        <visual name='Wall_0_Visual'>
          <pose>0 0 0.5 0 -0 0</pose>
          <geometry>
            <box>
              <size>4.15 0.15 1</size>
            </box>
          </geometry>
          <material>
            <script>
              <uri>file://media/materials/scripts/gazebo.material</uri>
              <name>Gazebo/Grey</name>
            </script>
            <ambient>1 1 1 1</ambient>
          </material>
          <meta>
            <layer>0</layer>
          </meta>
        </visual>
        <pose>0.4625 -1.25 0 0 -0 0</pose>
        <self_collide>0</self_collide>
        <enable_wind>0</enable_wind>
        <kinematic>0</kinematic>
      </link>
      <link name='Wall_1'>
        <collision name='Wall_1_Collision'>
          <geometry>
            <box>
              <size>2.65 0.15 1</size>
            </box>
          </geometry>
          <pose>0 0 0.5 0 -0 0</pose>
          <max_contacts>10</max_contacts>
          <surface>
            <contact>
              <ode/>
            </contact>
            <bounce/>
            <friction>
              <torsional>
                <ode/>
              </torsional>
              <ode/>
            </friction>
          </surface>
        </collision>
        <visual name='Wall_1_Visual'>
          <pose>0 0 0.5 0 -0 0</pose>
          <geometry>
            <box>
              <size>2.65 0.15 1</size>
            </box>
          </geometry>
          <material>
            <script>
              <uri>file://media/materials/scripts/gazebo.material</uri>
              <name>Gazebo/Grey</name>
            </script>
            <ambient>1 1 1 1</ambient>
          </material>
          <meta>
            <layer>0</layer>
          </meta>
        </visual>
        <pose>2.4625 0 0 0 -0 1.5708</pose>
        <self_collide>0</self_collide>
        <enable_wind>0</enable_wind>
        <kinematic>0</kinematic>
      </link>
      <link name='Wall_2'>
        <collision name='Wall_2_Collision'>
          <geometry>
            <box>
              <size>4.15 0.15 1</size>
            </box>
          </geometry>
          <pose>0 0 0.5 0 -0 0</pose>
          <max_contacts>10</max_contacts>
          <surface>
            <contact>
              <ode/>
            </contact>
            <bounce/>
            <friction>
              <torsional>
                <ode/>
              </torsional>
              <ode/>
            </friction>
          </surface>
        </collision>
        <visual name='Wall_2_Visual'>
          <pose>0 0 0.5 0 -0 0</pose>
          <geometry>
            <box>
              <size>4.15 0.15 1</size>
            </box>
          </geometry>
          <material>
            <script>
              <uri>file://media/materials/scripts/gazebo.material</uri>
              <name>Gazebo/Grey</name>
            </script>
            <ambient>1 1 1 1</ambient>
          </material>
          <meta>
            <layer>0</layer>
          </meta>
        </visual>
        <pose>0.4625 1.25 0 0 -0 3.14159</pose>
        <self_collide>0</self_collide>
        <enable_wind>0</enable_wind>
        <kinematic>0</kinematic>
      </link>
      <link name='Wall_3'>
        <pose>-1.5375 0 0 0 -0 -1.5708</pose>
        <visual name='Wall_3_Visual_0'>
          <pose>-1.1982 0 0.5 0 -0 0</pose>
          <geometry>
            <box>
              <size>0.253589 0.15 1</size>
            </box>
          </geometry>
          <material>
            <script>
              <uri>file://media/materials/scripts/gazebo.material</uri>
              <name>Gazebo/Grey</name>
            </script>
            <ambient>1 1 1 1</ambient>
          </material>
          <meta>
            <layer>0</layer>
          </meta>
        </visual>
        <collision name='Wall_3_Collision_0'>
          <geometry>
            <box>
              <size>0.253589 0.15 1</size>
            </box>
          </geometry>
          <pose>-1.1982 0 0.5 0 -0 0</pose>
          <max_contacts>10</max_contacts>
          <surface>
            <contact>
              <ode/>
            </contact>
            <bounce/>
            <friction>
              <torsional>
                <ode/>
              </torsional>
              <ode/>
            </friction>
          </surface>
        </collision>
        <visual name='Wall_3_Visual_1'>
          <pose>0.626795 0 0.5 0 -0 0</pose>
          <geometry>
            <box>
              <size>1.39641 0.15 1</size>
            </box>
          </geometry>
          <material>
            <script>
              <uri>file://media/materials/scripts/gazebo.material</uri>
              <name>Gazebo/Grey</name>
            </script>
            <ambient>1 1 1 1</ambient>
          </material>
          <meta>
            <layer>0</layer>
          </meta>
        </visual>
        <collision name='Wall_3_Collision_1'>
          <geometry>
            <box>
              <size>1.39641 0.15 1</size>
            </box>
          </geometry>
          <pose>0.626795 0 0.5 0 -0 0</pose>
          <max_contacts>10</max_contacts>
          <surface>
            <contact>
              <ode/>
            </contact>
            <bounce/>
            <friction>
              <torsional>
                <ode/>
              </torsional>
              <ode/>
            </friction>
          </surface>
        </collision>
        <self_collide>0</self_collide>
        <enable_wind>0</enable_wind>
        <kinematic>0</kinematic>
      </link>
      <static>1</static>
    </model>
    <state world_name='default'>
      <sim_time>140 704000000</sim_time>
      <real_time>173 527735119</real_time>
      <wall_time>1716621825 813400682</wall_time>
      <iterations>140704</iterations>
      <model name='ground_plane'>
        <pose>0 0 0 0 -0 0</pose>
        <scale>1 1 1</scale>
        <link name='link'>
          <pose>0 0 0 0 -0 0</pose>
          <velocity>0 0 0 0 -0 0</velocity>
          <acceleration>0 0 0 0 -0 0</acceleration>
          <wrench>0 0 0 0 -0 0</wrench>
        </link>
      </model>
      <model name='robot'>
        <pose>-0.107335 -0.124259 -0.001547 -0.00062 0.000809 0.024616</pose>
        <scale>1 1 1</scale>
        <link name='base_footprint'>
          <pose>-0.107335 -0.124259 -0.001547 -0.00062 0.000809 0.024616</pose>
          <velocity>-0.000705 -0.000218 -0.001411 0.014113 -0.006071 4e-05</velocity>
          <acceleration>0.424571 0.389232 -5.04702 -1.25483 -0.288527 2.95483</acceleration>
          <wrench>14.2928 13.1031 -169.903 0 -0 0</wrench>
        </link>
        <link name='roller_1_1'>
          <pose>-0.363518 0.169535 0.015049 1.48313 1.4439 2.29391</pose>
          <velocity>-0.000834 -0.000537 0.001176 0.002711 -0.016199 -8.7e-05</velocity>
          <acceleration>1.21393 1.5789 -3.11228 2.01194 1.45199 3.09019</acceleration>
          <wrench>0.150527 0.195784 -0.385923 0 -0 0</wrench>
        </link>
        <link name='roller_1_2'>
          <pose>-0.322003 0.170567 0.030936 -0.785901 0.85679 0.024491</pose>
          <velocity>-0.000917 -0.000722 0.001433 0.011759 -0.007714 -0.001121</velocity>
          <acceleration>1.07851 1.3697 -2.72862 -2.05055 -0.360683 -3.07019</acceleration>
          <wrench>0.133735 0.169843 -0.338349 0 -0 0</wrench>
        </link>
        <link name='roller_1_3'>
          <pose>-0.30041 0.171123 0.069799 -0.78665 0.154352 0.020529</pose>
          <velocity>-0.001146 -0.001226 0.001569 0.013677 -0.003913 0.002139</velocity>
          <acceleration>0.729923 0.831586 -2.52969 -1.63533 -0.655549 0.688514</acceleration>
          <wrench>0.09051 0.103117 -0.313682 0 -0 0</wrench>
        </link>
        <link name='roller_1_4'>
          <pose>-0.308842 0.170942 0.113454 -0.784551 -0.542421 0.021936</pose>
          <velocity>-0.001403 -0.001818 0.001508 0.01016 0.000484 0.005825</velocity>
          <acceleration>0.341073 0.210875 -2.61824 0.529751 -0.46426 2.97831</acceleration>
          <wrench>0.042293 0.026149 -0.324661 0 -0 0</wrench>
        </link>
        <link name='roller_1_5'>
          <pose>-0.343353 0.17011 0.141475 -0.797993 -1.23413 0.037736</pose>
          <velocity>-0.001564 -0.002217 0.001284 0.004595 0.003403 0.003468</velocity>
          <acceleration>0.095127 -0.19923 -2.94651 -1.62796 0.99854 0.603325</acceleration>
          <wrench>0.011796 -0.024705 -0.365367 0 -0 0</wrench>
        </link>
        <link name='roller_1_6'>
          <pose>-0.387796 0.169015 0.14075 2.39091 -1.21725 3.12936</pose>
          <velocity>-0.00156 -0.002227 0.001005 0.004707 0.003511 -0.003021</velocity>
          <acceleration>0.098007 -0.197491 -3.3607 -1.19547 0.804331 -0.55337</acceleration>
          <wrench>0.012153 -0.024489 -0.416726 0 -0 0</wrench>
        </link>
        <link name='roller_1_7'>
          <pose>-0.421375 0.168171 0.111619 2.3676 -0.525799 -3.13897</pose>
          <velocity>-0.001393 -0.00183 0.000788 0.010596 0.000646 -0.005451</velocity>
          <acceleration>0.350063 0.227131 -3.68216 1.13672 -0.742634 -2.73313</acceleration>
          <wrench>0.043408 0.028164 -0.456588 0 -0 0</wrench>
        </link>
        <link name='roller_1_8'>
          <pose>-0.428378 0.167971 0.067712 2.35312 0.170558 -3.13748</pose>
          <velocity>-0.001127 -0.001202 0.000724 0.014465 -0.004072 -0.00173</velocity>
          <acceleration>0.749298 0.884856 -3.76983 -0.834309 -0.345447 -0.81491</acceleration>
          <wrench>0.092913 0.109722 -0.467458 0 -0 0</wrench>
        </link>
        <link name='roller_1_9'>
          <pose>-0.405529 0.16851 0.029575 2.3377 0.872632 -3.14147</pose>
          <velocity>-0.000877 -0.000636 0.000853 0.012761 -0.008511 0.001464</velocity>
          <acceleration>1.11617 1.46947 -3.57104 -1.09744 0.626247 3.08223</acceleration>
          <wrench>0.138404 0.182214 -0.44281 0 -0 0</wrench>
        </link>
        <link name='roller_2_1'>
          <pose>0.199139 0.183421 0.067671 -2.34514 0.104247 0.105451</pose>
          <velocity>-0.000844 -0.000887 0.004745 0.018538 -0.002582 -0.006546</velocity>
          <acceleration>0.813297 0.797148 2.11504 -1.54827 1.39644 1.66625</acceleration>
          <wrench>0.100849 0.098846 0.262264 0 -0 0</wrench>
        </link>
        <link name='roller_2_2'>
          <pose>0.176502 0.182839 0.029406 -2.26713 0.795052 0.144688</pose>
          <velocity>-0.000494 -0.00011 0.004531 0.010235 0.003037 -0.008159</velocity>
          <acceleration>1.22725 1.35337 1.86205 -0.088989 1.52828 -2.14795</acceleration>
          <wrench>0.15218 0.167817 0.230894 0 -0 0</wrench>
        </link>
        <link name='roller_2_3'>
          <pose>0.134578 0.181799 0.014752 1.52077 1.42855 -2.38113</pose>
          <velocity>0.010778 0.011214 0.00091 -0.767737 0.741685 0.007267</velocity>
          <acceleration>3.47876 3.63188 -2.75155 -3.09366 1.50616 -2.10568</acceleration>
          <wrench>0.431366 0.450353 -0.341192 0 -0 0</wrench>
        </link>
        <link name='roller_2_4'>
          <pose>0.092971 0.180784 0.030292 0.649006 0.955557 2.99316</pose>
          <velocity>-0.001139 -0.000884 0.004332 0.00652 0.00285 0.003554</velocity>
          <acceleration>1.08521 1.28557 1.40592 -0.541132 0.148986 2.1947</acceleration>
          <wrench>0.134566 0.15941 0.174334 0 -0 0</wrench>
        </link>
        <link name='roller_2_5'>
          <pose>0.07116 0.180271 0.069034 0.762815 0.267484 3.05811</pose>
          <velocity>-0.001239 -0.001312 0.004263 0.010664 -0.000317 0.002351</velocity>
          <acceleration>0.731495 0.758317 1.19258 -2.04956 -0.656411 -0.845887</acceleration>
          <wrench>0.090705 0.094031 0.14788 0 -0 0</wrench>
        </link>
        <link name='roller_2_6'>
          <pose>0.079347 0.180499 0.112735 0.83873 -0.428194 3.05245</pose>
          <velocity>-0.001362 -0.001815 0.004279 0.010713 -0.004178 -0.001116</velocity>
          <acceleration>0.321586 0.136041 1.26064 -1.46246 -0.637827 2.65635</acceleration>
          <wrench>0.039877 0.016869 0.15632 0 -0 0</wrench>
        </link>
        <link name='roller_2_7'>
          <pose>0.113701 0.181363 0.140948 0.99659 -1.125 2.9384</pose>
          <velocity>-0.001454 -0.002155 0.004384 0.008105 -0.006887 -0.001202</velocity>
          <acceleration>0.04266 -0.2877 1.59009 -2.75893 1.55096 3.03239</acceleration>
          <wrench>0.00529 -0.035675 0.197171 0 -0 0</wrench>
        </link>
        <link name='roller_2_8'>
          <pose>0.158147 0.182457 0.140472 -2.663 -1.28595 0.347377</pose>
          <velocity>-0.001463 -0.002161 0.004538 0.00843 -0.007018 0.00143</velocity>
          <acceleration>0.033718 -0.30461 2.03779 0.60945 1.30335 0.068672</acceleration>
          <wrench>0.004181 -0.037772 0.252686 0 -0 0</wrench>
        </link>
        <link name='roller_2_9'>
          <pose>0.191888 0.18327 0.111529 -2.40905 -0.592909 0.12412</pose>
          <velocity>-0.001374 -0.001818 0.004666 0.011651 -0.004438 0.001079</velocity>
          <acceleration>0.312624 0.106005 2.3906 -0.729931 0.219106 -2.44065</acceleration>
          <wrench>0.038765 0.013145 0.296435 0 -0 0</wrench>
        </link>
        <link name='roller_3_1'>
          <pose>0.147173 -0.418074 0.015071 1.70707 1.33569 2.51385</pose>
          <velocity>-0.000937 -0.000492 -0.003802 0.056272 0.038157 -0.001856</velocity>
          <acceleration>1.17561 1.59907 -7.1929 0.05019 0.558423 -0.017776</acceleration>
          <wrench>0.145775 0.198285 -0.89192 0 -0 0</wrench>
        </link>
        <link name='roller_3_2'>
          <pose>0.18957 -0.417021 0.028422 -0.823011 0.886773 -0.022831</pose>
          <velocity>-0.000889 -0.000621 -0.003811 0.012378 -0.008448 -0.001485</velocity>
          <acceleration>1.01887 1.37677 -6.71972 -0.99889 0.506549 -3.06602</acceleration>
          <wrench>0.126339 0.17072 -0.833245 0 -0 0</wrench>
        </link>
        <link name='roller_3_3'>
          <pose>0.213471 -0.41641 0.065908 -0.792974 0.184533 -0.010144</pose>
          <velocity>-0.001108 -0.001155 -0.00367 0.014614 -0.004314 0.001566</velocity>
          <acceleration>0.665112 0.807801 -6.49371 -0.566691 -0.311905 0.998085</acceleration>
          <wrench>0.082474 0.100167 -0.805221 0 -0 0</wrench>
        </link>
        <link name='roller_3_4'>
          <pose>0.20769 -0.416524 0.109993 -0.768096 -0.512111 -0.012905</pose>
          <velocity>-0.001366 -0.001785 -0.003713 0.011224 0.000412 0.005689</velocity>
          <acceleration>0.248592 0.143839 -6.55881 1.56962 -1.23955 2.49841</acceleration>
          <wrench>0.030825 0.017836 -0.813292 0 -0 0</wrench>
        </link>
        <link name='roller_3_5'>
          <pose>0.174934 -0.417312 0.140048 -0.717659 -1.20343 -0.048574</pose>
          <velocity>-0.001543 -0.002217 -0.003925 0.005167 0.003549 0.003738</velocity>
          <acceleration>-0.035912 -0.304538 -6.88888 -0.80772 0.458187 0.525101</acceleration>
          <wrench>-0.004453 -0.037763 -0.854221 0 -0 0</wrench>
        </link>
        <link name='roller_3_6'>
          <pose>0.130529 -0.418404 0.14201 2.30303 -1.24682 -3.06087</pose>
          <velocity>-0.001554 -0.002247 -0.00421 0.004653 0.00376 -0.002927</velocity>
          <acceleration>-0.055435 -0.327596 -7.33386 -1.78614 1.1182 -0.667564</acceleration>
          <wrench>-0.006874 -0.040622 -0.909399 0 -0 0</wrench>
        </link>
        <link name='roller_3_7'>
          <pose>0.095252 -0.419289 0.114961 2.34957 -0.555865 -3.10354</pose>
          <velocity>-0.001395 -0.001862 -0.004439 0.010414 0.000963 -0.005812</velocity>
          <acceleration>0.199113 0.085408 -7.69003 1.17538 -0.810732 -2.88992</acceleration>
          <wrench>0.02469 0.010591 -0.953563 0 -0 0</wrench>
        </link>
        <link name='roller_3_8'>
          <pose>0.08561 -0.419554 0.071557 2.35817 0.140308 -3.10692</pose>
          <velocity>-0.001141 -0.001241 -0.004509 0.014551 -0.003662 -0.002153</velocity>
          <acceleration>0.608717 0.741184 -7.79517 -0.639181 0.138709 -0.271829</acceleration>
          <wrench>0.075481 0.091907 -0.966601 0 -0 0</wrench>
        </link>
        <link name='roller_3_9'>
          <pose>0.106115 -0.419074 0.032109 2.3724 0.842139 -3.0957</pose>
          <velocity>-0.000909 -0.000674 -0.004391 0.01283 -0.00801 0.001459</velocity>
          <acceleration>0.981806 1.33282 -7.60439 -0.950861 0.4851 3.09433</acceleration>
          <wrench>0.121744 0.16527 -0.942945 0 -0 0</wrench>
        </link>
        <link name='roller_4_1'>
          <pose>-0.284874 -0.428671 0.078033 -2.35662 0.030656 0.030678</pose>
          <velocity>-0.001223 -0.001413 -0.008389 0.014172 -0.002436 -0.003301</velocity>
          <acceleration>0.403458 0.553009 -12.9532 -0.570747 0.046001 0.664814</acceleration>
          <wrench>0.050029 0.068573 -1.60619 0 -0 0</wrench>
        </link>
        <link name='roller_4_2'>
          <pose>-0.3016 -0.429109 0.036838 -2.34873 0.725481 0.036514</pose>
          <velocity>-0.000983 -0.00082 -0.008505 0.008916 0.001937 -0.005779</velocity>
          <acceleration>0.785702 1.17903 -13.1284 -0.383932 1.15921 2.11158</acceleration>
          <wrench>0.097427 0.1462 -1.62792 0 -0 0</wrench>
        </link>
        <link name='roller_4_3'>
          <pose>-0.340879 -0.430083 0.016125 -2.6507 1.45992 -0.272053</pose>
          <velocity>-0.001917 -0.002203 -0.030977 -0.283872 0.268464 -0.038859</velocity>
          <acceleration>-5.8363 -6.08915 -37.3766 -1.33535 0.531537 -2.56152</acceleration>
          <wrench>-0.723701 -0.755054 -4.6347 0 -0 0</wrench>
        </link>
        <link name='roller_4_4'>
          <pose>-0.384344 -0.431154 0.025351 0.744804 1.03507 3.11828</pose>
          <velocity>-0.000885 -0.000609 -0.006869 0.006494 0.003129 0.00489</velocity>
          <acceleration>1.07259 1.57259 -11.6264 1.80992 -1.31978 -0.083762</acceleration>
          <wrench>0.133001 0.195001 -1.44167 0 -0 0</wrench>
        </link>
        <link name='roller_4_5'>
          <pose>-0.411646 -0.431804 0.060438 0.775781 0.342439 3.13447</pose>
          <velocity>-0.001086 -0.001115 -0.007052 0.012689 -0.000586 0.005041</velocity>
          <acceleration>0.746262 1.04482 -11.9061 -0.793617 -0.966955 -1.12856</acceleration>
          <wrench>0.092537 0.129558 -1.47635 0 -0 0</wrench>
        </link>
        <link name='roller_4_6'>
          <pose>-0.410015 -0.431736 0.10487 0.797562 -0.35601 3.13427</pose>
          <velocity>-0.001341 -0.001755 -0.007057 0.014555 -0.005428 0.00039</velocity>
          <acceleration>0.332557 0.369268 -11.906 -0.348343 -0.588313 2.09433</acceleration>
          <wrench>0.041237 0.045789 -1.47635 0 -0 0</wrench>
        </link>
        <link name='roller_4_7'>
          <pose>-0.380213 -0.430981 0.137858 0.829791 -1.05945 3.11599</pose>
          <velocity>-0.001531 -0.002229 -0.006889 0.011636 -0.009114 -0.00146</velocity>
          <acceleration>0.024865 -0.138052 -11.6333 -1.6013 1.17887 3.0932</acceleration>
          <wrench>0.003083 -0.017118 -1.44253 0 -0 0</wrench>
        </link>
        <link name='roller_4_8'>
          <pose>-0.336185 -0.429894 0.143965 -2.43819 -1.37447 0.108211</pose>
          <velocity>-0.001565 -0.002315 -0.006634 0.010711 -0.009789 0.000882</velocity>
          <acceleration>-0.032916 -0.239804 -11.2226 0.324153 0.779089 0.077844</acceleration>
          <wrench>-0.004082 -0.029736 -1.3916 0 -0 0</wrench>
        </link>
        <link name='roller_4_9'>
          <pose>-0.298534 -0.428981 0.120336 -2.36376 -0.669921 0.036069</pose>
          <velocity>-0.001427 -0.001971 -0.006417 0.013671 -0.007103 0.001081</velocity>
          <acceleration>0.186082 0.1116 -10.8733 -0.552071 -0.040405 -3.03023</acceleration>
          <wrench>0.023074 0.013838 -1.34829 0 -0 0</wrench>
        </link>
        <link name='wheel_1'>
          <pose>-0.364578 0.169549 0.080041 -1.57142 -0.0163 0.024626</pose>
          <velocity>-0.001214 -0.001384 0.001187 0.012666 -0.005538 7.7e-05</velocity>
          <acceleration>0.637568 0.690003 -3.0928 0.787682 -1.18464 -0.182162</acceleration>
          <wrench>1.08387 1.17301 -5.25777 0 -0 0</wrench>
        </link>
        <link name='wheel_2'>
          <pose>0.13527 0.181856 0.079644 -1.57144 0.185258 0.024498</pose>
          <velocity>-0.000957 -0.001112 0.004132 0.019778 -0.008952 -0.000164</velocity>
          <acceleration>0.68597 0.649431 1.41193 -1.69086 -0.232564 2.88733</acceleration>
          <wrench>1.16615 1.10403 2.40029 0 -0 0</wrench>
        </link>
        <link name='wheel_3'>
          <pose>0.150038 -0.417962 0.080008 -1.57142 0.044138 0.024588</pose>
          <velocity>-0.001205 -0.00137 -0.003997 0.01426 -0.005846 4.3e-05</velocity>
          <acceleration>0.533339 0.606038 -7.08118 -1.1369 0.338774 -2.95366</acceleration>
          <wrench>0.906676 1.03026 -12.038 0 -0 0</wrench>
        </link>
        <link name='wheel_4'>
          <pose>-0.34981 -0.430269 0.080412 -1.57142 0.03673 0.024593</pose>
          <velocity>-0.001194 -0.001386 -0.006897 0.014598 -0.005905 5e-05</velocity>
          <acceleration>0.555747 0.724396 -11.5522 -0.799907 0.344135 -2.95078</acceleration>
          <wrench>0.94477 1.23147 -19.6388 0 -0 0</wrench>
        </link>
      </model>
      <model name='test2'>
        <pose>2.21743 -0.602689 0 0 -0 0</pose>
        <scale>1 1 1</scale>
        <link name='Wall_0'>
          <pose>2.67993 -1.85269 0 0 -0 0</pose>
          <velocity>0 0 0 0 -0 0</velocity>
          <acceleration>0 0 0 0 -0 0</acceleration>
          <wrench>0 0 0 0 -0 0</wrench>
        </link>
        <link name='Wall_1'>
          <pose>4.67993 -0.602689 0 0 -0 1.5708</pose>
          <velocity>0 0 0 0 -0 0</velocity>
          <acceleration>0 0 0 0 -0 0</acceleration>
          <wrench>0 0 0 0 -0 0</wrench>
        </link>
        <link name='Wall_2'>
          <pose>2.67993 0.647311 0 0 -0 3.14159</pose>
          <velocity>0 0 0 0 -0 0</velocity>
          <acceleration>0 0 0 0 -0 0</acceleration>
          <wrench>0 0 0 0 -0 0</wrench>
        </link>
        <link name='Wall_3'>
          <pose>0.67993 -0.602689 0 0 0 -1.5708</pose>
          <velocity>0 0 0 0 -0 0</velocity>
          <acceleration>0 0 0 0 -0 0</acceleration>
          <wrench>0 0 0 0 -0 0</wrench>
        </link>
      </model>
      <light name='sun'>
        <pose>0 0 10 0 -0 0</pose>
      </light>
    </state>
    <gui fullscreen='0'>
      <camera name='user_camera'>
        <pose>6.21413 -5.76304 6.20495 0 0.709797 2.40419</pose>
        <view_controller>orbit</view_controller>
        <projection_type>perspective</projection_type>
      </camera>
    </gui>
  </world>
</sdf>
