<sdf version='1.7'>
  <world name='default'>
    <model name='ground_plane'>
      <static>1</static>
      <link name='link'>
        <collision name='collision'>
          <geometry>
            <plane>
              <normal>0 0 1</normal>
              <size>100 100</size>
            </plane>
          </geometry>
          <surface>
            <contact>
              <collide_bitmask>65535</collide_bitmask>
              <ode/>
            </contact>
            <friction>
              <ode>
                <mu>100</mu>
                <mu2>50</mu2>
              </ode>
              <torsional>
                <ode/>
              </torsional>
            </friction>
            <bounce/>
          </surface>
          <max_contacts>10</max_contacts>
        </collision>
        <visual name='visual'>
          <cast_shadows>0</cast_shadows>
          <geometry>
            <plane>
              <normal>0 0 1</normal>
              <size>100 100</size>
            </plane>
          </geometry>
          <material>
            <script>
              <uri>file://media/materials/scripts/gazebo.material</uri>
              <name>Gazebo/Grey</name>
            </script>
          </material>
        </visual>
        <self_collide>0</self_collide>
        <enable_wind>0</enable_wind>
        <kinematic>0</kinematic>
      </link>
    </model>
    <light name='sun' type='directional'>
      <cast_shadows>1</cast_shadows>
      <pose>0 0 10 0 -0 0</pose>
      <diffuse>0.8 0.8 0.8 1</diffuse>
      <specular>0.2 0.2 0.2 1</specular>
      <attenuation>
        <range>1000</range>
        <constant>0.9</constant>
        <linear>0.01</linear>
        <quadratic>0.001</quadratic>
      </attenuation>
      <direction>-0.5 0.1 -0.9</direction>
      <spot>
        <inner_angle>0</inner_angle>
        <outer_angle>0</outer_angle>
        <falloff>0</falloff>
      </spot>
    </light>
    <gravity>0 0 -9.8</gravity>
    <magnetic_field>6e-06 2.3e-05 -4.2e-05</magnetic_field>
    <atmosphere type='adiabatic'/>
    <physics type='ode'>
      <max_step_size>0.001</max_step_size>
      <real_time_factor>1</real_time_factor>
      <real_time_update_rate>1000</real_time_update_rate>
    </physics>
    <scene>
      <ambient>0.4 0.4 0.4 1</ambient>
      <background>0.7 0.7 0.7 1</background>
      <shadows>1</shadows>
    </scene>
    <wind/>
    <spherical_coordinates>
      <surface_model>EARTH_WGS84</surface_model>
      <latitude_deg>0</latitude_deg>
      <longitude_deg>0</longitude_deg>
      <elevation>0</elevation>
      <heading_deg>0</heading_deg>
    </spherical_coordinates>
    <model name='robot2'>
      <link name='base_footprint'>
        <inertial>
          <pose>0.004411 -0.000743 0.098793 0 -0 0</pose>
          <mass>33.664</mass>
          <inertia>
            <ixx>1.07533</ixx>
            <ixy>-0.131285</ixy>
            <ixz>-0.0155619</ixz>
            <iyy>2.41453</iyy>
            <iyz>0.00261984</iyz>
            <izz>3.12176</izz>
          </inertia>
        </inertial>
        <collision name='base_footprint_fixed_joint_lump__base_link_collision'>
          <pose>0 0 0.081572 0 -0 0</pose>
          <geometry>
            <mesh>
              <scale>0.01 0.01 0.01</scale>
              <uri>/home/jinmin/zm_ws/src/parking_robot/robot_description/meshes/agv_base.stl</uri>
            </mesh>
          </geometry>
          <surface>
            <contact>
              <ode>
                <kp>1e+30</kp>
                <kd>1e+20</kd>
              </ode>
            </contact>
            <friction>
              <ode>
                <mu>10</mu>
                <mu2>10</mu2>
              </ode>
              <torsional>
                <ode/>
              </torsional>
            </friction>
            <bounce/>
          </surface>
          <max_contacts>10</max_contacts>
        </collision>
        <collision name='base_footprint_fixed_joint_lump__IMU_sensor_collision_1'>
          <pose>0 0 0.161572 0 -0 0</pose>
          <geometry>
            <mesh>
              <scale>0.01 0.01 0.01</scale>
              <uri>/home/jinmin/zm_ws/src/parking_robot/robot_description/meshes/IMU_sensor.stl</uri>
            </mesh>
          </geometry>
          <surface>
            <contact>
              <ode/>
            </contact>
            <friction>
              <ode/>
              <torsional>
                <ode/>
              </torsional>
            </friction>
            <bounce/>
          </surface>
          <max_contacts>10</max_contacts>
        </collision>
        <collision name='base_footprint_fixed_joint_lump__kinect_v2_collision_2'>
          <pose>0.297 -0.05 0.203587 0 -0 0</pose>
          <geometry>
            <mesh>
              <scale>0.01 0.01 0.01</scale>
              <uri>/home/jinmin/zm_ws/src/parking_robot/robot_description/meshes/kinect_v2.stl</uri>
            </mesh>
          </geometry>
          <surface>
            <contact>
              <ode>
                <kp>1e+60</kp>
                <kd>1e+50</kd>
              </ode>
            </contact>
            <friction>
              <ode>
                <mu>30</mu>
                <mu2>30</mu2>
              </ode>
              <torsional>
                <ode/>
              </torsional>
            </friction>
            <bounce/>
          </surface>
          <max_contacts>10</max_contacts>
        </collision>
        <collision name='base_footprint_fixed_joint_lump__sick_lidar0_collision_3'>
          <pose>0.33 0.175 0.277294 0 -0 0.7854</pose>
          <geometry>
            <mesh>
              <scale>0.01 0.01 0.01</scale>
              <uri>/home/jinmin/zm_ws/src/parking_robot/robot_description/meshes/sick_s30b.stl</uri>
            </mesh>
          </geometry>
          <surface>
            <contact>
              <ode>
                <kp>1e+60</kp>
                <kd>1e+50</kd>
              </ode>
            </contact>
            <friction>
              <ode>
                <mu>30</mu>
                <mu2>30</mu2>
              </ode>
              <torsional>
                <ode/>
              </torsional>
            </friction>
            <bounce/>
          </surface>
          <max_contacts>10</max_contacts>
        </collision>
        <collision name='base_footprint_fixed_joint_lump__sick_lidar1_collision_4'>
          <pose>-0.33 -0.175 0.277294 0 0 -2.35619</pose>
          <geometry>
            <mesh>
              <scale>0.01 0.01 0.01</scale>
              <uri>/home/jinmin/zm_ws/src/parking_robot/robot_description/meshes/sick_s30b.stl</uri>
            </mesh>
          </geometry>
          <surface>
            <contact>
              <ode>
                <kp>1e+60</kp>
                <kd>1e+50</kd>
              </ode>
            </contact>
            <friction>
              <ode>
                <mu>30</mu>
                <mu2>30</mu2>
              </ode>
              <torsional>
                <ode/>
              </torsional>
            </friction>
            <bounce/>
          </surface>
          <max_contacts>10</max_contacts>
        </collision>
        <collision name='base_footprint_fixed_joint_lump__ultrasound_1_collision_5'>
          <pose>0.4 0.15 0.111572 0 -0 0</pose>
          <geometry>
            <mesh>
              <scale>0.1 0.1 0.1</scale>
              <uri>/home/jinmin/zm_ws/src/parking_robot/robot_description/meshes/ultrasound.stl</uri>
            </mesh>
          </geometry>
          <surface>
            <contact>
              <ode/>
            </contact>
            <friction>
              <ode/>
              <torsional>
                <ode/>
              </torsional>
            </friction>
            <bounce/>
          </surface>
          <max_contacts>10</max_contacts>
        </collision>
        <collision name='base_footprint_fixed_joint_lump__ultrasound_2_collision_6'>
          <pose>0.4 -0.15 0.111572 0 -0 0</pose>
          <geometry>
            <mesh>
              <scale>0.1 0.1 0.1</scale>
              <uri>/home/jinmin/zm_ws/src/parking_robot/robot_description/meshes/ultrasound.stl</uri>
            </mesh>
          </geometry>
          <surface>
            <contact>
              <ode/>
            </contact>
            <friction>
              <ode/>
              <torsional>
                <ode/>
              </torsional>
            </friction>
            <bounce/>
          </surface>
          <max_contacts>10</max_contacts>
        </collision>
        <collision name='base_footprint_fixed_joint_lump__ultrasound_3_collision_7'>
          <pose>-0.4 0.15 0.111572 0 0 -3.14159</pose>
          <geometry>
            <mesh>
              <scale>0.1 0.1 0.1</scale>
              <uri>/home/jinmin/zm_ws/src/parking_robot/robot_description/meshes/ultrasound.stl</uri>
            </mesh>
          </geometry>
          <surface>
            <contact>
              <ode/>
            </contact>
            <friction>
              <ode/>
              <torsional>
                <ode/>
              </torsional>
            </friction>
            <bounce/>
          </surface>
          <max_contacts>10</max_contacts>
        </collision>
        <collision name='base_footprint_fixed_joint_lump__ultrasound_4_collision_8'>
          <pose>-0.4 -0.15 0.111572 0 0 -3.14159</pose>
          <geometry>
            <mesh>
              <scale>0.1 0.1 0.1</scale>
              <uri>/home/jinmin/zm_ws/src/parking_robot/robot_description/meshes/ultrasound.stl</uri>
            </mesh>
          </geometry>
          <surface>
            <contact>
              <ode/>
            </contact>
            <friction>
              <ode/>
              <torsional>
                <ode/>
              </torsional>
            </friction>
            <bounce/>
          </surface>
          <max_contacts>10</max_contacts>
        </collision>
        <visual name='base_footprint_fixed_joint_lump__base_link_visual'>
          <pose>0 0 0.081572 0 -0 0</pose>
          <geometry>
            <mesh>
              <scale>0.01 0.01 0.01</scale>
              <uri>/home/jinmin/zm_ws/src/parking_robot/robot_description/meshes/agv_base.stl</uri>
            </mesh>
          </geometry>
          <material>
            <script>
              <name>Gazebo/Orange</name>
              <uri>file://media/materials/scripts/gazebo.material</uri>
            </script>
          </material>
        </visual>
        <visual name='base_footprint_fixed_joint_lump__IMU_sensor_visual_1'>
          <pose>0 0 0.161572 0 -0 0</pose>
          <geometry>
            <mesh>
              <scale>0.01 0.01 0.01</scale>
              <uri>/home/jinmin/zm_ws/src/parking_robot/robot_description/meshes/IMU_sensor.stl</uri>
            </mesh>
          </geometry>
        </visual>
        <visual name='base_footprint_fixed_joint_lump__kinect_v2_visual_2'>
          <pose>0.297 -0.05 0.203587 0 -0 0</pose>
          <geometry>
            <mesh>
              <scale>0.01 0.01 0.01</scale>
              <uri>/home/jinmin/zm_ws/src/parking_robot/robot_description/meshes/kinect_v2.stl</uri>
            </mesh>
          </geometry>
          <material>
            <script>
              <name>Gazebo/Black</name>
              <uri>file://media/materials/scripts/gazebo.material</uri>
            </script>
          </material>
        </visual>
        <visual name='base_footprint_fixed_joint_lump__sick_lidar0_visual_3'>
          <pose>0.33 0.175 0.277294 0 -0 0.7854</pose>
          <geometry>
            <mesh>
              <scale>0.01 0.01 0.01</scale>
              <uri>/home/jinmin/zm_ws/src/parking_robot/robot_description/meshes/sick_s30b.stl</uri>
            </mesh>
          </geometry>
          <material>
            <script>
              <name>Gazebo/Yellow</name>
              <uri>file://media/materials/scripts/gazebo.material</uri>
            </script>
          </material>
        </visual>
        <visual name='base_footprint_fixed_joint_lump__sick_lidar1_visual_4'>
          <pose>-0.33 -0.175 0.277294 0 0 -2.35619</pose>
          <geometry>
            <mesh>
              <scale>0.01 0.01 0.01</scale>
              <uri>/home/jinmin/zm_ws/src/parking_robot/robot_description/meshes/sick_s30b.stl</uri>
            </mesh>
          </geometry>
          <material>
            <script>
              <name>Gazebo/Yellow</name>
              <uri>file://media/materials/scripts/gazebo.material</uri>
            </script>
          </material>
        </visual>
        <visual name='base_footprint_fixed_joint_lump__ultrasound_1_visual_5'>
          <pose>0.4 0.15 0.111572 0 -0 0</pose>
          <geometry>
            <mesh>
              <scale>0.1 0.1 0.1</scale>
              <uri>/home/jinmin/zm_ws/src/parking_robot/robot_description/meshes/ultrasound.stl</uri>
            </mesh>
          </geometry>
        </visual>
        <visual name='base_footprint_fixed_joint_lump__ultrasound_2_visual_6'>
          <pose>0.4 -0.15 0.111572 0 -0 0</pose>
          <geometry>
            <mesh>
              <scale>0.1 0.1 0.1</scale>
              <uri>/home/jinmin/zm_ws/src/parking_robot/robot_description/meshes/ultrasound.stl</uri>
            </mesh>
          </geometry>
        </visual>
        <visual name='base_footprint_fixed_joint_lump__ultrasound_3_visual_7'>
          <pose>-0.4 0.15 0.111572 0 0 -3.14159</pose>
          <geometry>
            <mesh>
              <scale>0.1 0.1 0.1</scale>
              <uri>/home/jinmin/zm_ws/src/parking_robot/robot_description/meshes/ultrasound.stl</uri>
            </mesh>
          </geometry>
        </visual>
        <visual name='base_footprint_fixed_joint_lump__ultrasound_4_visual_8'>
          <pose>-0.4 -0.15 0.111572 0 0 -3.14159</pose>
          <geometry>
            <mesh>
              <scale>0.1 0.1 0.1</scale>
              <uri>/home/jinmin/zm_ws/src/parking_robot/robot_description/meshes/ultrasound.stl</uri>
            </mesh>
          </geometry>
        </visual>
        <gravity>1</gravity>
        <gravity>1</gravity>
        <sensor name='imu_sensor' type='imu'>
          <always_on>1</always_on>
          <update_rate>100</update_rate>
          <visualize>1</visualize>
          <topic>__default_topic__</topic>
          <plugin name='imu_plugin' filename='libgazebo_ros_imu_sensor.so'>
            <topicName>robot1_imu</topicName>
            <bodyName>IMU_sensor</bodyName>
            <updateRateHZ>10.0</updateRateHZ>
            <gaussianNoise>0.0</gaussianNoise>
            <xyzOffset>0 0 0</xyzOffset>
            <rpyOffset>0 0 0</rpyOffset>
            <frameName>IMU_sensor</frameName>
            <initialOrientationAsReference>0</initialOrientationAsReference>
            <robotNamespace>/</robotNamespace>
          </plugin>
          <pose>0 0 0.161572 0 -0 0</pose>
          <imu/>
        </sensor>
        <gravity>1</gravity>
        <sensor name='kinect_v2_camera' type='depth'>
          <update_rate>30</update_rate>
          <camera>
            <horizontal_fov>1.0472</horizontal_fov>
            <image>
              <width>960</width>
              <height>540</height>
              <format>R8G8B8</format>
            </image>
            <clip>
              <near>0.05</near>
              <far>3</far>
            </clip>
          </camera>
          <plugin name='kinect_v2_controller' filename='libgazebo_ros_openni_kinect.so'>
            <baseline>0.2</baseline>
            <alwaysOn>1</alwaysOn>
            <updateRate>1.0</updateRate>
            <cameraName>kinect_v2_ir</cameraName>
            <imageTopicName>/kinect_v2/color/image_raw</imageTopicName>
            <cameraInfoTopicName>/kinect_v2/color/camera_info</cameraInfoTopicName>
            <depthImageTopicName>/kinect_v2/depth/image_raw</depthImageTopicName>
            <depthImageInfoTopicName>/kinect_v2/depth/camera_info</depthImageInfoTopicName>
            <pointCloudTopicName>/kinect_v2/depth/points</pointCloudTopicName>
            <frameName>kinect_v2</frameName>
            <pointCloudCutoff>0.5</pointCloudCutoff>
            <pointCloudCutoffMax>3.0</pointCloudCutoffMax>
            <distortionK1>0.00000001</distortionK1>
            <distortionK2>0.00000001</distortionK2>
            <distortionK3>0.00000001</distortionK3>
            <distortionT1>0.00000001</distortionT1>
            <distortionT2>0.00000001</distortionT2>
            <CxPrime>0</CxPrime>
            <Cx>0</Cx>
            <Cy>0</Cy>
            <focalLength>0</focalLength>
            <hackBaseline>0</hackBaseline>
            <robotNamespace>/</robotNamespace>
          </plugin>
          <pose>0.297 -0.05 0.203587 0 -0 0</pose>
        </sensor>
        <gravity>1</gravity>
        <sensor name='sick_LiDAR0_sensor' type='ray'>
          <visualize>0</visualize>
          <update_rate>40</update_rate>
          <ray>
            <scan>
              <horizontal>
                <samples>720</samples>
                <resolution>1</resolution>
                <min_angle>-2.35619</min_angle>
                <max_angle>2.35619</max_angle>
              </horizontal>
              <vertical>
                <samples>1</samples>
                <min_angle>0</min_angle>
                <max_angle>0</max_angle>
              </vertical>
            </scan>
            <range>
              <min>0.1</min>
              <max>30</max>
              <resolution>0.01</resolution>
            </range>
            <noise>
              <type>gaussian</type>
              <mean>0</mean>
              <stddev>0.01</stddev>
            </noise>
          </ray>
          <plugin name='gazebo_ros_head_hokuyo_controller' filename='libgazebo_ros_laser.so'>
            <topicName>/sick_s30b/laser/scan0</topicName>
            <frameName>sick_lidar0</frameName>
            <robotNamespace>/</robotNamespace>
          </plugin>
          <pose>0.33 0.175 0.277294 0 -0 0.7854</pose>
        </sensor>
        <self_collide>0</self_collide>
        <gravity>1</gravity>
        <sensor name='sick_LiDAR1_sensor' type='ray'>
          <visualize>0</visualize>
          <update_rate>40</update_rate>
          <ray>
            <scan>
              <horizontal>
                <samples>720</samples>
                <resolution>1</resolution>
                <min_angle>-2.35619</min_angle>
                <max_angle>2.35619</max_angle>
              </horizontal>
              <vertical>
                <samples>1</samples>
                <min_angle>0</min_angle>
                <max_angle>0</max_angle>
              </vertical>
            </scan>
            <range>
              <min>0.1</min>
              <max>30</max>
              <resolution>0.01</resolution>
            </range>
            <noise>
              <type>gaussian</type>
              <mean>0</mean>
              <stddev>0.01</stddev>
            </noise>
          </ray>
          <plugin name='gazebo_ros_head_hokuyo_controller' filename='libgazebo_ros_laser.so'>
            <topicName>/sick_s30b/laser/scan1</topicName>
            <frameName>sick_lidar1</frameName>
            <robotNamespace>/</robotNamespace>
          </plugin>
          <pose>-0.33 -0.175 0.277294 0 0 -2.35619</pose>
        </sensor>
        <sensor name='TeraRanger' type='ray'>
          <visualize>1</visualize>
          <update_rate>50</update_rate>
          <ray>
            <scan>
              <horizontal>
                <samples>10</samples>
                <resolution>1</resolution>
                <min_angle>-0.14835</min_angle>
                <max_angle>0.14835</max_angle>
              </horizontal>
              <vertical>
                <samples>10</samples>
                <resolution>1</resolution>
                <min_angle>-0.14835</min_angle>
                <max_angle>0.14835</max_angle>
              </vertical>
            </scan>
            <range>
              <min>0.03</min>
              <max>0.5</max>
              <resolution>0.01</resolution>
            </range>
          </ray>
          <plugin name='gazebo_ros_range' filename='libgazebo_ros_range.so'>
            <gaussianNoise>0.005</gaussianNoise>
            <alwaysOn>1</alwaysOn>
            <updateRate>50</updateRate>
            <topicName>/ultrasound_1</topicName>
            <frameName>ultrasound_1</frameName>
            <radiation>INFRARED</radiation>
            <fov>0.5</fov>
            <robotNamespace>/</robotNamespace>
          </plugin>
          <pose>0.4 0.15 0.111572 0 -0 0</pose>
        </sensor>
        <sensor name='TeraRanger' type='ray'>
          <visualize>1</visualize>
          <update_rate>50</update_rate>
          <ray>
            <scan>
              <horizontal>
                <samples>10</samples>
                <resolution>1</resolution>
                <min_angle>-0.14835</min_angle>
                <max_angle>0.14835</max_angle>
              </horizontal>
              <vertical>
                <samples>10</samples>
                <resolution>1</resolution>
                <min_angle>-0.14835</min_angle>
                <max_angle>0.14835</max_angle>
              </vertical>
            </scan>
            <range>
              <min>0.03</min>
              <max>0.5</max>
              <resolution>0.01</resolution>
            </range>
          </ray>
          <plugin name='gazebo_ros_range' filename='libgazebo_ros_range.so'>
            <gaussianNoise>0.005</gaussianNoise>
            <alwaysOn>1</alwaysOn>
            <updateRate>50</updateRate>
            <topicName>/ultrasound_2</topicName>
            <frameName>ultrasound_2</frameName>
            <radiation>INFRARED</radiation>
            <fov>0.5</fov>
            <robotNamespace>/</robotNamespace>
          </plugin>
          <pose>0.4 -0.15 0.111572 0 -0 0</pose>
        </sensor>
        <sensor name='TeraRanger' type='ray'>
          <visualize>1</visualize>
          <update_rate>50</update_rate>
          <ray>
            <scan>
              <horizontal>
                <samples>10</samples>
                <resolution>1</resolution>
                <min_angle>-0.14835</min_angle>
                <max_angle>0.14835</max_angle>
              </horizontal>
              <vertical>
                <samples>10</samples>
                <resolution>1</resolution>
                <min_angle>-0.14835</min_angle>
                <max_angle>0.14835</max_angle>
              </vertical>
            </scan>
            <range>
              <min>0.03</min>
              <max>0.5</max>
              <resolution>0.01</resolution>
            </range>
          </ray>
          <plugin name='gazebo_ros_range' filename='libgazebo_ros_range.so'>
            <gaussianNoise>0.005</gaussianNoise>
            <alwaysOn>1</alwaysOn>
            <updateRate>50</updateRate>
            <topicName>/ultrasound_3</topicName>
            <frameName>ultrasound_3</frameName>
            <radiation>INFRARED</radiation>
            <fov>0.5</fov>
            <robotNamespace>/</robotNamespace>
          </plugin>
          <pose>-0.4 0.15 0.111572 0 -0 -3.14159</pose>
        </sensor>
        <sensor name='TeraRanger' type='ray'>
          <visualize>1</visualize>
          <update_rate>50</update_rate>
          <ray>
            <scan>
              <horizontal>
                <samples>10</samples>
                <resolution>1</resolution>
                <min_angle>-0.14835</min_angle>
                <max_angle>0.14835</max_angle>
              </horizontal>
              <vertical>
                <samples>10</samples>
                <resolution>1</resolution>
                <min_angle>-0.14835</min_angle>
                <max_angle>0.14835</max_angle>
              </vertical>
            </scan>
            <range>
              <min>0.03</min>
              <max>0.5</max>
              <resolution>0.01</resolution>
            </range>
          </ray>
          <plugin name='gazebo_ros_range' filename='libgazebo_ros_range.so'>
            <gaussianNoise>0.005</gaussianNoise>
            <alwaysOn>1</alwaysOn>
            <updateRate>50</updateRate>
            <topicName>/ultrasound_4</topicName>
            <frameName>ultrasound_4</frameName>
            <radiation>INFRARED</radiation>
            <fov>0.5</fov>
            <robotNamespace>/</robotNamespace>
          </plugin>
          <pose>-0.4 -0.15 0.111572 0 -0 -3.14159</pose>
        </sensor>
        <enable_wind>0</enable_wind>
        <kinematic>0</kinematic>
      </link>
      <joint name='wheel_joint_1' type='revolute'>
        <pose relative_to='base_footprint'>-0.25 0.3 0.081572 -1.5708 0 0</pose>
        <parent>base_footprint</parent>
        <child>wheel_1</child>
        <axis>
          <xyz>0 0 1</xyz>
          <limit>
            <lower>-1e+16</lower>
            <upper>1e+16</upper>
          </limit>
          <dynamics>
            <damping>3</damping>
            <friction>5</friction>
            <spring_reference>0</spring_reference>
            <spring_stiffness>0</spring_stiffness>
          </dynamics>
        </axis>
      </joint>
      <link name='wheel_1'>
        <pose relative_to='wheel_joint_1'>0 0 0 0 -0 0</pose>
        <inertial>
          <pose>0.001 0 0 0 -0 0</pose>
          <mass>1.7</mass>
          <inertia>
            <ixx>0.00424805</ixx>
            <ixy>0</ixy>
            <ixz>0</ixz>
            <iyy>0.00424804</iyy>
            <iyz>0</iyz>
            <izz>0.00487997</izz>
          </inertia>
        </inertial>
        <collision name='wheel_1_collision'>
          <pose>0 0 0 0 -0 0</pose>
          <geometry>
            <mesh>
              <scale>0.01 0.01 0.01</scale>
              <uri>/home/jinmin/zm_ws/src/parking_robot/robot_description/meshes/mecanum_left_after.stl</uri>
            </mesh>
          </geometry>
          <surface>
            <contact>
              <ode>
                <kp>1e+50</kp>
                <kd>1e+50</kd>
              </ode>
            </contact>
            <friction>
              <ode>
                <mu>30</mu>
                <mu2>30</mu2>
              </ode>
              <torsional>
                <ode/>
              </torsional>
            </friction>
            <bounce/>
          </surface>
          <max_contacts>10</max_contacts>
        </collision>
        <visual name='wheel_1_visual'>
          <pose>0 0 0 0 -0 0</pose>
          <geometry>
            <mesh>
              <scale>0.01 0.01 0.01</scale>
              <uri>/home/jinmin/zm_ws/src/parking_robot/robot_description/meshes/mecanum_left_after.stl</uri>
            </mesh>
          </geometry>
          <material>
            <script>
              <name>Gazebo/White</name>
              <uri>file://media/materials/scripts/gazebo.material</uri>
            </script>
          </material>
        </visual>
        <self_collide>0</self_collide>
        <gravity>1</gravity>
        <enable_wind>0</enable_wind>
        <kinematic>0</kinematic>
      </link>
      <joint name='roller_1_1_joint' type='revolute'>
        <pose relative_to='wheel_1'>0 0.065 0 0.7854 -0 1.5708</pose>
        <parent>wheel_1</parent>
        <child>roller_1_1</child>
        <axis>
          <xyz>0 0 1</xyz>
          <limit>
            <lower>-1e+16</lower>
            <upper>1e+16</upper>
          </limit>
          <dynamics>
            <damping>0</damping>
            <friction>0</friction>
            <spring_reference>0</spring_reference>
            <spring_stiffness>0</spring_stiffness>
          </dynamics>
        </axis>
      </joint>
      <link name='roller_1_1'>
        <pose relative_to='roller_1_1_joint'>0 0 0 0 -0 0</pose>
        <inertial>
          <pose>0 0 0 0 -0 0</pose>
          <mass>0.124</mass>
          <inertia>
            <ixx>0.0051893</ixx>
            <ixy>0</ixy>
            <ixz>0</ixz>
            <iyy>0.0051893</iyy>
            <iyz>0</iyz>
            <izz>0.0013891</izz>
          </inertia>
        </inertial>
        <collision name='roller_1_1_collision'>
          <pose>0 0 0 0 -0 0</pose>
          <geometry>
            <mesh>
              <scale>0.01 0.01 0.01</scale>
              <uri>/home/jinmin/zm_ws/src/parking_robot/robot_description/meshes/mecanum_roller.stl</uri>
            </mesh>
          </geometry>
          <surface>
            <contact>
              <ode>
                <kp>1e+50</kp>
                <kd>1e+50</kd>
              </ode>
            </contact>
            <friction>
              <ode>
                <mu>30</mu>
                <mu2>30</mu2>
              </ode>
              <torsional>
                <ode/>
              </torsional>
            </friction>
            <bounce/>
          </surface>
          <max_contacts>10</max_contacts>
        </collision>
        <visual name='roller_1_1_visual'>
          <pose>0 0 0 0 -0 0</pose>
          <geometry>
            <mesh>
              <scale>0.01 0.01 0.01</scale>
              <uri>/home/jinmin/zm_ws/src/parking_robot/robot_description/meshes/mecanum_roller.stl</uri>
            </mesh>
          </geometry>
          <material>
            <script>
              <name>Gazebo/Black</name>
              <uri>file://media/materials/scripts/gazebo.material</uri>
            </script>
          </material>
        </visual>
        <self_collide>0</self_collide>
        <gravity>1</gravity>
        <enable_wind>0</enable_wind>
        <kinematic>0</kinematic>
      </link>
      <joint name='roller_1_2_joint' type='revolute'>
        <pose relative_to='wheel_1'>0.041781 0.049792 0 0.7854 -0 0.8727</pose>
        <parent>wheel_1</parent>
        <child>roller_1_2</child>
        <axis>
          <xyz>0 0 1</xyz>
          <limit>
            <lower>-1e+16</lower>
            <upper>1e+16</upper>
          </limit>
          <dynamics>
            <damping>0</damping>
            <friction>0</friction>
            <spring_reference>0</spring_reference>
            <spring_stiffness>0</spring_stiffness>
          </dynamics>
        </axis>
      </joint>
      <link name='roller_1_2'>
        <pose relative_to='roller_1_2_joint'>0 0 0 0 -0 0</pose>
        <inertial>
          <pose>0 0 0 0 -0 0</pose>
          <mass>0.124</mass>
          <inertia>
            <ixx>0.0051893</ixx>
            <ixy>0</ixy>
            <ixz>0</ixz>
            <iyy>0.0051893</iyy>
            <iyz>0</iyz>
            <izz>0.0013891</izz>
          </inertia>
        </inertial>
        <collision name='roller_1_2_collision'>
          <pose>0 0 0 0 -0 0</pose>
          <geometry>
            <mesh>
              <scale>0.01 0.01 0.01</scale>
              <uri>/home/jinmin/zm_ws/src/parking_robot/robot_description/meshes/mecanum_roller.stl</uri>
            </mesh>
          </geometry>
          <surface>
            <contact>
              <ode>
                <kp>1e+50</kp>
                <kd>1e+50</kd>
              </ode>
            </contact>
            <friction>
              <ode>
                <mu>30</mu>
                <mu2>30</mu2>
              </ode>
              <torsional>
                <ode/>
              </torsional>
            </friction>
            <bounce/>
          </surface>
          <max_contacts>10</max_contacts>
        </collision>
        <visual name='roller_1_2_visual'>
          <pose>0 0 0 0 -0 0</pose>
          <geometry>
            <mesh>
              <scale>0.01 0.01 0.01</scale>
              <uri>/home/jinmin/zm_ws/src/parking_robot/robot_description/meshes/mecanum_roller.stl</uri>
            </mesh>
          </geometry>
          <material>
            <script>
              <name>Gazebo/Black</name>
              <uri>file://media/materials/scripts/gazebo.material</uri>
            </script>
          </material>
        </visual>
        <self_collide>0</self_collide>
        <gravity>1</gravity>
        <enable_wind>0</enable_wind>
        <kinematic>0</kinematic>
      </link>
      <joint name='roller_1_3_joint' type='revolute'>
        <pose relative_to='wheel_1'>0.064012 0.011287 0 0.7854 -0 0.1746</pose>
        <parent>wheel_1</parent>
        <child>roller_1_3</child>
        <axis>
          <xyz>0 0 1</xyz>
          <limit>
            <lower>-1e+16</lower>
            <upper>1e+16</upper>
          </limit>
          <dynamics>
            <damping>0</damping>
            <friction>0</friction>
            <spring_reference>0</spring_reference>
            <spring_stiffness>0</spring_stiffness>
          </dynamics>
        </axis>
      </joint>
      <link name='roller_1_3'>
        <pose relative_to='roller_1_3_joint'>0 0 0 0 -0 0</pose>
        <inertial>
          <pose>0 0 0 0 -0 0</pose>
          <mass>0.124</mass>
          <inertia>
            <ixx>0.0051893</ixx>
            <ixy>0</ixy>
            <ixz>0</ixz>
            <iyy>0.0051893</iyy>
            <iyz>0</iyz>
            <izz>0.0013891</izz>
          </inertia>
        </inertial>
        <collision name='roller_1_3_collision'>
          <pose>0 0 0 0 -0 0</pose>
          <geometry>
            <mesh>
              <scale>0.01 0.01 0.01</scale>
              <uri>/home/jinmin/zm_ws/src/parking_robot/robot_description/meshes/mecanum_roller.stl</uri>
            </mesh>
          </geometry>
          <surface>
            <contact>
              <ode>
                <kp>1e+50</kp>
                <kd>1e+50</kd>
              </ode>
            </contact>
            <friction>
              <ode>
                <mu>30</mu>
                <mu2>30</mu2>
              </ode>
              <torsional>
                <ode/>
              </torsional>
            </friction>
            <bounce/>
          </surface>
          <max_contacts>10</max_contacts>
        </collision>
        <visual name='roller_1_3_visual'>
          <pose>0 0 0 0 -0 0</pose>
          <geometry>
            <mesh>
              <scale>0.01 0.01 0.01</scale>
              <uri>/home/jinmin/zm_ws/src/parking_robot/robot_description/meshes/mecanum_roller.stl</uri>
            </mesh>
          </geometry>
          <material>
            <script>
              <name>Gazebo/Black</name>
              <uri>file://media/materials/scripts/gazebo.material</uri>
            </script>
          </material>
        </visual>
        <self_collide>0</self_collide>
        <gravity>1</gravity>
        <enable_wind>0</enable_wind>
        <kinematic>0</kinematic>
      </link>
      <joint name='roller_1_4_joint' type='revolute'>
        <pose relative_to='wheel_1'>0.056291 -0.0325 0 0.7854 -0 -0.5235</pose>
        <parent>wheel_1</parent>
        <child>roller_1_4</child>
        <axis>
          <xyz>0 0 1</xyz>
          <limit>
            <lower>-1e+16</lower>
            <upper>1e+16</upper>
          </limit>
          <dynamics>
            <damping>0</damping>
            <friction>0</friction>
            <spring_reference>0</spring_reference>
            <spring_stiffness>0</spring_stiffness>
          </dynamics>
        </axis>
      </joint>
      <link name='roller_1_4'>
        <pose relative_to='roller_1_4_joint'>0 0 0 0 -0 0</pose>
        <inertial>
          <pose>0 0 0 0 -0 0</pose>
          <mass>0.124</mass>
          <inertia>
            <ixx>0.0051893</ixx>
            <ixy>0</ixy>
            <ixz>0</ixz>
            <iyy>0.0051893</iyy>
            <iyz>0</iyz>
            <izz>0.0013891</izz>
          </inertia>
        </inertial>
        <collision name='roller_1_4_collision'>
          <pose>0 0 0 0 -0 0</pose>
          <geometry>
            <mesh>
              <scale>0.01 0.01 0.01</scale>
              <uri>/home/jinmin/zm_ws/src/parking_robot/robot_description/meshes/mecanum_roller.stl</uri>
            </mesh>
          </geometry>
          <surface>
            <contact>
              <ode>
                <kp>1e+50</kp>
                <kd>1e+50</kd>
              </ode>
            </contact>
            <friction>
              <ode>
                <mu>30</mu>
                <mu2>30</mu2>
              </ode>
              <torsional>
                <ode/>
              </torsional>
            </friction>
            <bounce/>
          </surface>
          <max_contacts>10</max_contacts>
        </collision>
        <visual name='roller_1_4_visual'>
          <pose>0 0 0 0 -0 0</pose>
          <geometry>
            <mesh>
              <scale>0.01 0.01 0.01</scale>
              <uri>/home/jinmin/zm_ws/src/parking_robot/robot_description/meshes/mecanum_roller.stl</uri>
            </mesh>
          </geometry>
          <material>
            <script>
              <name>Gazebo/Black</name>
              <uri>file://media/materials/scripts/gazebo.material</uri>
            </script>
          </material>
        </visual>
        <self_collide>0</self_collide>
        <gravity>1</gravity>
        <enable_wind>0</enable_wind>
        <kinematic>0</kinematic>
      </link>
      <joint name='roller_1_5_joint' type='revolute'>
        <pose relative_to='wheel_1'>0.022231 -0.06108 0 0.7854 0 -1.2216</pose>
        <parent>wheel_1</parent>
        <child>roller_1_5</child>
        <axis>
          <xyz>0 0 1</xyz>
          <limit>
            <lower>-1e+16</lower>
            <upper>1e+16</upper>
          </limit>
          <dynamics>
            <damping>0</damping>
            <friction>0</friction>
            <spring_reference>0</spring_reference>
            <spring_stiffness>0</spring_stiffness>
          </dynamics>
        </axis>
      </joint>
      <link name='roller_1_5'>
        <pose relative_to='roller_1_5_joint'>0 0 0 0 -0 0</pose>
        <inertial>
          <pose>0 0 0 0 -0 0</pose>
          <mass>0.124</mass>
          <inertia>
            <ixx>0.0051893</ixx>
            <ixy>0</ixy>
            <ixz>0</ixz>
            <iyy>0.0051893</iyy>
            <iyz>0</iyz>
            <izz>0.0013891</izz>
          </inertia>
        </inertial>
        <collision name='roller_1_5_collision'>
          <pose>0 0 0 0 -0 0</pose>
          <geometry>
            <mesh>
              <scale>0.01 0.01 0.01</scale>
              <uri>/home/jinmin/zm_ws/src/parking_robot/robot_description/meshes/mecanum_roller.stl</uri>
            </mesh>
          </geometry>
          <surface>
            <contact>
              <ode>
                <kp>1e+50</kp>
                <kd>1e+50</kd>
              </ode>
            </contact>
            <friction>
              <ode>
                <mu>30</mu>
                <mu2>30</mu2>
              </ode>
              <torsional>
                <ode/>
              </torsional>
            </friction>
            <bounce/>
          </surface>
          <max_contacts>10</max_contacts>
        </collision>
        <visual name='roller_1_5_visual'>
          <pose>0 0 0 0 -0 0</pose>
          <geometry>
            <mesh>
              <scale>0.01 0.01 0.01</scale>
              <uri>/home/jinmin/zm_ws/src/parking_robot/robot_description/meshes/mecanum_roller.stl</uri>
            </mesh>
          </geometry>
          <material>
            <script>
              <name>Gazebo/Black</name>
              <uri>file://media/materials/scripts/gazebo.material</uri>
            </script>
          </material>
        </visual>
        <self_collide>0</self_collide>
        <gravity>1</gravity>
        <enable_wind>0</enable_wind>
        <kinematic>0</kinematic>
      </link>
      <joint name='roller_1_6_joint' type='revolute'>
        <pose relative_to='wheel_1'>-0.022231 -0.06108 0 0.7854 -0 -1.91999</pose>
        <parent>wheel_1</parent>
        <child>roller_1_6</child>
        <axis>
          <xyz>0 0 1</xyz>
          <limit>
            <lower>-1e+16</lower>
            <upper>1e+16</upper>
          </limit>
          <dynamics>
            <damping>0</damping>
            <friction>0</friction>
            <spring_reference>0</spring_reference>
            <spring_stiffness>0</spring_stiffness>
          </dynamics>
        </axis>
      </joint>
      <link name='roller_1_6'>
        <pose relative_to='roller_1_6_joint'>0 0 0 0 -0 0</pose>
        <inertial>
          <pose>0 0 0 0 -0 0</pose>
          <mass>0.124</mass>
          <inertia>
            <ixx>0.0051893</ixx>
            <ixy>0</ixy>
            <ixz>0</ixz>
            <iyy>0.0051893</iyy>
            <iyz>0</iyz>
            <izz>0.0013891</izz>
          </inertia>
        </inertial>
        <collision name='roller_1_6_collision'>
          <pose>0 0 0 0 -0 0</pose>
          <geometry>
            <mesh>
              <scale>0.01 0.01 0.01</scale>
              <uri>/home/jinmin/zm_ws/src/parking_robot/robot_description/meshes/mecanum_roller.stl</uri>
            </mesh>
          </geometry>
          <surface>
            <contact>
              <ode>
                <kp>1e+50</kp>
                <kd>1e+50</kd>
              </ode>
            </contact>
            <friction>
              <ode>
                <mu>30</mu>
                <mu2>30</mu2>
              </ode>
              <torsional>
                <ode/>
              </torsional>
            </friction>
            <bounce/>
          </surface>
          <max_contacts>10</max_contacts>
        </collision>
        <visual name='roller_1_6_visual'>
          <pose>0 0 0 0 -0 0</pose>
          <geometry>
            <mesh>
              <scale>0.01 0.01 0.01</scale>
              <uri>/home/jinmin/zm_ws/src/parking_robot/robot_description/meshes/mecanum_roller.stl</uri>
            </mesh>
          </geometry>
          <material>
            <script>
              <name>Gazebo/Black</name>
              <uri>file://media/materials/scripts/gazebo.material</uri>
            </script>
          </material>
        </visual>
        <self_collide>0</self_collide>
        <gravity>1</gravity>
        <enable_wind>0</enable_wind>
        <kinematic>0</kinematic>
      </link>
      <joint name='roller_1_7_joint' type='revolute'>
        <pose relative_to='wheel_1'>-0.056291 -0.0325 0 0.7854 -0 -2.61809</pose>
        <parent>wheel_1</parent>
        <child>roller_1_7</child>
        <axis>
          <xyz>0 0 1</xyz>
          <limit>
            <lower>-1e+16</lower>
            <upper>1e+16</upper>
          </limit>
          <dynamics>
            <damping>0</damping>
            <friction>0</friction>
            <spring_reference>0</spring_reference>
            <spring_stiffness>0</spring_stiffness>
          </dynamics>
        </axis>
      </joint>
      <link name='roller_1_7'>
        <pose relative_to='roller_1_7_joint'>0 0 0 0 -0 0</pose>
        <inertial>
          <pose>0 0 0 0 -0 0</pose>
          <mass>0.124</mass>
          <inertia>
            <ixx>0.0051893</ixx>
            <ixy>0</ixy>
            <ixz>0</ixz>
            <iyy>0.0051893</iyy>
            <iyz>0</iyz>
            <izz>0.0013891</izz>
          </inertia>
        </inertial>
        <collision name='roller_1_7_collision'>
          <pose>0 0 0 0 -0 0</pose>
          <geometry>
            <mesh>
              <scale>0.01 0.01 0.01</scale>
              <uri>/home/jinmin/zm_ws/src/parking_robot/robot_description/meshes/mecanum_roller.stl</uri>
            </mesh>
          </geometry>
          <surface>
            <contact>
              <ode>
                <kp>1e+50</kp>
                <kd>1e+50</kd>
              </ode>
            </contact>
            <friction>
              <ode>
                <mu>30</mu>
                <mu2>30</mu2>
              </ode>
              <torsional>
                <ode/>
              </torsional>
            </friction>
            <bounce/>
          </surface>
          <max_contacts>10</max_contacts>
        </collision>
        <visual name='roller_1_7_visual'>
          <pose>0 0 0 0 -0 0</pose>
          <geometry>
            <mesh>
              <scale>0.01 0.01 0.01</scale>
              <uri>/home/jinmin/zm_ws/src/parking_robot/robot_description/meshes/mecanum_roller.stl</uri>
            </mesh>
          </geometry>
          <material>
            <script>
              <name>Gazebo/Black</name>
              <uri>file://media/materials/scripts/gazebo.material</uri>
            </script>
          </material>
        </visual>
        <self_collide>0</self_collide>
        <gravity>1</gravity>
        <enable_wind>0</enable_wind>
        <kinematic>0</kinematic>
      </link>
      <joint name='roller_1_8_joint' type='revolute'>
        <pose relative_to='wheel_1'>-0.064012 0.011287 0 0.7854 -0 2.967</pose>
        <parent>wheel_1</parent>
        <child>roller_1_8</child>
        <axis>
          <xyz>0 0 1</xyz>
          <limit>
            <lower>-1e+16</lower>
            <upper>1e+16</upper>
          </limit>
          <dynamics>
            <damping>0</damping>
            <friction>0</friction>
            <spring_reference>0</spring_reference>
            <spring_stiffness>0</spring_stiffness>
          </dynamics>
        </axis>
      </joint>
      <link name='roller_1_8'>
        <pose relative_to='roller_1_8_joint'>0 0 0 0 -0 0</pose>
        <inertial>
          <pose>0 0 0 0 -0 0</pose>
          <mass>0.124</mass>
          <inertia>
            <ixx>0.0051893</ixx>
            <ixy>0</ixy>
            <ixz>0</ixz>
            <iyy>0.0051893</iyy>
            <iyz>0</iyz>
            <izz>0.0013891</izz>
          </inertia>
        </inertial>
        <collision name='roller_1_8_collision'>
          <pose>0 0 0 0 -0 0</pose>
          <geometry>
            <mesh>
              <scale>0.01 0.01 0.01</scale>
              <uri>/home/jinmin/zm_ws/src/parking_robot/robot_description/meshes/mecanum_roller.stl</uri>
            </mesh>
          </geometry>
          <surface>
            <contact>
              <ode>
                <kp>1e+50</kp>
                <kd>1e+50</kd>
              </ode>
            </contact>
            <friction>
              <ode>
                <mu>30</mu>
                <mu2>30</mu2>
              </ode>
              <torsional>
                <ode/>
              </torsional>
            </friction>
            <bounce/>
          </surface>
          <max_contacts>10</max_contacts>
        </collision>
        <visual name='roller_1_8_visual'>
          <pose>0 0 0 0 -0 0</pose>
          <geometry>
            <mesh>
              <scale>0.01 0.01 0.01</scale>
              <uri>/home/jinmin/zm_ws/src/parking_robot/robot_description/meshes/mecanum_roller.stl</uri>
            </mesh>
          </geometry>
          <material>
            <script>
              <name>Gazebo/Black</name>
              <uri>file://media/materials/scripts/gazebo.material</uri>
            </script>
          </material>
        </visual>
        <self_collide>0</self_collide>
        <gravity>1</gravity>
        <enable_wind>0</enable_wind>
        <kinematic>0</kinematic>
      </link>
      <joint name='roller_1_9_joint' type='revolute'>
        <pose relative_to='wheel_1'>-0.041781 0.049792 0 0.7854 -0 2.2689</pose>
        <parent>wheel_1</parent>
        <child>roller_1_9</child>
        <axis>
          <xyz>0 0 1</xyz>
          <limit>
            <lower>-1e+16</lower>
            <upper>1e+16</upper>
          </limit>
          <dynamics>
            <damping>0</damping>
            <friction>0</friction>
            <spring_reference>0</spring_reference>
            <spring_stiffness>0</spring_stiffness>
          </dynamics>
        </axis>
      </joint>
      <link name='roller_1_9'>
        <pose relative_to='roller_1_9_joint'>0 0 0 0 -0 0</pose>
        <inertial>
          <pose>0 0 0 0 -0 0</pose>
          <mass>0.124</mass>
          <inertia>
            <ixx>0.0051893</ixx>
            <ixy>0</ixy>
            <ixz>0</ixz>
            <iyy>0.0051893</iyy>
            <iyz>0</iyz>
            <izz>0.0013891</izz>
          </inertia>
        </inertial>
        <collision name='roller_1_9_collision'>
          <pose>0 0 0 0 -0 0</pose>
          <geometry>
            <mesh>
              <scale>0.01 0.01 0.01</scale>
              <uri>/home/jinmin/zm_ws/src/parking_robot/robot_description/meshes/mecanum_roller.stl</uri>
            </mesh>
          </geometry>
          <surface>
            <contact>
              <ode>
                <kp>1e+50</kp>
                <kd>1e+50</kd>
              </ode>
            </contact>
            <friction>
              <ode>
                <mu>30</mu>
                <mu2>30</mu2>
              </ode>
              <torsional>
                <ode/>
              </torsional>
            </friction>
            <bounce/>
          </surface>
          <max_contacts>10</max_contacts>
        </collision>
        <visual name='roller_1_9_visual'>
          <pose>0 0 0 0 -0 0</pose>
          <geometry>
            <mesh>
              <scale>0.01 0.01 0.01</scale>
              <uri>/home/jinmin/zm_ws/src/parking_robot/robot_description/meshes/mecanum_roller.stl</uri>
            </mesh>
          </geometry>
          <material>
            <script>
              <name>Gazebo/Black</name>
              <uri>file://media/materials/scripts/gazebo.material</uri>
            </script>
          </material>
        </visual>
        <self_collide>0</self_collide>
        <gravity>1</gravity>
        <enable_wind>0</enable_wind>
        <kinematic>0</kinematic>
      </link>
      <joint name='wheel_joint_2' type='revolute'>
        <pose relative_to='base_footprint'>0.25 0.3 0.081572 -1.5708 0 0</pose>
        <parent>base_footprint</parent>
        <child>wheel_2</child>
        <axis>
          <xyz>0 0 1</xyz>
          <limit>
            <lower>-1e+16</lower>
            <upper>1e+16</upper>
          </limit>
          <dynamics>
            <damping>3</damping>
            <friction>5</friction>
            <spring_reference>0</spring_reference>
            <spring_stiffness>0</spring_stiffness>
          </dynamics>
        </axis>
      </joint>
      <link name='wheel_2'>
        <pose relative_to='wheel_joint_2'>0 0 0 0 -0 0</pose>
        <inertial>
          <pose>0.001 0 0 0 -0 0</pose>
          <mass>1.7</mass>
          <inertia>
            <ixx>0.00424805</ixx>
            <ixy>0</ixy>
            <ixz>0</ixz>
            <iyy>0.00424804</iyy>
            <iyz>0</iyz>
            <izz>0.00487997</izz>
          </inertia>
        </inertial>
        <collision name='wheel_2_collision'>
          <pose>0 0 0 0 -0 0</pose>
          <geometry>
            <mesh>
              <scale>0.01 0.01 0.01</scale>
              <uri>/home/jinmin/zm_ws/src/parking_robot/robot_description/meshes/mecanum_left_before.stl</uri>
            </mesh>
          </geometry>
          <surface>
            <contact>
              <ode>
                <kp>1e+50</kp>
                <kd>1e+50</kd>
              </ode>
            </contact>
            <friction>
              <ode>
                <mu>30</mu>
                <mu2>30</mu2>
              </ode>
              <torsional>
                <ode/>
              </torsional>
            </friction>
            <bounce/>
          </surface>
          <max_contacts>10</max_contacts>
        </collision>
        <visual name='wheel_2_visual'>
          <pose>0 0 0 0 -0 0</pose>
          <geometry>
            <mesh>
              <scale>0.01 0.01 0.01</scale>
              <uri>/home/jinmin/zm_ws/src/parking_robot/robot_description/meshes/mecanum_left_before.stl</uri>
            </mesh>
          </geometry>
          <material>
            <script>
              <name>Gazebo/White</name>
              <uri>file://media/materials/scripts/gazebo.material</uri>
            </script>
          </material>
        </visual>
        <self_collide>0</self_collide>
        <gravity>1</gravity>
        <enable_wind>0</enable_wind>
        <kinematic>0</kinematic>
      </link>
      <joint name='roller_2_1_joint' type='revolute'>
        <pose relative_to='wheel_2'>0.065 0 0 -0.7854 0 0</pose>
        <parent>wheel_2</parent>
        <child>roller_2_1</child>
        <axis>
          <xyz>0 0 1</xyz>
          <limit>
            <lower>-1e+16</lower>
            <upper>1e+16</upper>
          </limit>
          <dynamics>
            <damping>0</damping>
            <friction>0</friction>
            <spring_reference>0</spring_reference>
            <spring_stiffness>0</spring_stiffness>
          </dynamics>
        </axis>
      </joint>
      <link name='roller_2_1'>
        <pose relative_to='roller_2_1_joint'>0 0 0 0 -0 0</pose>
        <inertial>
          <pose>0 0 0 0 -0 0</pose>
          <mass>0.124</mass>
          <inertia>
            <ixx>0.0051893</ixx>
            <ixy>0</ixy>
            <ixz>0</ixz>
            <iyy>0.0051893</iyy>
            <iyz>0</iyz>
            <izz>0.0013891</izz>
          </inertia>
        </inertial>
        <collision name='roller_2_1_collision'>
          <pose>0 0 0 0 -0 0</pose>
          <geometry>
            <mesh>
              <scale>0.01 0.01 0.01</scale>
              <uri>/home/jinmin/zm_ws/src/parking_robot/robot_description/meshes/mecanum_roller.stl</uri>
            </mesh>
          </geometry>
          <surface>
            <contact>
              <ode>
                <kp>1e+50</kp>
                <kd>1e+50</kd>
              </ode>
            </contact>
            <friction>
              <ode>
                <mu>30</mu>
                <mu2>30</mu2>
              </ode>
              <torsional>
                <ode/>
              </torsional>
            </friction>
            <bounce/>
          </surface>
          <max_contacts>10</max_contacts>
        </collision>
        <visual name='roller_2_1_visual'>
          <pose>0 0 0 0 -0 0</pose>
          <geometry>
            <mesh>
              <scale>0.01 0.01 0.01</scale>
              <uri>/home/jinmin/zm_ws/src/parking_robot/robot_description/meshes/mecanum_roller.stl</uri>
            </mesh>
          </geometry>
          <material>
            <script>
              <name>Gazebo/Black</name>
              <uri>file://media/materials/scripts/gazebo.material</uri>
            </script>
          </material>
        </visual>
        <self_collide>0</self_collide>
        <gravity>1</gravity>
        <enable_wind>0</enable_wind>
        <kinematic>0</kinematic>
      </link>
      <joint name='roller_2_2_joint' type='revolute'>
        <pose relative_to='wheel_2'>0.049792 0.041781 0 -0.7854 0 0.6981</pose>
        <parent>wheel_2</parent>
        <child>roller_2_2</child>
        <axis>
          <xyz>0 0 1</xyz>
          <limit>
            <lower>-1e+16</lower>
            <upper>1e+16</upper>
          </limit>
          <dynamics>
            <damping>0</damping>
            <friction>0</friction>
            <spring_reference>0</spring_reference>
            <spring_stiffness>0</spring_stiffness>
          </dynamics>
        </axis>
      </joint>
      <link name='roller_2_2'>
        <pose relative_to='roller_2_2_joint'>0 0 0 0 -0 0</pose>
        <inertial>
          <pose>0 0 0 0 -0 0</pose>
          <mass>0.124</mass>
          <inertia>
            <ixx>0.0051893</ixx>
            <ixy>0</ixy>
            <ixz>0</ixz>
            <iyy>0.0051893</iyy>
            <iyz>0</iyz>
            <izz>0.0013891</izz>
          </inertia>
        </inertial>
        <collision name='roller_2_2_collision'>
          <pose>0 0 0 0 -0 0</pose>
          <geometry>
            <mesh>
              <scale>0.01 0.01 0.01</scale>
              <uri>/home/jinmin/zm_ws/src/parking_robot/robot_description/meshes/mecanum_roller.stl</uri>
            </mesh>
          </geometry>
          <surface>
            <contact>
              <ode>
                <kp>1e+50</kp>
                <kd>1e+50</kd>
              </ode>
            </contact>
            <friction>
              <ode>
                <mu>30</mu>
                <mu2>30</mu2>
              </ode>
              <torsional>
                <ode/>
              </torsional>
            </friction>
            <bounce/>
          </surface>
          <max_contacts>10</max_contacts>
        </collision>
        <visual name='roller_2_2_visual'>
          <pose>0 0 0 0 -0 0</pose>
          <geometry>
            <mesh>
              <scale>0.01 0.01 0.01</scale>
              <uri>/home/jinmin/zm_ws/src/parking_robot/robot_description/meshes/mecanum_roller.stl</uri>
            </mesh>
          </geometry>
          <material>
            <script>
              <name>Gazebo/Black</name>
              <uri>file://media/materials/scripts/gazebo.material</uri>
            </script>
          </material>
        </visual>
        <self_collide>0</self_collide>
        <gravity>1</gravity>
        <enable_wind>0</enable_wind>
        <kinematic>0</kinematic>
      </link>
      <joint name='roller_2_3_joint' type='revolute'>
        <pose relative_to='wheel_2'>0.011287 0.064012 0 -0.7854 -0 1.3962</pose>
        <parent>wheel_2</parent>
        <child>roller_2_3</child>
        <axis>
          <xyz>0 0 1</xyz>
          <limit>
            <lower>-1e+16</lower>
            <upper>1e+16</upper>
          </limit>
          <dynamics>
            <damping>0</damping>
            <friction>0</friction>
            <spring_reference>0</spring_reference>
            <spring_stiffness>0</spring_stiffness>
          </dynamics>
        </axis>
      </joint>
      <link name='roller_2_3'>
        <pose relative_to='roller_2_3_joint'>0 0 0 0 -0 0</pose>
        <inertial>
          <pose>0 0 0 0 -0 0</pose>
          <mass>0.124</mass>
          <inertia>
            <ixx>0.0051893</ixx>
            <ixy>0</ixy>
            <ixz>0</ixz>
            <iyy>0.0051893</iyy>
            <iyz>0</iyz>
            <izz>0.0013891</izz>
          </inertia>
        </inertial>
        <collision name='roller_2_3_collision'>
          <pose>0 0 0 0 -0 0</pose>
          <geometry>
            <mesh>
              <scale>0.01 0.01 0.01</scale>
              <uri>/home/jinmin/zm_ws/src/parking_robot/robot_description/meshes/mecanum_roller.stl</uri>
            </mesh>
          </geometry>
          <surface>
            <contact>
              <ode>
                <kp>1e+50</kp>
                <kd>1e+50</kd>
              </ode>
            </contact>
            <friction>
              <ode>
                <mu>30</mu>
                <mu2>30</mu2>
              </ode>
              <torsional>
                <ode/>
              </torsional>
            </friction>
            <bounce/>
          </surface>
          <max_contacts>10</max_contacts>
        </collision>
        <visual name='roller_2_3_visual'>
          <pose>0 0 0 0 -0 0</pose>
          <geometry>
            <mesh>
              <scale>0.01 0.01 0.01</scale>
              <uri>/home/jinmin/zm_ws/src/parking_robot/robot_description/meshes/mecanum_roller.stl</uri>
            </mesh>
          </geometry>
          <material>
            <script>
              <name>Gazebo/Black</name>
              <uri>file://media/materials/scripts/gazebo.material</uri>
            </script>
          </material>
        </visual>
        <self_collide>0</self_collide>
        <gravity>1</gravity>
        <enable_wind>0</enable_wind>
        <kinematic>0</kinematic>
      </link>
      <joint name='roller_2_4_joint' type='revolute'>
        <pose relative_to='wheel_2'>-0.0325 0.056291 0 -0.7854 0 2.0943</pose>
        <parent>wheel_2</parent>
        <child>roller_2_4</child>
        <axis>
          <xyz>0 0 1</xyz>
          <limit>
            <lower>-1e+16</lower>
            <upper>1e+16</upper>
          </limit>
          <dynamics>
            <damping>0</damping>
            <friction>0</friction>
            <spring_reference>0</spring_reference>
            <spring_stiffness>0</spring_stiffness>
          </dynamics>
        </axis>
      </joint>
      <link name='roller_2_4'>
        <pose relative_to='roller_2_4_joint'>0 0 0 0 -0 0</pose>
        <inertial>
          <pose>0 0 0 0 -0 0</pose>
          <mass>0.124</mass>
          <inertia>
            <ixx>0.0051893</ixx>
            <ixy>0</ixy>
            <ixz>0</ixz>
            <iyy>0.0051893</iyy>
            <iyz>0</iyz>
            <izz>0.0013891</izz>
          </inertia>
        </inertial>
        <collision name='roller_2_4_collision'>
          <pose>0 0 0 0 -0 0</pose>
          <geometry>
            <mesh>
              <scale>0.01 0.01 0.01</scale>
              <uri>/home/jinmin/zm_ws/src/parking_robot/robot_description/meshes/mecanum_roller.stl</uri>
            </mesh>
          </geometry>
          <surface>
            <contact>
              <ode>
                <kp>1e+50</kp>
                <kd>1e+50</kd>
              </ode>
            </contact>
            <friction>
              <ode>
                <mu>30</mu>
                <mu2>30</mu2>
              </ode>
              <torsional>
                <ode/>
              </torsional>
            </friction>
            <bounce/>
          </surface>
          <max_contacts>10</max_contacts>
        </collision>
        <visual name='roller_2_4_visual'>
          <pose>0 0 0 0 -0 0</pose>
          <geometry>
            <mesh>
              <scale>0.01 0.01 0.01</scale>
              <uri>/home/jinmin/zm_ws/src/parking_robot/robot_description/meshes/mecanum_roller.stl</uri>
            </mesh>
          </geometry>
          <material>
            <script>
              <name>Gazebo/Black</name>
              <uri>file://media/materials/scripts/gazebo.material</uri>
            </script>
          </material>
        </visual>
        <self_collide>0</self_collide>
        <gravity>1</gravity>
        <enable_wind>0</enable_wind>
        <kinematic>0</kinematic>
      </link>
      <joint name='roller_2_5_joint' type='revolute'>
        <pose relative_to='wheel_2'>-0.06108 0.022231 0 -0.7854 -0 2.7924</pose>
        <parent>wheel_2</parent>
        <child>roller_2_5</child>
        <axis>
          <xyz>0 0 1</xyz>
          <limit>
            <lower>-1e+16</lower>
            <upper>1e+16</upper>
          </limit>
          <dynamics>
            <damping>0</damping>
            <friction>0</friction>
            <spring_reference>0</spring_reference>
            <spring_stiffness>0</spring_stiffness>
          </dynamics>
        </axis>
      </joint>
      <link name='roller_2_5'>
        <pose relative_to='roller_2_5_joint'>0 0 0 0 -0 0</pose>
        <inertial>
          <pose>0 0 0 0 -0 0</pose>
          <mass>0.124</mass>
          <inertia>
            <ixx>0.0051893</ixx>
            <ixy>0</ixy>
            <ixz>0</ixz>
            <iyy>0.0051893</iyy>
            <iyz>0</iyz>
            <izz>0.0013891</izz>
          </inertia>
        </inertial>
        <collision name='roller_2_5_collision'>
          <pose>0 0 0 0 -0 0</pose>
          <geometry>
            <mesh>
              <scale>0.01 0.01 0.01</scale>
              <uri>/home/jinmin/zm_ws/src/parking_robot/robot_description/meshes/mecanum_roller.stl</uri>
            </mesh>
          </geometry>
          <surface>
            <contact>
              <ode>
                <kp>1e+50</kp>
                <kd>1e+50</kd>
              </ode>
            </contact>
            <friction>
              <ode>
                <mu>30</mu>
                <mu2>30</mu2>
              </ode>
              <torsional>
                <ode/>
              </torsional>
            </friction>
            <bounce/>
          </surface>
          <max_contacts>10</max_contacts>
        </collision>
        <visual name='roller_2_5_visual'>
          <pose>0 0 0 0 -0 0</pose>
          <geometry>
            <mesh>
              <scale>0.01 0.01 0.01</scale>
              <uri>/home/jinmin/zm_ws/src/parking_robot/robot_description/meshes/mecanum_roller.stl</uri>
            </mesh>
          </geometry>
          <material>
            <script>
              <name>Gazebo/Black</name>
              <uri>file://media/materials/scripts/gazebo.material</uri>
            </script>
          </material>
        </visual>
        <self_collide>0</self_collide>
        <gravity>1</gravity>
        <enable_wind>0</enable_wind>
        <kinematic>0</kinematic>
      </link>
      <joint name='roller_2_6_joint' type='revolute'>
        <pose relative_to='wheel_2'>-0.06108 -0.022231 0 -0.7854 -0 -2.7924</pose>
        <parent>wheel_2</parent>
        <child>roller_2_6</child>
        <axis>
          <xyz>0 0 1</xyz>
          <limit>
            <lower>-1e+16</lower>
            <upper>1e+16</upper>
          </limit>
          <dynamics>
            <damping>0</damping>
            <friction>0</friction>
            <spring_reference>0</spring_reference>
            <spring_stiffness>0</spring_stiffness>
          </dynamics>
        </axis>
      </joint>
      <link name='roller_2_6'>
        <pose relative_to='roller_2_6_joint'>0 0 0 0 -0 0</pose>
        <inertial>
          <pose>0 0 0 0 -0 0</pose>
          <mass>0.124</mass>
          <inertia>
            <ixx>0.0051893</ixx>
            <ixy>0</ixy>
            <ixz>0</ixz>
            <iyy>0.0051893</iyy>
            <iyz>0</iyz>
            <izz>0.0013891</izz>
          </inertia>
        </inertial>
        <collision name='roller_2_6_collision'>
          <pose>0 0 0 0 -0 0</pose>
          <geometry>
            <mesh>
              <scale>0.01 0.01 0.01</scale>
              <uri>/home/jinmin/zm_ws/src/parking_robot/robot_description/meshes/mecanum_roller.stl</uri>
            </mesh>
          </geometry>
          <surface>
            <contact>
              <ode>
                <kp>1e+50</kp>
                <kd>1e+50</kd>
              </ode>
            </contact>
            <friction>
              <ode>
                <mu>30</mu>
                <mu2>30</mu2>
              </ode>
              <torsional>
                <ode/>
              </torsional>
            </friction>
            <bounce/>
          </surface>
          <max_contacts>10</max_contacts>
        </collision>
        <visual name='roller_2_6_visual'>
          <pose>0 0 0 0 -0 0</pose>
          <geometry>
            <mesh>
              <scale>0.01 0.01 0.01</scale>
              <uri>/home/jinmin/zm_ws/src/parking_robot/robot_description/meshes/mecanum_roller.stl</uri>
            </mesh>
          </geometry>
          <material>
            <script>
              <name>Gazebo/Black</name>
              <uri>file://media/materials/scripts/gazebo.material</uri>
            </script>
          </material>
        </visual>
        <self_collide>0</self_collide>
        <gravity>1</gravity>
        <enable_wind>0</enable_wind>
        <kinematic>0</kinematic>
      </link>
      <joint name='roller_2_7_joint' type='revolute'>
        <pose relative_to='wheel_2'>-0.0325 -0.056291 0 -0.7854 -0 -2.0943</pose>
        <parent>wheel_2</parent>
        <child>roller_2_7</child>
        <axis>
          <xyz>0 0 1</xyz>
          <limit>
            <lower>-1e+16</lower>
            <upper>1e+16</upper>
          </limit>
          <dynamics>
            <damping>0</damping>
            <friction>0</friction>
            <spring_reference>0</spring_reference>
            <spring_stiffness>0</spring_stiffness>
          </dynamics>
        </axis>
      </joint>
      <link name='roller_2_7'>
        <pose relative_to='roller_2_7_joint'>0 0 0 0 -0 0</pose>
        <inertial>
          <pose>0 0 0 0 -0 0</pose>
          <mass>0.124</mass>
          <inertia>
            <ixx>0.0051893</ixx>
            <ixy>0</ixy>
            <ixz>0</ixz>
            <iyy>0.0051893</iyy>
            <iyz>0</iyz>
            <izz>0.0013891</izz>
          </inertia>
        </inertial>
        <collision name='roller_2_7_collision'>
          <pose>0 0 0 0 -0 0</pose>
          <geometry>
            <mesh>
              <scale>0.01 0.01 0.01</scale>
              <uri>/home/jinmin/zm_ws/src/parking_robot/robot_description/meshes/mecanum_roller.stl</uri>
            </mesh>
          </geometry>
          <surface>
            <contact>
              <ode>
                <kp>1e+50</kp>
                <kd>1e+50</kd>
              </ode>
            </contact>
            <friction>
              <ode>
                <mu>30</mu>
                <mu2>30</mu2>
              </ode>
              <torsional>
                <ode/>
              </torsional>
            </friction>
            <bounce/>
          </surface>
          <max_contacts>10</max_contacts>
        </collision>
        <visual name='roller_2_7_visual'>
          <pose>0 0 0 0 -0 0</pose>
          <geometry>
            <mesh>
              <scale>0.01 0.01 0.01</scale>
              <uri>/home/jinmin/zm_ws/src/parking_robot/robot_description/meshes/mecanum_roller.stl</uri>
            </mesh>
          </geometry>
          <material>
            <script>
              <name>Gazebo/Black</name>
              <uri>file://media/materials/scripts/gazebo.material</uri>
            </script>
          </material>
        </visual>
        <self_collide>0</self_collide>
        <gravity>1</gravity>
        <enable_wind>0</enable_wind>
        <kinematic>0</kinematic>
      </link>
      <joint name='roller_2_8_joint' type='revolute'>
        <pose relative_to='wheel_2'>0.011287 -0.064012 0 -0.7854 0 -1.3962</pose>
        <parent>wheel_2</parent>
        <child>roller_2_8</child>
        <axis>
          <xyz>0 0 1</xyz>
          <limit>
            <lower>-1e+16</lower>
            <upper>1e+16</upper>
          </limit>
          <dynamics>
            <damping>0</damping>
            <friction>0</friction>
            <spring_reference>0</spring_reference>
            <spring_stiffness>0</spring_stiffness>
          </dynamics>
        </axis>
      </joint>
      <link name='roller_2_8'>
        <pose relative_to='roller_2_8_joint'>0 0 0 0 -0 0</pose>
        <inertial>
          <pose>0 0 0 0 -0 0</pose>
          <mass>0.124</mass>
          <inertia>
            <ixx>0.0051893</ixx>
            <ixy>0</ixy>
            <ixz>0</ixz>
            <iyy>0.0051893</iyy>
            <iyz>0</iyz>
            <izz>0.0013891</izz>
          </inertia>
        </inertial>
        <collision name='roller_2_8_collision'>
          <pose>0 0 0 0 -0 0</pose>
          <geometry>
            <mesh>
              <scale>0.01 0.01 0.01</scale>
              <uri>/home/jinmin/zm_ws/src/parking_robot/robot_description/meshes/mecanum_roller.stl</uri>
            </mesh>
          </geometry>
          <surface>
            <contact>
              <ode>
                <kp>1e+50</kp>
                <kd>1e+50</kd>
              </ode>
            </contact>
            <friction>
              <ode>
                <mu>30</mu>
                <mu2>30</mu2>
              </ode>
              <torsional>
                <ode/>
              </torsional>
            </friction>
            <bounce/>
          </surface>
          <max_contacts>10</max_contacts>
        </collision>
        <visual name='roller_2_8_visual'>
          <pose>0 0 0 0 -0 0</pose>
          <geometry>
            <mesh>
              <scale>0.01 0.01 0.01</scale>
              <uri>/home/jinmin/zm_ws/src/parking_robot/robot_description/meshes/mecanum_roller.stl</uri>
            </mesh>
          </geometry>
          <material>
            <script>
              <name>Gazebo/Black</name>
              <uri>file://media/materials/scripts/gazebo.material</uri>
            </script>
          </material>
        </visual>
        <self_collide>0</self_collide>
        <gravity>1</gravity>
        <enable_wind>0</enable_wind>
        <kinematic>0</kinematic>
      </link>
      <joint name='roller_2_9_joint' type='revolute'>
        <pose relative_to='wheel_2'>0.049792 -0.041781 0 -0.7854 -0 -0.6981</pose>
        <parent>wheel_2</parent>
        <child>roller_2_9</child>
        <axis>
          <xyz>0 0 1</xyz>
          <limit>
            <lower>-1e+16</lower>
            <upper>1e+16</upper>
          </limit>
          <dynamics>
            <damping>0</damping>
            <friction>0</friction>
            <spring_reference>0</spring_reference>
            <spring_stiffness>0</spring_stiffness>
          </dynamics>
        </axis>
      </joint>
      <link name='roller_2_9'>
        <pose relative_to='roller_2_9_joint'>0 0 0 0 -0 0</pose>
        <inertial>
          <pose>0 0 0 0 -0 0</pose>
          <mass>0.124</mass>
          <inertia>
            <ixx>0.0051893</ixx>
            <ixy>0</ixy>
            <ixz>0</ixz>
            <iyy>0.0051893</iyy>
            <iyz>0</iyz>
            <izz>0.0013891</izz>
          </inertia>
        </inertial>
        <collision name='roller_2_9_collision'>
          <pose>0 0 0 0 -0 0</pose>
          <geometry>
            <mesh>
              <scale>0.01 0.01 0.01</scale>
              <uri>/home/jinmin/zm_ws/src/parking_robot/robot_description/meshes/mecanum_roller.stl</uri>
            </mesh>
          </geometry>
          <surface>
            <contact>
              <ode>
                <kp>1e+50</kp>
                <kd>1e+50</kd>
              </ode>
            </contact>
            <friction>
              <ode>
                <mu>30</mu>
                <mu2>30</mu2>
              </ode>
              <torsional>
                <ode/>
              </torsional>
            </friction>
            <bounce/>
          </surface>
          <max_contacts>10</max_contacts>
        </collision>
        <visual name='roller_2_9_visual'>
          <pose>0 0 0 0 -0 0</pose>
          <geometry>
            <mesh>
              <scale>0.01 0.01 0.01</scale>
              <uri>/home/jinmin/zm_ws/src/parking_robot/robot_description/meshes/mecanum_roller.stl</uri>
            </mesh>
          </geometry>
          <material>
            <script>
              <name>Gazebo/Black</name>
              <uri>file://media/materials/scripts/gazebo.material</uri>
            </script>
          </material>
        </visual>
        <self_collide>0</self_collide>
        <gravity>1</gravity>
        <enable_wind>0</enable_wind>
        <kinematic>0</kinematic>
      </link>
      <joint name='wheel_joint_3' type='revolute'>
        <pose relative_to='base_footprint'>0.25 -0.3 0.081572 -1.5708 0 0</pose>
        <parent>base_footprint</parent>
        <child>wheel_3</child>
        <axis>
          <xyz>0 0 1</xyz>
          <limit>
            <lower>-1e+16</lower>
            <upper>1e+16</upper>
          </limit>
          <dynamics>
            <damping>3</damping>
            <friction>5</friction>
            <spring_reference>0</spring_reference>
            <spring_stiffness>0</spring_stiffness>
          </dynamics>
        </axis>
      </joint>
      <link name='wheel_3'>
        <pose relative_to='wheel_joint_3'>0 0 0 0 -0 0</pose>
        <inertial>
          <pose>-0.001 0 0 0 -0 0</pose>
          <mass>1.7</mass>
          <inertia>
            <ixx>0.00424805</ixx>
            <ixy>0</ixy>
            <ixz>0</ixz>
            <iyy>0.00424804</iyy>
            <iyz>0</iyz>
            <izz>-0.00487997</izz>
          </inertia>
        </inertial>
        <collision name='wheel_3_collision'>
          <pose>0 0 0 0 -0 0</pose>
          <geometry>
            <mesh>
              <scale>0.01 0.01 0.01</scale>
              <uri>/home/jinmin/zm_ws/src/parking_robot/robot_description/meshes/mecanum_right_before.stl</uri>
            </mesh>
          </geometry>
          <surface>
            <contact>
              <ode>
                <kp>1e+50</kp>
                <kd>1e+50</kd>
              </ode>
            </contact>
            <friction>
              <ode>
                <mu>30</mu>
                <mu2>30</mu2>
              </ode>
              <torsional>
                <ode/>
              </torsional>
            </friction>
            <bounce/>
          </surface>
          <max_contacts>10</max_contacts>
        </collision>
        <visual name='wheel_3_visual'>
          <pose>0 0 0 0 -0 0</pose>
          <geometry>
            <mesh>
              <scale>0.01 0.01 0.01</scale>
              <uri>/home/jinmin/zm_ws/src/parking_robot/robot_description/meshes/mecanum_right_before.stl</uri>
            </mesh>
          </geometry>
          <material>
            <script>
              <name>Gazebo/White</name>
              <uri>file://media/materials/scripts/gazebo.material</uri>
            </script>
          </material>
        </visual>
        <self_collide>0</self_collide>
        <gravity>1</gravity>
        <enable_wind>0</enable_wind>
        <kinematic>0</kinematic>
      </link>
      <joint name='roller_3_1_joint' type='revolute'>
        <pose relative_to='wheel_3'>0 0.065 0 0.7854 -0 1.5708</pose>
        <parent>wheel_3</parent>
        <child>roller_3_1</child>
        <axis>
          <xyz>0 0 1</xyz>
          <limit>
            <lower>-1e+16</lower>
            <upper>1e+16</upper>
          </limit>
          <dynamics>
            <damping>0</damping>
            <friction>0</friction>
            <spring_reference>0</spring_reference>
            <spring_stiffness>0</spring_stiffness>
          </dynamics>
        </axis>
      </joint>
      <link name='roller_3_1'>
        <pose relative_to='roller_3_1_joint'>0 0 0 0 -0 0</pose>
        <inertial>
          <pose>0 0 0 0 -0 0</pose>
          <mass>0.124</mass>
          <inertia>
            <ixx>0.0051893</ixx>
            <ixy>0</ixy>
            <ixz>0</ixz>
            <iyy>0.0051893</iyy>
            <iyz>0</iyz>
            <izz>0.0013891</izz>
          </inertia>
        </inertial>
        <collision name='roller_3_1_collision'>
          <pose>0 0 0 0 -0 0</pose>
          <geometry>
            <mesh>
              <scale>0.01 0.01 0.01</scale>
              <uri>/home/jinmin/zm_ws/src/parking_robot/robot_description/meshes/mecanum_roller.stl</uri>
            </mesh>
          </geometry>
          <surface>
            <contact>
              <ode>
                <kp>1e+50</kp>
                <kd>1e+50</kd>
              </ode>
            </contact>
            <friction>
              <ode>
                <mu>30</mu>
                <mu2>30</mu2>
              </ode>
              <torsional>
                <ode/>
              </torsional>
            </friction>
            <bounce/>
          </surface>
          <max_contacts>10</max_contacts>
        </collision>
        <visual name='roller_3_1_visual'>
          <pose>0 0 0 0 -0 0</pose>
          <geometry>
            <mesh>
              <scale>0.01 0.01 0.01</scale>
              <uri>/home/jinmin/zm_ws/src/parking_robot/robot_description/meshes/mecanum_roller.stl</uri>
            </mesh>
          </geometry>
          <material>
            <script>
              <name>Gazebo/Black</name>
              <uri>file://media/materials/scripts/gazebo.material</uri>
            </script>
          </material>
        </visual>
        <self_collide>0</self_collide>
        <gravity>1</gravity>
        <enable_wind>0</enable_wind>
        <kinematic>0</kinematic>
      </link>
      <joint name='roller_3_2_joint' type='revolute'>
        <pose relative_to='wheel_3'>0.041781 0.049792 0 0.7854 -0 0.8727</pose>
        <parent>wheel_3</parent>
        <child>roller_3_2</child>
        <axis>
          <xyz>0 0 1</xyz>
          <limit>
            <lower>-1e+16</lower>
            <upper>1e+16</upper>
          </limit>
          <dynamics>
            <damping>0</damping>
            <friction>0</friction>
            <spring_reference>0</spring_reference>
            <spring_stiffness>0</spring_stiffness>
          </dynamics>
        </axis>
      </joint>
      <link name='roller_3_2'>
        <pose relative_to='roller_3_2_joint'>0 0 0 0 -0 0</pose>
        <inertial>
          <pose>0 0 0 0 -0 0</pose>
          <mass>0.124</mass>
          <inertia>
            <ixx>0.0051893</ixx>
            <ixy>0</ixy>
            <ixz>0</ixz>
            <iyy>0.0051893</iyy>
            <iyz>0</iyz>
            <izz>0.0013891</izz>
          </inertia>
        </inertial>
        <collision name='roller_3_2_collision'>
          <pose>0 0 0 0 -0 0</pose>
          <geometry>
            <mesh>
              <scale>0.01 0.01 0.01</scale>
              <uri>/home/jinmin/zm_ws/src/parking_robot/robot_description/meshes/mecanum_roller.stl</uri>
            </mesh>
          </geometry>
          <surface>
            <contact>
              <ode>
                <kp>1e+50</kp>
                <kd>1e+50</kd>
              </ode>
            </contact>
            <friction>
              <ode>
                <mu>30</mu>
                <mu2>30</mu2>
              </ode>
              <torsional>
                <ode/>
              </torsional>
            </friction>
            <bounce/>
          </surface>
          <max_contacts>10</max_contacts>
        </collision>
        <visual name='roller_3_2_visual'>
          <pose>0 0 0 0 -0 0</pose>
          <geometry>
            <mesh>
              <scale>0.01 0.01 0.01</scale>
              <uri>/home/jinmin/zm_ws/src/parking_robot/robot_description/meshes/mecanum_roller.stl</uri>
            </mesh>
          </geometry>
          <material>
            <script>
              <name>Gazebo/Black</name>
              <uri>file://media/materials/scripts/gazebo.material</uri>
            </script>
          </material>
        </visual>
        <self_collide>0</self_collide>
        <gravity>1</gravity>
        <enable_wind>0</enable_wind>
        <kinematic>0</kinematic>
      </link>
      <joint name='roller_3_3_joint' type='revolute'>
        <pose relative_to='wheel_3'>0.064012 0.011287 0 0.7854 -0 0.1746</pose>
        <parent>wheel_3</parent>
        <child>roller_3_3</child>
        <axis>
          <xyz>0 0 1</xyz>
          <limit>
            <lower>-1e+16</lower>
            <upper>1e+16</upper>
          </limit>
          <dynamics>
            <damping>0</damping>
            <friction>0</friction>
            <spring_reference>0</spring_reference>
            <spring_stiffness>0</spring_stiffness>
          </dynamics>
        </axis>
      </joint>
      <link name='roller_3_3'>
        <pose relative_to='roller_3_3_joint'>0 0 0 0 -0 0</pose>
        <inertial>
          <pose>0 0 0 0 -0 0</pose>
          <mass>0.124</mass>
          <inertia>
            <ixx>0.0051893</ixx>
            <ixy>0</ixy>
            <ixz>0</ixz>
            <iyy>0.0051893</iyy>
            <iyz>0</iyz>
            <izz>0.0013891</izz>
          </inertia>
        </inertial>
        <collision name='roller_3_3_collision'>
          <pose>0 0 0 0 -0 0</pose>
          <geometry>
            <mesh>
              <scale>0.01 0.01 0.01</scale>
              <uri>/home/jinmin/zm_ws/src/parking_robot/robot_description/meshes/mecanum_roller.stl</uri>
            </mesh>
          </geometry>
          <surface>
            <contact>
              <ode>
                <kp>1e+50</kp>
                <kd>1e+50</kd>
              </ode>
            </contact>
            <friction>
              <ode>
                <mu>30</mu>
                <mu2>30</mu2>
              </ode>
              <torsional>
                <ode/>
              </torsional>
            </friction>
            <bounce/>
          </surface>
          <max_contacts>10</max_contacts>
        </collision>
        <visual name='roller_3_3_visual'>
          <pose>0 0 0 0 -0 0</pose>
          <geometry>
            <mesh>
              <scale>0.01 0.01 0.01</scale>
              <uri>/home/jinmin/zm_ws/src/parking_robot/robot_description/meshes/mecanum_roller.stl</uri>
            </mesh>
          </geometry>
          <material>
            <script>
              <name>Gazebo/Black</name>
              <uri>file://media/materials/scripts/gazebo.material</uri>
            </script>
          </material>
        </visual>
        <self_collide>0</self_collide>
        <gravity>1</gravity>
        <enable_wind>0</enable_wind>
        <kinematic>0</kinematic>
      </link>
      <joint name='roller_3_4_joint' type='revolute'>
        <pose relative_to='wheel_3'>0.056291 -0.0325 0 0.7854 -0 -0.5235</pose>
        <parent>wheel_3</parent>
        <child>roller_3_4</child>
        <axis>
          <xyz>0 0 1</xyz>
          <limit>
            <lower>-1e+16</lower>
            <upper>1e+16</upper>
          </limit>
          <dynamics>
            <damping>0</damping>
            <friction>0</friction>
            <spring_reference>0</spring_reference>
            <spring_stiffness>0</spring_stiffness>
          </dynamics>
        </axis>
      </joint>
      <link name='roller_3_4'>
        <pose relative_to='roller_3_4_joint'>0 0 0 0 -0 0</pose>
        <inertial>
          <pose>0 0 0 0 -0 0</pose>
          <mass>0.124</mass>
          <inertia>
            <ixx>0.0051893</ixx>
            <ixy>0</ixy>
            <ixz>0</ixz>
            <iyy>0.0051893</iyy>
            <iyz>0</iyz>
            <izz>0.0013891</izz>
          </inertia>
        </inertial>
        <collision name='roller_3_4_collision'>
          <pose>0 0 0 0 -0 0</pose>
          <geometry>
            <mesh>
              <scale>0.01 0.01 0.01</scale>
              <uri>/home/jinmin/zm_ws/src/parking_robot/robot_description/meshes/mecanum_roller.stl</uri>
            </mesh>
          </geometry>
          <surface>
            <contact>
              <ode>
                <kp>1e+50</kp>
                <kd>1e+50</kd>
              </ode>
            </contact>
            <friction>
              <ode>
                <mu>30</mu>
                <mu2>30</mu2>
              </ode>
              <torsional>
                <ode/>
              </torsional>
            </friction>
            <bounce/>
          </surface>
          <max_contacts>10</max_contacts>
        </collision>
        <visual name='roller_3_4_visual'>
          <pose>0 0 0 0 -0 0</pose>
          <geometry>
            <mesh>
              <scale>0.01 0.01 0.01</scale>
              <uri>/home/jinmin/zm_ws/src/parking_robot/robot_description/meshes/mecanum_roller.stl</uri>
            </mesh>
          </geometry>
          <material>
            <script>
              <name>Gazebo/Black</name>
              <uri>file://media/materials/scripts/gazebo.material</uri>
            </script>
          </material>
        </visual>
        <self_collide>0</self_collide>
        <gravity>1</gravity>
        <enable_wind>0</enable_wind>
        <kinematic>0</kinematic>
      </link>
      <joint name='roller_3_5_joint' type='revolute'>
        <pose relative_to='wheel_3'>0.022231 -0.06108 0 0.7854 0 -1.2216</pose>
        <parent>wheel_3</parent>
        <child>roller_3_5</child>
        <axis>
          <xyz>0 0 1</xyz>
          <limit>
            <lower>-1e+16</lower>
            <upper>1e+16</upper>
          </limit>
          <dynamics>
            <damping>0</damping>
            <friction>0</friction>
            <spring_reference>0</spring_reference>
            <spring_stiffness>0</spring_stiffness>
          </dynamics>
        </axis>
      </joint>
      <link name='roller_3_5'>
        <pose relative_to='roller_3_5_joint'>0 0 0 0 -0 0</pose>
        <inertial>
          <pose>0 0 0 0 -0 0</pose>
          <mass>0.124</mass>
          <inertia>
            <ixx>0.0051893</ixx>
            <ixy>0</ixy>
            <ixz>0</ixz>
            <iyy>0.0051893</iyy>
            <iyz>0</iyz>
            <izz>0.0013891</izz>
          </inertia>
        </inertial>
        <collision name='roller_3_5_collision'>
          <pose>0 0 0 0 -0 0</pose>
          <geometry>
            <mesh>
              <scale>0.01 0.01 0.01</scale>
              <uri>/home/jinmin/zm_ws/src/parking_robot/robot_description/meshes/mecanum_roller.stl</uri>
            </mesh>
          </geometry>
          <surface>
            <contact>
              <ode>
                <kp>1e+50</kp>
                <kd>1e+50</kd>
              </ode>
            </contact>
            <friction>
              <ode>
                <mu>30</mu>
                <mu2>30</mu2>
              </ode>
              <torsional>
                <ode/>
              </torsional>
            </friction>
            <bounce/>
          </surface>
          <max_contacts>10</max_contacts>
        </collision>
        <visual name='roller_3_5_visual'>
          <pose>0 0 0 0 -0 0</pose>
          <geometry>
            <mesh>
              <scale>0.01 0.01 0.01</scale>
              <uri>/home/jinmin/zm_ws/src/parking_robot/robot_description/meshes/mecanum_roller.stl</uri>
            </mesh>
          </geometry>
          <material>
            <script>
              <name>Gazebo/Black</name>
              <uri>file://media/materials/scripts/gazebo.material</uri>
            </script>
          </material>
        </visual>
        <self_collide>0</self_collide>
        <gravity>1</gravity>
        <enable_wind>0</enable_wind>
        <kinematic>0</kinematic>
      </link>
      <joint name='roller_3_6_joint' type='revolute'>
        <pose relative_to='wheel_3'>-0.022231 -0.06108 0 0.7854 -0 -1.91999</pose>
        <parent>wheel_3</parent>
        <child>roller_3_6</child>
        <axis>
          <xyz>0 0 1</xyz>
          <limit>
            <lower>-1e+16</lower>
            <upper>1e+16</upper>
          </limit>
          <dynamics>
            <damping>0</damping>
            <friction>0</friction>
            <spring_reference>0</spring_reference>
            <spring_stiffness>0</spring_stiffness>
          </dynamics>
        </axis>
      </joint>
      <link name='roller_3_6'>
        <pose relative_to='roller_3_6_joint'>0 0 0 0 -0 0</pose>
        <inertial>
          <pose>0 0 0 0 -0 0</pose>
          <mass>0.124</mass>
          <inertia>
            <ixx>0.0051893</ixx>
            <ixy>0</ixy>
            <ixz>0</ixz>
            <iyy>0.0051893</iyy>
            <iyz>0</iyz>
            <izz>0.0013891</izz>
          </inertia>
        </inertial>
        <collision name='roller_3_6_collision'>
          <pose>0 0 0 0 -0 0</pose>
          <geometry>
            <mesh>
              <scale>0.01 0.01 0.01</scale>
              <uri>/home/jinmin/zm_ws/src/parking_robot/robot_description/meshes/mecanum_roller.stl</uri>
            </mesh>
          </geometry>
          <surface>
            <contact>
              <ode>
                <kp>1e+50</kp>
                <kd>1e+50</kd>
              </ode>
            </contact>
            <friction>
              <ode>
                <mu>30</mu>
                <mu2>30</mu2>
              </ode>
              <torsional>
                <ode/>
              </torsional>
            </friction>
            <bounce/>
          </surface>
          <max_contacts>10</max_contacts>
        </collision>
        <visual name='roller_3_6_visual'>
          <pose>0 0 0 0 -0 0</pose>
          <geometry>
            <mesh>
              <scale>0.01 0.01 0.01</scale>
              <uri>/home/jinmin/zm_ws/src/parking_robot/robot_description/meshes/mecanum_roller.stl</uri>
            </mesh>
          </geometry>
          <material>
            <script>
              <name>Gazebo/Black</name>
              <uri>file://media/materials/scripts/gazebo.material</uri>
            </script>
          </material>
        </visual>
        <self_collide>0</self_collide>
        <gravity>1</gravity>
        <enable_wind>0</enable_wind>
        <kinematic>0</kinematic>
      </link>
      <joint name='roller_3_7_joint' type='revolute'>
        <pose relative_to='wheel_3'>-0.056291 -0.0325 0 0.7854 -0 -2.61809</pose>
        <parent>wheel_3</parent>
        <child>roller_3_7</child>
        <axis>
          <xyz>0 0 1</xyz>
          <limit>
            <lower>-1e+16</lower>
            <upper>1e+16</upper>
          </limit>
          <dynamics>
            <damping>0</damping>
            <friction>0</friction>
            <spring_reference>0</spring_reference>
            <spring_stiffness>0</spring_stiffness>
          </dynamics>
        </axis>
      </joint>
      <link name='roller_3_7'>
        <pose relative_to='roller_3_7_joint'>0 0 0 0 -0 0</pose>
        <inertial>
          <pose>0 0 0 0 -0 0</pose>
          <mass>0.124</mass>
          <inertia>
            <ixx>0.0051893</ixx>
            <ixy>0</ixy>
            <ixz>0</ixz>
            <iyy>0.0051893</iyy>
            <iyz>0</iyz>
            <izz>0.0013891</izz>
          </inertia>
        </inertial>
        <collision name='roller_3_7_collision'>
          <pose>0 0 0 0 -0 0</pose>
          <geometry>
            <mesh>
              <scale>0.01 0.01 0.01</scale>
              <uri>/home/jinmin/zm_ws/src/parking_robot/robot_description/meshes/mecanum_roller.stl</uri>
            </mesh>
          </geometry>
          <surface>
            <contact>
              <ode>
                <kp>1e+50</kp>
                <kd>1e+50</kd>
              </ode>
            </contact>
            <friction>
              <ode>
                <mu>30</mu>
                <mu2>30</mu2>
              </ode>
              <torsional>
                <ode/>
              </torsional>
            </friction>
            <bounce/>
          </surface>
          <max_contacts>10</max_contacts>
        </collision>
        <visual name='roller_3_7_visual'>
          <pose>0 0 0 0 -0 0</pose>
          <geometry>
            <mesh>
              <scale>0.01 0.01 0.01</scale>
              <uri>/home/jinmin/zm_ws/src/parking_robot/robot_description/meshes/mecanum_roller.stl</uri>
            </mesh>
          </geometry>
          <material>
            <script>
              <name>Gazebo/Black</name>
              <uri>file://media/materials/scripts/gazebo.material</uri>
            </script>
          </material>
        </visual>
        <self_collide>0</self_collide>
        <gravity>1</gravity>
        <enable_wind>0</enable_wind>
        <kinematic>0</kinematic>
      </link>
      <joint name='roller_3_8_joint' type='revolute'>
        <pose relative_to='wheel_3'>-0.064012 0.011287 0 0.7854 -0 2.967</pose>
        <parent>wheel_3</parent>
        <child>roller_3_8</child>
        <axis>
          <xyz>0 0 1</xyz>
          <limit>
            <lower>-1e+16</lower>
            <upper>1e+16</upper>
          </limit>
          <dynamics>
            <damping>0</damping>
            <friction>0</friction>
            <spring_reference>0</spring_reference>
            <spring_stiffness>0</spring_stiffness>
          </dynamics>
        </axis>
      </joint>
      <link name='roller_3_8'>
        <pose relative_to='roller_3_8_joint'>0 0 0 0 -0 0</pose>
        <inertial>
          <pose>0 0 0 0 -0 0</pose>
          <mass>0.124</mass>
          <inertia>
            <ixx>0.0051893</ixx>
            <ixy>0</ixy>
            <ixz>0</ixz>
            <iyy>0.0051893</iyy>
            <iyz>0</iyz>
            <izz>0.0013891</izz>
          </inertia>
        </inertial>
        <collision name='roller_3_8_collision'>
          <pose>0 0 0 0 -0 0</pose>
          <geometry>
            <mesh>
              <scale>0.01 0.01 0.01</scale>
              <uri>/home/jinmin/zm_ws/src/parking_robot/robot_description/meshes/mecanum_roller.stl</uri>
            </mesh>
          </geometry>
          <surface>
            <contact>
              <ode>
                <kp>1e+50</kp>
                <kd>1e+50</kd>
              </ode>
            </contact>
            <friction>
              <ode>
                <mu>30</mu>
                <mu2>30</mu2>
              </ode>
              <torsional>
                <ode/>
              </torsional>
            </friction>
            <bounce/>
          </surface>
          <max_contacts>10</max_contacts>
        </collision>
        <visual name='roller_3_8_visual'>
          <pose>0 0 0 0 -0 0</pose>
          <geometry>
            <mesh>
              <scale>0.01 0.01 0.01</scale>
              <uri>/home/jinmin/zm_ws/src/parking_robot/robot_description/meshes/mecanum_roller.stl</uri>
            </mesh>
          </geometry>
          <material>
            <script>
              <name>Gazebo/Black</name>
              <uri>file://media/materials/scripts/gazebo.material</uri>
            </script>
          </material>
        </visual>
        <self_collide>0</self_collide>
        <gravity>1</gravity>
        <enable_wind>0</enable_wind>
        <kinematic>0</kinematic>
      </link>
      <joint name='roller_3_9_joint' type='revolute'>
        <pose relative_to='wheel_3'>-0.041781 0.049792 0 0.7854 -0 2.2689</pose>
        <parent>wheel_3</parent>
        <child>roller_3_9</child>
        <axis>
          <xyz>0 0 1</xyz>
          <limit>
            <lower>-1e+16</lower>
            <upper>1e+16</upper>
          </limit>
          <dynamics>
            <damping>0</damping>
            <friction>0</friction>
            <spring_reference>0</spring_reference>
            <spring_stiffness>0</spring_stiffness>
          </dynamics>
        </axis>
      </joint>
      <link name='roller_3_9'>
        <pose relative_to='roller_3_9_joint'>0 0 0 0 -0 0</pose>
        <inertial>
          <pose>0 0 0 0 -0 0</pose>
          <mass>0.124</mass>
          <inertia>
            <ixx>0.0051893</ixx>
            <ixy>0</ixy>
            <ixz>0</ixz>
            <iyy>0.0051893</iyy>
            <iyz>0</iyz>
            <izz>0.0013891</izz>
          </inertia>
        </inertial>
        <collision name='roller_3_9_collision'>
          <pose>0 0 0 0 -0 0</pose>
          <geometry>
            <mesh>
              <scale>0.01 0.01 0.01</scale>
              <uri>/home/jinmin/zm_ws/src/parking_robot/robot_description/meshes/mecanum_roller.stl</uri>
            </mesh>
          </geometry>
          <surface>
            <contact>
              <ode>
                <kp>1e+50</kp>
                <kd>1e+50</kd>
              </ode>
            </contact>
            <friction>
              <ode>
                <mu>30</mu>
                <mu2>30</mu2>
              </ode>
              <torsional>
                <ode/>
              </torsional>
            </friction>
            <bounce/>
          </surface>
          <max_contacts>10</max_contacts>
        </collision>
        <visual name='roller_3_9_visual'>
          <pose>0 0 0 0 -0 0</pose>
          <geometry>
            <mesh>
              <scale>0.01 0.01 0.01</scale>
              <uri>/home/jinmin/zm_ws/src/parking_robot/robot_description/meshes/mecanum_roller.stl</uri>
            </mesh>
          </geometry>
          <material>
            <script>
              <name>Gazebo/Black</name>
              <uri>file://media/materials/scripts/gazebo.material</uri>
            </script>
          </material>
        </visual>
        <self_collide>0</self_collide>
        <gravity>1</gravity>
        <enable_wind>0</enable_wind>
        <kinematic>0</kinematic>
      </link>
      <joint name='wheel_joint_4' type='revolute'>
        <pose relative_to='base_footprint'>-0.25 -0.3 0.081572 -1.5708 0 0</pose>
        <parent>base_footprint</parent>
        <child>wheel_4</child>
        <axis>
          <xyz>0 0 1</xyz>
          <limit>
            <lower>-1e+16</lower>
            <upper>1e+16</upper>
          </limit>
          <dynamics>
            <damping>3</damping>
            <friction>5</friction>
            <spring_reference>0</spring_reference>
            <spring_stiffness>0</spring_stiffness>
          </dynamics>
        </axis>
      </joint>
      <link name='wheel_4'>
        <pose relative_to='wheel_joint_4'>0 0 0 0 -0 0</pose>
        <inertial>
          <pose>-0.001 0 0 0 -0 0</pose>
          <mass>1.7</mass>
          <inertia>
            <ixx>0.00424805</ixx>
            <ixy>0</ixy>
            <ixz>0</ixz>
            <iyy>0.00424804</iyy>
            <iyz>0</iyz>
            <izz>-0.00487997</izz>
          </inertia>
        </inertial>
        <collision name='wheel_4_collision'>
          <pose>0 0 0 0 -0 0</pose>
          <geometry>
            <mesh>
              <scale>0.01 0.01 0.01</scale>
              <uri>/home/jinmin/zm_ws/src/parking_robot/robot_description/meshes/mecanum_right_after.stl</uri>
            </mesh>
          </geometry>
          <surface>
            <contact>
              <ode>
                <kp>1e+50</kp>
                <kd>1e+50</kd>
              </ode>
            </contact>
            <friction>
              <ode>
                <mu>30</mu>
                <mu2>30</mu2>
              </ode>
              <torsional>
                <ode/>
              </torsional>
            </friction>
            <bounce/>
          </surface>
          <max_contacts>10</max_contacts>
        </collision>
        <visual name='wheel_4_visual'>
          <pose>0 0 0 0 -0 0</pose>
          <geometry>
            <mesh>
              <scale>0.01 0.01 0.01</scale>
              <uri>/home/jinmin/zm_ws/src/parking_robot/robot_description/meshes/mecanum_right_after.stl</uri>
            </mesh>
          </geometry>
          <material>
            <script>
              <name>Gazebo/White</name>
              <uri>file://media/materials/scripts/gazebo.material</uri>
            </script>
          </material>
        </visual>
        <self_collide>0</self_collide>
        <gravity>1</gravity>
        <enable_wind>0</enable_wind>
        <kinematic>0</kinematic>
      </link>
      <joint name='roller_4_1_joint' type='revolute'>
        <pose relative_to='wheel_4'>0.065 0 0 -0.7854 0 0</pose>
        <parent>wheel_4</parent>
        <child>roller_4_1</child>
        <axis>
          <xyz>0 0 1</xyz>
          <limit>
            <lower>-1e+16</lower>
            <upper>1e+16</upper>
          </limit>
          <dynamics>
            <damping>0</damping>
            <friction>0</friction>
            <spring_reference>0</spring_reference>
            <spring_stiffness>0</spring_stiffness>
          </dynamics>
        </axis>
      </joint>
      <link name='roller_4_1'>
        <pose relative_to='roller_4_1_joint'>0 0 0 0 -0 0</pose>
        <inertial>
          <pose>0 0 0 0 -0 0</pose>
          <mass>0.124</mass>
          <inertia>
            <ixx>0.0051893</ixx>
            <ixy>0</ixy>
            <ixz>0</ixz>
            <iyy>0.0051893</iyy>
            <iyz>0</iyz>
            <izz>0.0013891</izz>
          </inertia>
        </inertial>
        <collision name='roller_4_1_collision'>
          <pose>0 0 0 0 -0 0</pose>
          <geometry>
            <mesh>
              <scale>0.01 0.01 0.01</scale>
              <uri>/home/jinmin/zm_ws/src/parking_robot/robot_description/meshes/mecanum_roller.stl</uri>
            </mesh>
          </geometry>
          <surface>
            <contact>
              <ode>
                <kp>1e+50</kp>
                <kd>1e+50</kd>
              </ode>
            </contact>
            <friction>
              <ode>
                <mu>30</mu>
                <mu2>30</mu2>
              </ode>
              <torsional>
                <ode/>
              </torsional>
            </friction>
            <bounce/>
          </surface>
          <max_contacts>10</max_contacts>
        </collision>
        <visual name='roller_4_1_visual'>
          <pose>0 0 0 0 -0 0</pose>
          <geometry>
            <mesh>
              <scale>0.01 0.01 0.01</scale>
              <uri>/home/jinmin/zm_ws/src/parking_robot/robot_description/meshes/mecanum_roller.stl</uri>
            </mesh>
          </geometry>
          <material>
            <script>
              <name>Gazebo/Black</name>
              <uri>file://media/materials/scripts/gazebo.material</uri>
            </script>
          </material>
        </visual>
        <self_collide>0</self_collide>
        <gravity>1</gravity>
        <enable_wind>0</enable_wind>
        <kinematic>0</kinematic>
      </link>
      <joint name='roller_4_2_joint' type='revolute'>
        <pose relative_to='wheel_4'>0.049792 0.041781 0 -0.7854 0 0.6981</pose>
        <parent>wheel_4</parent>
        <child>roller_4_2</child>
        <axis>
          <xyz>0 0 1</xyz>
          <limit>
            <lower>-1e+16</lower>
            <upper>1e+16</upper>
          </limit>
          <dynamics>
            <damping>0</damping>
            <friction>0</friction>
            <spring_reference>0</spring_reference>
            <spring_stiffness>0</spring_stiffness>
          </dynamics>
        </axis>
      </joint>
      <link name='roller_4_2'>
        <pose relative_to='roller_4_2_joint'>0 0 0 0 -0 0</pose>
        <inertial>
          <pose>0 0 0 0 -0 0</pose>
          <mass>0.124</mass>
          <inertia>
            <ixx>0.0051893</ixx>
            <ixy>0</ixy>
            <ixz>0</ixz>
            <iyy>0.0051893</iyy>
            <iyz>0</iyz>
            <izz>0.0013891</izz>
          </inertia>
        </inertial>
        <collision name='roller_4_2_collision'>
          <pose>0 0 0 0 -0 0</pose>
          <geometry>
            <mesh>
              <scale>0.01 0.01 0.01</scale>
              <uri>/home/jinmin/zm_ws/src/parking_robot/robot_description/meshes/mecanum_roller.stl</uri>
            </mesh>
          </geometry>
          <surface>
            <contact>
              <ode>
                <kp>1e+50</kp>
                <kd>1e+50</kd>
              </ode>
            </contact>
            <friction>
              <ode>
                <mu>30</mu>
                <mu2>30</mu2>
              </ode>
              <torsional>
                <ode/>
              </torsional>
            </friction>
            <bounce/>
          </surface>
          <max_contacts>10</max_contacts>
        </collision>
        <visual name='roller_4_2_visual'>
          <pose>0 0 0 0 -0 0</pose>
          <geometry>
            <mesh>
              <scale>0.01 0.01 0.01</scale>
              <uri>/home/jinmin/zm_ws/src/parking_robot/robot_description/meshes/mecanum_roller.stl</uri>
            </mesh>
          </geometry>
          <material>
            <script>
              <name>Gazebo/Black</name>
              <uri>file://media/materials/scripts/gazebo.material</uri>
            </script>
          </material>
        </visual>
        <self_collide>0</self_collide>
        <gravity>1</gravity>
        <enable_wind>0</enable_wind>
        <kinematic>0</kinematic>
      </link>
      <joint name='roller_4_3_joint' type='revolute'>
        <pose relative_to='wheel_4'>0.011287 0.064012 0 -0.7854 -0 1.3962</pose>
        <parent>wheel_4</parent>
        <child>roller_4_3</child>
        <axis>
          <xyz>0 0 1</xyz>
          <limit>
            <lower>-1e+16</lower>
            <upper>1e+16</upper>
          </limit>
          <dynamics>
            <damping>0</damping>
            <friction>0</friction>
            <spring_reference>0</spring_reference>
            <spring_stiffness>0</spring_stiffness>
          </dynamics>
        </axis>
      </joint>
      <link name='roller_4_3'>
        <pose relative_to='roller_4_3_joint'>0 0 0 0 -0 0</pose>
        <inertial>
          <pose>0 0 0 0 -0 0</pose>
          <mass>0.124</mass>
          <inertia>
            <ixx>0.0051893</ixx>
            <ixy>0</ixy>
            <ixz>0</ixz>
            <iyy>0.0051893</iyy>
            <iyz>0</iyz>
            <izz>0.0013891</izz>
          </inertia>
        </inertial>
        <collision name='roller_4_3_collision'>
          <pose>0 0 0 0 -0 0</pose>
          <geometry>
            <mesh>
              <scale>0.01 0.01 0.01</scale>
              <uri>/home/jinmin/zm_ws/src/parking_robot/robot_description/meshes/mecanum_roller.stl</uri>
            </mesh>
          </geometry>
          <surface>
            <contact>
              <ode>
                <kp>1e+50</kp>
                <kd>1e+50</kd>
              </ode>
            </contact>
            <friction>
              <ode>
                <mu>30</mu>
                <mu2>30</mu2>
              </ode>
              <torsional>
                <ode/>
              </torsional>
            </friction>
            <bounce/>
          </surface>
          <max_contacts>10</max_contacts>
        </collision>
        <visual name='roller_4_3_visual'>
          <pose>0 0 0 0 -0 0</pose>
          <geometry>
            <mesh>
              <scale>0.01 0.01 0.01</scale>
              <uri>/home/jinmin/zm_ws/src/parking_robot/robot_description/meshes/mecanum_roller.stl</uri>
            </mesh>
          </geometry>
          <material>
            <script>
              <name>Gazebo/Black</name>
              <uri>file://media/materials/scripts/gazebo.material</uri>
            </script>
          </material>
        </visual>
        <self_collide>0</self_collide>
        <gravity>1</gravity>
        <enable_wind>0</enable_wind>
        <kinematic>0</kinematic>
      </link>
      <joint name='roller_4_4_joint' type='revolute'>
        <pose relative_to='wheel_4'>-0.0325 0.056291 0 -0.7854 0 2.0943</pose>
        <parent>wheel_4</parent>
        <child>roller_4_4</child>
        <axis>
          <xyz>0 0 1</xyz>
          <limit>
            <lower>-1e+16</lower>
            <upper>1e+16</upper>
          </limit>
          <dynamics>
            <damping>0</damping>
            <friction>0</friction>
            <spring_reference>0</spring_reference>
            <spring_stiffness>0</spring_stiffness>
          </dynamics>
        </axis>
      </joint>
      <link name='roller_4_4'>
        <pose relative_to='roller_4_4_joint'>0 0 0 0 -0 0</pose>
        <inertial>
          <pose>0 0 0 0 -0 0</pose>
          <mass>0.124</mass>
          <inertia>
            <ixx>0.0051893</ixx>
            <ixy>0</ixy>
            <ixz>0</ixz>
            <iyy>0.0051893</iyy>
            <iyz>0</iyz>
            <izz>0.0013891</izz>
          </inertia>
        </inertial>
        <collision name='roller_4_4_collision'>
          <pose>0 0 0 0 -0 0</pose>
          <geometry>
            <mesh>
              <scale>0.01 0.01 0.01</scale>
              <uri>/home/jinmin/zm_ws/src/parking_robot/robot_description/meshes/mecanum_roller.stl</uri>
            </mesh>
          </geometry>
          <surface>
            <contact>
              <ode>
                <kp>1e+50</kp>
                <kd>1e+50</kd>
              </ode>
            </contact>
            <friction>
              <ode>
                <mu>30</mu>
                <mu2>30</mu2>
              </ode>
              <torsional>
                <ode/>
              </torsional>
            </friction>
            <bounce/>
          </surface>
          <max_contacts>10</max_contacts>
        </collision>
        <visual name='roller_4_4_visual'>
          <pose>0 0 0 0 -0 0</pose>
          <geometry>
            <mesh>
              <scale>0.01 0.01 0.01</scale>
              <uri>/home/jinmin/zm_ws/src/parking_robot/robot_description/meshes/mecanum_roller.stl</uri>
            </mesh>
          </geometry>
          <material>
            <script>
              <name>Gazebo/Black</name>
              <uri>file://media/materials/scripts/gazebo.material</uri>
            </script>
          </material>
        </visual>
        <self_collide>0</self_collide>
        <gravity>1</gravity>
        <enable_wind>0</enable_wind>
        <kinematic>0</kinematic>
      </link>
      <joint name='roller_4_5_joint' type='revolute'>
        <pose relative_to='wheel_4'>-0.06108 0.022231 0 -0.7854 -0 2.7924</pose>
        <parent>wheel_4</parent>
        <child>roller_4_5</child>
        <axis>
          <xyz>0 0 1</xyz>
          <limit>
            <lower>-1e+16</lower>
            <upper>1e+16</upper>
          </limit>
          <dynamics>
            <damping>0</damping>
            <friction>0</friction>
            <spring_reference>0</spring_reference>
            <spring_stiffness>0</spring_stiffness>
          </dynamics>
        </axis>
      </joint>
      <link name='roller_4_5'>
        <pose relative_to='roller_4_5_joint'>0 0 0 0 -0 0</pose>
        <inertial>
          <pose>0 0 0 0 -0 0</pose>
          <mass>0.124</mass>
          <inertia>
            <ixx>0.0051893</ixx>
            <ixy>0</ixy>
            <ixz>0</ixz>
            <iyy>0.0051893</iyy>
            <iyz>0</iyz>
            <izz>0.0013891</izz>
          </inertia>
        </inertial>
        <collision name='roller_4_5_collision'>
          <pose>0 0 0 0 -0 0</pose>
          <geometry>
            <mesh>
              <scale>0.01 0.01 0.01</scale>
              <uri>/home/jinmin/zm_ws/src/parking_robot/robot_description/meshes/mecanum_roller.stl</uri>
            </mesh>
          </geometry>
          <surface>
            <contact>
              <ode>
                <kp>1e+50</kp>
                <kd>1e+50</kd>
              </ode>
            </contact>
            <friction>
              <ode>
                <mu>30</mu>
                <mu2>30</mu2>
              </ode>
              <torsional>
                <ode/>
              </torsional>
            </friction>
            <bounce/>
          </surface>
          <max_contacts>10</max_contacts>
        </collision>
        <visual name='roller_4_5_visual'>
          <pose>0 0 0 0 -0 0</pose>
          <geometry>
            <mesh>
              <scale>0.01 0.01 0.01</scale>
              <uri>/home/jinmin/zm_ws/src/parking_robot/robot_description/meshes/mecanum_roller.stl</uri>
            </mesh>
          </geometry>
          <material>
            <script>
              <name>Gazebo/Black</name>
              <uri>file://media/materials/scripts/gazebo.material</uri>
            </script>
          </material>
        </visual>
        <self_collide>0</self_collide>
        <gravity>1</gravity>
        <enable_wind>0</enable_wind>
        <kinematic>0</kinematic>
      </link>
      <joint name='roller_4_6_joint' type='revolute'>
        <pose relative_to='wheel_4'>-0.06108 -0.022231 0 -0.7854 -0 -2.7924</pose>
        <parent>wheel_4</parent>
        <child>roller_4_6</child>
        <axis>
          <xyz>0 0 1</xyz>
          <limit>
            <lower>-1e+16</lower>
            <upper>1e+16</upper>
          </limit>
          <dynamics>
            <damping>0</damping>
            <friction>0</friction>
            <spring_reference>0</spring_reference>
            <spring_stiffness>0</spring_stiffness>
          </dynamics>
        </axis>
      </joint>
      <link name='roller_4_6'>
        <pose relative_to='roller_4_6_joint'>0 0 0 0 -0 0</pose>
        <inertial>
          <pose>0 0 0 0 -0 0</pose>
          <mass>0.124</mass>
          <inertia>
            <ixx>0.0051893</ixx>
            <ixy>0</ixy>
            <ixz>0</ixz>
            <iyy>0.0051893</iyy>
            <iyz>0</iyz>
            <izz>0.0013891</izz>
          </inertia>
        </inertial>
        <collision name='roller_4_6_collision'>
          <pose>0 0 0 0 -0 0</pose>
          <geometry>
            <mesh>
              <scale>0.01 0.01 0.01</scale>
              <uri>/home/jinmin/zm_ws/src/parking_robot/robot_description/meshes/mecanum_roller.stl</uri>
            </mesh>
          </geometry>
          <surface>
            <contact>
              <ode>
                <kp>1e+50</kp>
                <kd>1e+50</kd>
              </ode>
            </contact>
            <friction>
              <ode>
                <mu>30</mu>
                <mu2>30</mu2>
              </ode>
              <torsional>
                <ode/>
              </torsional>
            </friction>
            <bounce/>
          </surface>
          <max_contacts>10</max_contacts>
        </collision>
        <visual name='roller_4_6_visual'>
          <pose>0 0 0 0 -0 0</pose>
          <geometry>
            <mesh>
              <scale>0.01 0.01 0.01</scale>
              <uri>/home/jinmin/zm_ws/src/parking_robot/robot_description/meshes/mecanum_roller.stl</uri>
            </mesh>
          </geometry>
          <material>
            <script>
              <name>Gazebo/Black</name>
              <uri>file://media/materials/scripts/gazebo.material</uri>
            </script>
          </material>
        </visual>
        <self_collide>0</self_collide>
        <gravity>1</gravity>
        <enable_wind>0</enable_wind>
        <kinematic>0</kinematic>
      </link>
      <joint name='roller_4_7_joint' type='revolute'>
        <pose relative_to='wheel_4'>-0.0325 -0.056291 0 -0.7854 -0 -2.0943</pose>
        <parent>wheel_4</parent>
        <child>roller_4_7</child>
        <axis>
          <xyz>0 0 1</xyz>
          <limit>
            <lower>-1e+16</lower>
            <upper>1e+16</upper>
          </limit>
          <dynamics>
            <damping>0</damping>
            <friction>0</friction>
            <spring_reference>0</spring_reference>
            <spring_stiffness>0</spring_stiffness>
          </dynamics>
        </axis>
      </joint>
      <link name='roller_4_7'>
        <pose relative_to='roller_4_7_joint'>0 0 0 0 -0 0</pose>
        <inertial>
          <pose>0 0 0 0 -0 0</pose>
          <mass>0.124</mass>
          <inertia>
            <ixx>0.0051893</ixx>
            <ixy>0</ixy>
            <ixz>0</ixz>
            <iyy>0.0051893</iyy>
            <iyz>0</iyz>
            <izz>0.0013891</izz>
          </inertia>
        </inertial>
        <collision name='roller_4_7_collision'>
          <pose>0 0 0 0 -0 0</pose>
          <geometry>
            <mesh>
              <scale>0.01 0.01 0.01</scale>
              <uri>/home/jinmin/zm_ws/src/parking_robot/robot_description/meshes/mecanum_roller.stl</uri>
            </mesh>
          </geometry>
          <surface>
            <contact>
              <ode>
                <kp>1e+50</kp>
                <kd>1e+50</kd>
              </ode>
            </contact>
            <friction>
              <ode>
                <mu>30</mu>
                <mu2>30</mu2>
              </ode>
              <torsional>
                <ode/>
              </torsional>
            </friction>
            <bounce/>
          </surface>
          <max_contacts>10</max_contacts>
        </collision>
        <visual name='roller_4_7_visual'>
          <pose>0 0 0 0 -0 0</pose>
          <geometry>
            <mesh>
              <scale>0.01 0.01 0.01</scale>
              <uri>/home/jinmin/zm_ws/src/parking_robot/robot_description/meshes/mecanum_roller.stl</uri>
            </mesh>
          </geometry>
          <material>
            <script>
              <name>Gazebo/Black</name>
              <uri>file://media/materials/scripts/gazebo.material</uri>
            </script>
          </material>
        </visual>
        <self_collide>0</self_collide>
        <gravity>1</gravity>
        <enable_wind>0</enable_wind>
        <kinematic>0</kinematic>
      </link>
      <joint name='roller_4_8_joint' type='revolute'>
        <pose relative_to='wheel_4'>0.011287 -0.064012 0 -0.7854 0 -1.3962</pose>
        <parent>wheel_4</parent>
        <child>roller_4_8</child>
        <axis>
          <xyz>0 0 1</xyz>
          <limit>
            <lower>-1e+16</lower>
            <upper>1e+16</upper>
          </limit>
          <dynamics>
            <damping>0</damping>
            <friction>0</friction>
            <spring_reference>0</spring_reference>
            <spring_stiffness>0</spring_stiffness>
          </dynamics>
        </axis>
      </joint>
      <link name='roller_4_8'>
        <pose relative_to='roller_4_8_joint'>0 0 0 0 -0 0</pose>
        <inertial>
          <pose>0 0 0 0 -0 0</pose>
          <mass>0.124</mass>
          <inertia>
            <ixx>0.0051893</ixx>
            <ixy>0</ixy>
            <ixz>0</ixz>
            <iyy>0.0051893</iyy>
            <iyz>0</iyz>
            <izz>0.0013891</izz>
          </inertia>
        </inertial>
        <collision name='roller_4_8_collision'>
          <pose>0 0 0 0 -0 0</pose>
          <geometry>
            <mesh>
              <scale>0.01 0.01 0.01</scale>
              <uri>/home/jinmin/zm_ws/src/parking_robot/robot_description/meshes/mecanum_roller.stl</uri>
            </mesh>
          </geometry>
          <surface>
            <contact>
              <ode>
                <kp>1e+50</kp>
                <kd>1e+50</kd>
              </ode>
            </contact>
            <friction>
              <ode>
                <mu>30</mu>
                <mu2>30</mu2>
              </ode>
              <torsional>
                <ode/>
              </torsional>
            </friction>
            <bounce/>
          </surface>
          <max_contacts>10</max_contacts>
        </collision>
        <visual name='roller_4_8_visual'>
          <pose>0 0 0 0 -0 0</pose>
          <geometry>
            <mesh>
              <scale>0.01 0.01 0.01</scale>
              <uri>/home/jinmin/zm_ws/src/parking_robot/robot_description/meshes/mecanum_roller.stl</uri>
            </mesh>
          </geometry>
          <material>
            <script>
              <name>Gazebo/Black</name>
              <uri>file://media/materials/scripts/gazebo.material</uri>
            </script>
          </material>
        </visual>
        <self_collide>0</self_collide>
        <gravity>1</gravity>
        <enable_wind>0</enable_wind>
        <kinematic>0</kinematic>
      </link>
      <joint name='roller_4_9_joint' type='revolute'>
        <pose relative_to='wheel_4'>0.049792 -0.041781 0 -0.7854 -0 -0.6981</pose>
        <parent>wheel_4</parent>
        <child>roller_4_9</child>
        <axis>
          <xyz>0 0 1</xyz>
          <limit>
            <lower>-1e+16</lower>
            <upper>1e+16</upper>
          </limit>
          <dynamics>
            <damping>0</damping>
            <friction>0</friction>
            <spring_reference>0</spring_reference>
            <spring_stiffness>0</spring_stiffness>
          </dynamics>
        </axis>
      </joint>
      <link name='roller_4_9'>
        <pose relative_to='roller_4_9_joint'>0 0 0 0 -0 0</pose>
        <inertial>
          <pose>0 0 0 0 -0 0</pose>
          <mass>0.124</mass>
          <inertia>
            <ixx>0.0051893</ixx>
            <ixy>0</ixy>
            <ixz>0</ixz>
            <iyy>0.0051893</iyy>
            <iyz>0</iyz>
            <izz>0.0013891</izz>
          </inertia>
        </inertial>
        <collision name='roller_4_9_collision'>
          <pose>0 0 0 0 -0 0</pose>
          <geometry>
            <mesh>
              <scale>0.01 0.01 0.01</scale>
              <uri>/home/jinmin/zm_ws/src/parking_robot/robot_description/meshes/mecanum_roller.stl</uri>
            </mesh>
          </geometry>
          <surface>
            <contact>
              <ode>
                <kp>1e+50</kp>
                <kd>1e+50</kd>
              </ode>
            </contact>
            <friction>
              <ode>
                <mu>30</mu>
                <mu2>30</mu2>
              </ode>
              <torsional>
                <ode/>
              </torsional>
            </friction>
            <bounce/>
          </surface>
          <max_contacts>10</max_contacts>
        </collision>
        <visual name='roller_4_9_visual'>
          <pose>0 0 0 0 -0 0</pose>
          <geometry>
            <mesh>
              <scale>0.01 0.01 0.01</scale>
              <uri>/home/jinmin/zm_ws/src/parking_robot/robot_description/meshes/mecanum_roller.stl</uri>
            </mesh>
          </geometry>
          <material>
            <script>
              <name>Gazebo/Black</name>
              <uri>file://media/materials/scripts/gazebo.material</uri>
            </script>
          </material>
        </visual>
        <self_collide>0</self_collide>
        <gravity>1</gravity>
        <enable_wind>0</enable_wind>
        <kinematic>0</kinematic>
      </link>
      <static>0</static>
      <plugin name='robot_diff_drive' filename='libgazebo_ros_mecanum_drive.so'>
        <commandTopic>cmd_vel</commandTopic>
        <odometryTopic>odom</odometryTopic>
        <odometryFrame>odom</odometryFrame>
        <robotBaseFrame>base_footprint</robotBaseFrame>
        <LeftRear>wheel_joint_1</LeftRear>
        <LeftFront>wheel_joint_2</LeftFront>
        <RightFront>wheel_joint_3</RightFront>
        <RightRear>wheel_joint_4</RightRear>
        <odometryRate>20</odometryRate>
        <publishWheelTF>0</publishWheelTF>
        <publishWheelJointState>1</publishWheelJointState>
        <WheelTorque>30</WheelTorque>
        <WheelSeparationW>0.5</WheelSeparationW>
        <WheelSeparationL>0.6</WheelSeparationL>
        <wheelAccel>5</wheelAccel>
        <wheelDiameter>0.13</wheelDiameter>
        <publishOdom>1</publishOdom>
        <isRollerModel>1</isRollerModel>
        <robotNamespace>/</robotNamespace>
      </plugin>
      <pose>0 0 0 0 -0 0</pose>
    </model>
    <model name='test3'>
      <pose>3.74593 -1.08965 0 0 -0 0</pose>
      <link name='Wall_0'>
        <collision name='Wall_0_Collision'>
          <geometry>
            <box>
              <size>7 0.15 1</size>
            </box>
          </geometry>
          <pose>0 0 0.5 0 -0 0</pose>
          <max_contacts>10</max_contacts>
          <surface>
            <contact>
              <ode/>
            </contact>
            <bounce/>
            <friction>
              <torsional>
                <ode/>
              </torsional>
              <ode/>
            </friction>
          </surface>
        </collision>
        <visual name='Wall_0_Visual'>
          <pose>0 0 0.5 0 -0 0</pose>
          <geometry>
            <box>
              <size>7 0.15 1</size>
            </box>
          </geometry>
          <material>
            <script>
              <uri>file://media/materials/scripts/gazebo.material</uri>
              <name>Gazebo/Grey</name>
            </script>
            <ambient>1 1 1 1</ambient>
          </material>
          <meta>
            <layer>0</layer>
          </meta>
        </visual>
        <pose>1.26593 -1.92499 0 0 -0 0</pose>
        <self_collide>0</self_collide>
        <enable_wind>0</enable_wind>
        <kinematic>0</kinematic>
      </link>
      <link name='Wall_1'>
        <collision name='Wall_1_Collision'>
          <geometry>
            <box>
              <size>4 0.15 1</size>
            </box>
          </geometry>
          <pose>0 0 0.5 0 -0 0</pose>
          <max_contacts>10</max_contacts>
          <surface>
            <contact>
              <ode/>
            </contact>
            <bounce/>
            <friction>
              <torsional>
                <ode/>
              </torsional>
              <ode/>
            </friction>
          </surface>
        </collision>
        <visual name='Wall_1_Visual'>
          <pose>0 0 0.5 0 -0 0</pose>
          <geometry>
            <box>
              <size>4 0.15 1</size>
            </box>
          </geometry>
          <material>
            <script>
              <uri>file://media/materials/scripts/gazebo.material</uri>
              <name>Gazebo/Grey</name>
            </script>
            <ambient>1 1 1 1</ambient>
          </material>
          <meta>
            <layer>0</layer>
          </meta>
        </visual>
        <pose>4.69093 1.1e-05 0 0 -0 1.5708</pose>
        <self_collide>0</self_collide>
        <enable_wind>0</enable_wind>
        <kinematic>0</kinematic>
      </link>
      <link name='Wall_2'>
        <collision name='Wall_2_Collision'>
          <geometry>
            <box>
              <size>7 0.15 1</size>
            </box>
          </geometry>
          <pose>0 0 0.5 0 -0 0</pose>
          <max_contacts>10</max_contacts>
          <surface>
            <contact>
              <ode/>
            </contact>
            <bounce/>
            <friction>
              <torsional>
                <ode/>
              </torsional>
              <ode/>
            </friction>
          </surface>
        </collision>
        <visual name='Wall_2_Visual'>
          <pose>0 0 0.5 0 -0 0</pose>
          <geometry>
            <box>
              <size>7 0.15 1</size>
            </box>
          </geometry>
          <material>
            <script>
              <uri>file://media/materials/scripts/gazebo.material</uri>
              <name>Gazebo/Grey</name>
            </script>
            <ambient>1 1 1 1</ambient>
          </material>
          <meta>
            <layer>0</layer>
          </meta>
        </visual>
        <pose>1.26593 1.91801 0 0 -0 -3.13955</pose>
        <self_collide>0</self_collide>
        <enable_wind>0</enable_wind>
        <kinematic>0</kinematic>
      </link>
      <link name='Wall_3'>
        <pose>-2.15907 -0.006989 0 0 -0 -1.5708</pose>
        <visual name='Wall_3_Visual_0'>
          <pose>-1.8334 0 0.5 0 -0 0</pose>
          <geometry>
            <box>
              <size>0.319549 0.15 1</size>
            </box>
          </geometry>
          <material>
            <script>
              <uri>file://media/materials/scripts/gazebo.material</uri>
              <name>Gazebo/Grey</name>
            </script>
            <ambient>1 1 1 1</ambient>
          </material>
          <meta>
            <layer>0</layer>
          </meta>
        </visual>
        <collision name='Wall_3_Collision_0'>
          <geometry>
            <box>
              <size>0.319549 0.15 1</size>
            </box>
          </geometry>
          <pose>-1.8334 0 0.5 0 -0 0</pose>
          <max_contacts>10</max_contacts>
          <surface>
            <contact>
              <ode/>
            </contact>
            <bounce/>
            <friction>
              <torsional>
                <ode/>
              </torsional>
              <ode/>
            </friction>
          </surface>
        </collision>
        <visual name='Wall_3_Visual_1'>
          <pose>1.15978 0 0.5 0 -0 0</pose>
          <geometry>
            <box>
              <size>1.6668 0.15 1</size>
            </box>
          </geometry>
          <material>
            <script>
              <uri>file://media/materials/scripts/gazebo.material</uri>
              <name>Gazebo/Grey</name>
            </script>
            <ambient>1 1 1 1</ambient>
          </material>
          <meta>
            <layer>0</layer>
          </meta>
        </visual>
        <collision name='Wall_3_Collision_1'>
          <geometry>
            <box>
              <size>1.6668 0.15 1</size>
            </box>
          </geometry>
          <pose>1.15978 0 0.5 0 -0 0</pose>
          <max_contacts>10</max_contacts>
          <surface>
            <contact>
              <ode/>
            </contact>
            <bounce/>
            <friction>
              <torsional>
                <ode/>
              </torsional>
              <ode/>
            </friction>
          </surface>
        </collision>
        <self_collide>0</self_collide>
        <enable_wind>0</enable_wind>
        <kinematic>0</kinematic>
      </link>
      <static>1</static>
    </model>
    <state world_name='default'>
      <sim_time>39 12000000</sim_time>
      <real_time>44 547703735</real_time>
      <wall_time>1716702347 243200143</wall_time>
      <iterations>39012</iterations>
      <model name='ground_plane'>
        <pose>0 0 0 0 -0 0</pose>
        <scale>1 1 1</scale>
        <link name='link'>
          <pose>0 0 0 0 -0 0</pose>
          <velocity>0 0 0 0 -0 0</velocity>
          <acceleration>0 0 0 0 -0 0</acceleration>
          <wrench>0 0 0 0 -0 0</wrench>
        </link>
      </model>
      <model name='robot2'>
        <pose>-0.02815 -0.031422 -0.001167 0.000995 0.001301 0.007084</pose>
        <scale>1 1 1</scale>
        <link name='base_footprint'>
          <pose>-0.02815 -0.031422 -0.001167 0.000995 0.001301 0.007084</pose>
          <velocity>-0.000212 -0.000185 0.001099 -0.000739 0.003666 -0.000337</velocity>
          <acceleration>0.001498 -0.036992 2.40305 0.977138 0.928253 -0.182366</acceleration>
          <wrench>0.050419 -1.2453 80.8963 0 -0 0</wrench>
        </link>
        <link name='roller_1_1'>
          <pose>-0.279922 0.266785 0.016029 -0.003231 1.56748 0.78925</pose>
          <velocity>-3.8e-05 -9.1e-05 0.001805 -0.002177 0.002148 -0.00036</velocity>
          <acceleration>-0.01814 0.097344 2.92813 0.123014 -0.11875 -0.048463</acceleration>
          <wrench>-0.002249 0.012071 0.363088 0 -0 0</wrench>
        </link>
        <link name='roller_1_2'>
          <pose>-0.238198 0.267066 0.031392 -0.784825 0.868186 0.006992</pose>
          <velocity>2e-05 -9.2e-05 0.001663 -0.001811 0.002154 -0.001228</velocity>
          <acceleration>-0.005019 0.072438 2.8884 0.834537 0.544171 0.106523</acceleration>
          <wrench>-0.000622 0.008982 0.358162 0 -0 0</wrench>
        </link>
        <link name='roller_1_3'>
          <pose>-0.21611 0.267184 0.069979 -0.784688 0.169172 0.005498</pose>
          <velocity>0.000154 -6.8e-05 0.001594 -0.001006 0.001956 -0.001817</velocity>
          <acceleration>0.031402 0.026912 2.86505 1.10997 1.09122 0.449519</acceleration>
          <wrench>0.003894 0.003337 0.355267 0 -0 0</wrench>
        </link>
        <link name='roller_1_4'>
          <pose>-0.223993 0.267085 0.113737 -0.783683 -0.52817 0.005381</pose>
          <velocity>0.000298 -3.2e-05 0.001629 0.000133 0.001649 -0.001819</velocity>
          <acceleration>0.075565 -0.016916 2.86928 0.99923 1.08061 0.139976</acceleration>
          <wrench>0.00937 -0.002098 0.35579 0 -0 0</wrench>
        </link>
        <link name='roller_1_5'>
          <pose>-0.258157 0.266814 0.142191 -0.78554 -1.2242 0.007593</pose>
          <velocity>0.00039 1e-06 0.001748 0.001092 0.001374 -0.00097</velocity>
          <acceleration>0.105554 -0.038582 2.9004 0.95978 1.07696 -0.024744</acceleration>
          <wrench>0.013089 -0.004784 0.35965 0 -0 0</wrench>
        </link>
        <link name='roller_1_6'>
          <pose>-0.302618 0.2665 0.142026 2.36298 -1.22142 3.14108</pose>
          <velocity>0.000391 1.5e-05 0.001897 0.001172 0.001251 0.000394</velocity>
          <acceleration>0.105909 -0.028894 2.94366 1.11108 0.911538 -0.021646</acceleration>
          <wrench>0.013133 -0.003583 0.365013 0 -0 0</wrench>
        </link>
        <link name='roller_1_7'>
          <pose>-0.336571 0.266288 0.113321 2.35803 -0.524964 -3.1399</pose>
          <velocity>0.000299 5e-06 0.002013 0.000238 0.001333 0.001395</velocity>
          <acceleration>0.077061 0.006421 2.97676 1.09024 0.79928 -0.061639</acceleration>
          <wrench>0.009556 0.000796 0.369118 0 -0 0</wrench>
        </link>
        <link name='roller_1_8'>
          <pose>-0.34413 0.266278 0.069505 2.35426 0.173038 -3.14001</pose>
          <velocity>0.000151 -2.3e-05 0.002046 -0.001053 0.001576 0.001424</velocity>
          <acceleration>0.034007 0.050142 2.98245 0.916157 0.825137 -0.34415</acceleration>
          <wrench>0.004217 0.006218 0.369824 0 -0 0</wrench>
        </link>
        <link name='roller_1_9'>
          <pose>-0.321758 0.266474 0.031083 2.35019 0.872639 -3.14151</pose>
          <velocity>1.7e-05 -5.7e-05 0.001977 -0.001912 0.001866 0.00066</velocity>
          <acceleration>-0.002815 0.081897 2.95804 0.429878 0.339524 -0.056992</acceleration>
          <wrench>-0.000349 0.010155 0.366797 0 -0 0</wrench>
        </link>
        <link name='roller_2_1'>
          <pose>0.284759 0.270724 0.07749 -2.35451 0.025788 0.025858</pose>
          <velocity>0.000244 -0.000185 0.000144 0.003383 0.002039 0.00187</velocity>
          <acceleration>0.108855 -0.012206 2.27971 1.50053 -0.918906 0.363594</acceleration>
          <wrench>0.013498 -0.001514 0.282684 0 -0 0</wrench>
        </link>
        <link name='roller_2_2'>
          <pose>0.267705 0.270646 0.036428 -2.33762 0.723185 0.033705</pose>
          <velocity>6.3e-05 -3.9e-05 0.000231 0.004184 0.003111 0.000325</velocity>
          <acceleration>0.139095 0.055433 2.26381 1.40871 -0.511682 0.223125</acceleration>
          <wrench>0.017248 0.006874 0.280713 0 -0 0</wrench>
        </link>
        <link name='roller_2_3'>
          <pose>0.228257 0.270388 0.016035 -2.62167 1.46582 -0.260316</pose>
          <velocity>0.003343 0.003119 0.007056 -0.223011 0.231796 -0.03167</velocity>
          <acceleration>3.267 3.19842 -1.10671 2.72674 -1.52455 0.039197</acceleration>
          <wrench>0.405108 0.396604 -0.137231 0 -0 0</wrench>
        </link>
        <link name='roller_2_4'>
          <pose>0.184851 0.270067 0.025588 0.744711 1.02591 3.10138</pose>
          <velocity>-0.000132 -0.000332 -5e-06 0.000958 0.001977 -0.002132</velocity>
          <acceleration>-0.058094 -0.012111 2.60845 1.20034 1.50873 0.007631</acceleration>
          <wrench>-0.007204 -0.001502 0.323448 0 -0 0</wrench>
        </link>
        <link name='roller_2_5'>
          <pose>0.157817 0.269841 0.060887 0.775964 0.329969 3.12144</pose>
          <velocity>6e-05 -0.000254 0.000151 -0.001059 0.002575 -0.003029</velocity>
          <acceleration>-0.001551 -0.045022 2.64705 -2.09011 1.42458 -2.69219</acceleration>
          <wrench>-0.000192 -0.005583 0.328234 0 -0 0</wrench>
        </link>
        <link name='roller_2_6'>
          <pose>0.159797 0.269812 0.105305 0.794603 -0.367883 3.12146</pose>
          <velocity>0.00031 -0.000167 0.00015 -0.002782 0.003253 -0.002392</velocity>
          <acceleration>0.065979 -0.090435 2.64047 -2.0594 1.52213 -2.53992</acceleration>
          <wrench>0.008181 -0.011214 0.327418 0 -0 0</wrench>
        </link>
        <link name='roller_2_7'>
          <pose>0.189865 0.269993 0.138059 0.827975 -1.06692 3.09986</pose>
          <velocity>0.000497 -0.000111 -1.2e-05 -0.0036 0.003693 -0.001181</velocity>
          <acceleration>0.11707 -0.126658 2.59277 0.289309 0.725752 -0.04129</acceleration>
          <wrench>0.014517 -0.015706 0.321504 0 -0 0</wrench>
        </link>
        <link name='roller_2_8'>
          <pose>0.233952 0.270299 0.143822 -2.46118 -1.37263 0.114593</pose>
          <velocity>0.000528 -0.000112 -0.000257 -0.003806 0.003689 0.000124</velocity>
          <acceleration>0.130953 -0.138002 2.52274 -0.283141 0.298163 0.008945</acceleration>
          <wrench>0.016238 -0.017112 0.312819 0 -0 0</wrench>
        </link>
        <link name='roller_2_9'>
          <pose>0.271427 0.270588 0.119898 -2.37057 -0.673265 0.031685</pose>
          <velocity>0.000388 -0.000165 -0.000463 -0.003329 0.003248 0.001594</velocity>
          <acceleration>0.097345 -0.121893 2.45816 0.494251 1.00958 -0.252391</acceleration>
          <wrench>0.012071 -0.015115 0.304812 0 -0 0</wrench>
        </link>
        <link name='roller_3_1'>
          <pose>0.223211 -0.329664 0.014784 1.62848 1.41914 2.42035</pose>
          <velocity>-0.000475 -0.00055 0.001156 -0.004016 0.000992 -0.000292</velocity>
          <acceleration>-0.082699 0.071015 1.69798 0.082963 -0.088103 -0.046005</acceleration>
          <wrench>-0.010255 0.008806 0.210549 0 -0 0</wrench>
        </link>
        <link name='roller_3_2'>
          <pose>0.265189 -0.329382 0.029438 -0.795059 0.876672 -0.006254</pose>
          <velocity>-0.000237 -0.000307 0.000235 -0.002171 0.002481 -0.001306</velocity>
          <acceleration>-0.11332 -0.012639 1.84736 0.785507 0.54921 0.09412</acceleration>
          <wrench>-0.014052 -0.001567 0.229073 0 -0 0</wrench>
        </link>
        <link name='roller_3_3'>
          <pose>0.287929 -0.329259 0.067644 -0.786281 0.177679 -0.003127</pose>
          <velocity>-8.2e-05 -0.000278 0.000146 -0.001292 0.002267 -0.00207</velocity>
          <acceleration>-0.077614 -0.056761 1.82567 1.09637 1.08673 0.449893</acceleration>
          <wrench>-0.009624 -0.007038 0.226382 0 -0 0</wrench>
        </link>
        <link name='roller_3_4'>
          <pose>0.280792 -0.329353 0.11153 -0.778875 -0.519648 -0.004412</pose>
          <velocity>9.5e-05 -0.000235 0.000178 7.8e-05 0.001941 -0.002167</velocity>
          <acceleration>-0.036677 -0.101226 1.8311 0.997176 1.05407 0.141104</acceleration>
          <wrench>-0.004548 -0.012552 0.227056 0 -0 0</wrench>
        </link>
        <link name='roller_3_5'>
          <pose>0.247116 -0.32962 0.140561 -0.762562 -1.21563 -0.016934</pose>
          <velocity>0.000212 -0.000198 0.000318 0.001301 0.001655 -0.001174</velocity>
          <acceleration>-0.009326 -0.124747 1.86069 0.936614 1.05248 -0.022434</acceleration>
          <wrench>-0.001156 -0.015469 0.230725 0 -0 0</wrench>
        </link>
        <link name='roller_3_6'>
          <pose>0.202659 -0.329936 0.141152 2.33913 -1.22985 -3.11677</pose>
          <velocity>0.000214 -0.000185 0.000502 0.001431 0.00154 0.000514</velocity>
          <acceleration>-0.008019 -0.11582 1.90017 1.10678 0.873444 -0.030994</acceleration>
          <wrench>-0.000994 -0.014362 0.23562 0 -0 0</wrench>
        </link>
        <link name='roller_3_7'>
          <pose>0.168223 -0.330152 0.113028 2.35306 -0.533444 -3.13003</pose>
          <velocity>9.9e-05 -0.000204 0.000645 0.000277 0.00165 0.00175</velocity>
          <acceleration>-0.033012 -0.078105 1.93062 1.18433 0.687542 -0.017311</acceleration>
          <wrench>-0.004093 -0.009685 0.239396 0 -0 0</wrench>
        </link>
        <link name='roller_3_8'>
          <pose>0.15992 -0.330167 0.069347 2.35573 0.164542 -3.13138</pose>
          <velocity>-7.9e-05 -0.000247 0.000682 -0.001295 0.001935 0.001765</velocity>
          <acceleration>-0.072242 -0.028708 1.93736 1.03396 0.714312 -0.308627</acceleration>
          <wrench>-0.008958 -0.00356 0.240232 0 -0 0</wrench>
        </link>
        <link name='roller_3_9'>
          <pose>0.181636 -0.329975 0.03055 2.36022 0.864123 -3.12837</pose>
          <velocity>-0.000236 -0.000294 0.000597 -0.002303 0.002264 0.000843</velocity>
          <acceleration>-0.106977 0.009827 1.91681 0.575524 0.260633 -0.065266</acceleration>
          <wrench>-0.013265 0.001218 0.237684 0 -0 0</wrench>
        </link>
        <link name='roller_4_1'>
          <pose>-0.210918 -0.332804 0.079707 -2.35519 0.009171 0.009191</pose>
          <velocity>-3.5e-05 -8.3e-05 0.002388 -0.00094 0.001818 0.001839</velocity>
          <acceleration>0.024509 0.102803 2.22012 1.08268 0.717471 -0.255301</acceleration>
          <wrench>0.003039 0.012748 0.275295 0 -0 0</wrench>
        </link>
        <link name='roller_4_2'>
          <pose>-0.226596 -0.332874 0.0381 -2.35265 0.706743 0.011376</pose>
          <velocity>-0.000201 -0.000118 0.002454 0.000635 0.001567 0.001508</velocity>
          <acceleration>-0.011927 0.151112 2.23356 1.2105 0.694883 0.017526</acceleration>
          <wrench>-0.001479 0.018738 0.276961 0 -0 0</wrench>
        </link>
        <link name='roller_4_3'>
          <pose>-0.26535 -0.333127 0.016414 -2.71697 1.4451 -0.357492</pose>
          <velocity>-0.000431 -0.000516 0.008163 0.036096 -0.030099 0.005781</velocity>
          <acceleration>4.89903 5.09845 1.41414 0.157046 0.548383 -0.076008</acceleration>
          <wrench>0.60748 0.632208 0.175353 0 -0 0</wrench>
        </link>
        <link name='roller_4_4'>
          <pose>-0.309044 -0.333445 0.024508 0.771452 1.04296 3.13308</pose>
          <velocity>-0.000251 -9e-05 0.002248 0.001033 0.001695 -0.001543</velocity>
          <acceleration>-0.151819 0.052312 2.38878 0.953135 1.03746 -0.000943</acceleration>
          <wrench>-0.018826 0.006487 0.296209 0 -0 0</wrench>
        </link>
        <link name='roller_4_5'>
          <pose>-0.337237 -0.333678 0.058888 0.781204 0.346703 3.13896</pose>
          <velocity>-0.000113 -4.6e-05 0.002365 -0.000312 0.002018 -0.002241</velocity>
          <acceleration>-0.120156 0.02094 2.41374 1.01763 1.05173 0.22099</acceleration>
          <wrench>-0.014899 0.002597 0.299304 0 -0 0</wrench>
        </link>
        <link name='roller_4_6'>
          <pose>-0.336736 -0.333719 0.103347 0.787733 -0.351329 3.13931</pose>
          <velocity>6.5e-05 -2e-06 0.002366 -0.001567 0.002336 -0.001919</velocity>
          <acceleration>-0.079279 -0.026117 2.4129 1.0999 1.0038 0.425575</acceleration>
          <wrench>-0.009831 -0.003238 0.2992 0 -0 0</wrench>
        </link>
        <link name='roller_4_7'>
          <pose>-0.307774 -0.333547 0.137083 0.797097 -1.05071 3.13466</pose>
          <velocity>0.000201 2.1e-05 0.002252 -0.002289 0.0025 -0.001091</velocity>
          <acceleration>-0.048045 -0.06662 2.38646 0.567415 0.326855 -0.015752</acceleration>
          <wrench>-0.005958 -0.008261 0.295921 0 -0 0</wrench>
        </link>
        <link name='roller_4_8'>
          <pose>-0.263904 -0.333243 0.14431 -2.38079 -1.39036 0.032274</pose>
          <velocity>0.00023 1.3e-05 0.002079 -0.002521 0.002431 -6.4e-05</velocity>
          <acceleration>-0.040812 -0.081401 2.34659 0.098689 -0.091304 0.001857</acceleration>
          <wrench>-0.005061 -0.010094 0.290977 0 -0 0</wrench>
        </link>
        <link name='roller_4_9'>
          <pose>-0.225653 -0.33295 0.121647 -2.35758 -0.690059 0.010459</pose>
          <velocity>0.000139 -2.3e-05 0.001929 -0.002144 0.00216 0.00107</velocity>
          <acceleration>-0.060723 -0.063328 2.31175 0.764899 0.424722 -0.160873</acceleration>
          <wrench>-0.00753 -0.007853 0.286657 0 -0 0</wrench>
        </link>
        <link name='wheel_1'>
          <pose>-0.280162 0.266719 0.081029 -1.5698 -0.003699 0.00708</pose>
          <velocity>0.00019 -4e-05 0.001793 -0.000829 0.003528 -0.000352</velocity>
          <acceleration>0.039056 0.023666 2.93223 1.136 0.781102 -0.202161</acceleration>
          <wrench>0.066395 0.040231 4.98479 0 -0 0</wrench>
        </link>
        <link name='wheel_2'>
          <pose>0.219825 0.270261 0.080385 -1.56977 0.044558 0.007129</pose>
          <velocity>0.000256 -0.000152 0.000426 0.003252 0.004609 -0.000665</velocity>
          <acceleration>0.10404 -0.005427 2.23631 1.46165 -0.837008 -0.184962</acceleration>
          <wrench>0.176868 -0.009226 3.80173 0 -0 0</wrench>
        </link>
        <link name='wheel_3'>
          <pose>0.224075 -0.329723 0.079781 -1.56981 0.013302 0.007096</pose>
          <velocity>-4.5e-05 -0.000267 0.000458 -0.00098 0.004057 -0.000326</velocity>
          <acceleration>-0.066757 -0.055313 1.87199 1.08289 -0.532224 0.211405</acceleration>
          <wrench>-0.113487 -0.094032 3.18237 0 -0 0</wrench>
        </link>
        <link name='wheel_4'>
          <pose>-0.275912 -0.333265 0.08043 -1.56981 0.011273 0.007094</pose>
          <velocity>-2.5e-05 -4.4e-05 0.002165 -0.000979 0.004 -0.000354</velocity>
          <acceleration>-0.092239 -0.004842 2.35307 1.05875 -0.577859 0.198534</acceleration>
          <wrench>-0.156807 -0.008232 4.00022 0 -0 0</wrench>
        </link>
      </model>
      <model name='test3'>
        <pose>3.74593 -1.08965 0 0 -0 0</pose>
        <scale>1 1 1</scale>
        <link name='Wall_0'>
          <pose>5.01186 -3.01464 0 0 -0 0</pose>
          <velocity>0 0 0 0 -0 0</velocity>
          <acceleration>0 0 0 0 -0 0</acceleration>
          <wrench>0 0 0 0 -0 0</wrench>
        </link>
        <link name='Wall_1'>
          <pose>8.43686 -1.08964 0 0 -0 1.5708</pose>
          <velocity>0 0 0 0 -0 0</velocity>
          <acceleration>0 0 0 0 -0 0</acceleration>
          <wrench>0 0 0 0 -0 0</wrench>
        </link>
        <link name='Wall_2'>
          <pose>5.01186 0.82836 0 0 0 -3.13955</pose>
          <velocity>0 0 0 0 -0 0</velocity>
          <acceleration>0 0 0 0 -0 0</acceleration>
          <wrench>0 0 0 0 -0 0</wrench>
        </link>
        <link name='Wall_3'>
          <pose>1.58686 -1.09664 0 0 0 -1.5708</pose>
          <velocity>0 0 0 0 -0 0</velocity>
          <acceleration>0 0 0 0 -0 0</acceleration>
          <wrench>0 0 0 0 -0 0</wrench>
        </link>
      </model>
      <light name='sun'>
        <pose>0 0 10 0 -0 0</pose>
      </light>
    </state>
    <gui fullscreen='0'>
      <camera name='user_camera'>
        <pose>-3.68894 -10.1963 8.80866 -0 0.740031 0.711522</pose>
        <view_controller>orbit</view_controller>
        <projection_type>perspective</projection_type>
      </camera>
    </gui>
  </world>
</sdf>
